Workbook

Sheet Instructiuni
A1: MODULE DECLARATIVE — instrucțiuni de utilizare
A3: Ce este acest fișier
A4: Primul pas concret către organizarea fluxurilor din Plan de conturi pe rol ca module declarative care se „sumonează” dintr-un catalog.
A5: Structura urmează exact pattern-ul din template-urile tale (Salarii, Leasing, Deconturi): Declarații → Reguli → Jurnale → NotaExport.
A7: Cum se folosește MOD_INCHIDERE_TVA (primul modul implementat)
A8: 1. Deschide CatalogModule — verifică că Activ=DA pe MOD_INCHIDERE_TVA.
A9: 2. Deschide Declarații_INCHIDERE_TVA — completează celulele galbene (rulaje 4426/4427 din balanță sau jurnale SAGA).
A10: 3. Deschide Jurnale_INCHIDERE_TVA — verifică Check=0 (OK — nota se închide).
A11: 4. Deschide NotaExport_INCHIDERE_TVA — filtrează Include=DA, copiază/înregistrează în program.
A12: 5. După înregistrare: sold 4426=0, sold 4427=0, sold 4423 sau 4424 = diferența.
A14: Ce urmează (ordine recomandată)
A15: • Module IMPLEMENTATE: INCHIDERE_TVA, APROV_TRANZIT, INTERMEDIAR, INCHIDERE_EX, NEUTRALIZARE, VANZ_AMANUNT, TVA_INCASARE
... A21: Modulul nu inventează conturi. Folosește doar conturile din politica declarată + rolurile din Plan de conturi. Porțile de calitate (ΣDr=ΣCr, stare terminală, pas revelator) rămân aceleași ca în foaia Fluxuri.

Sheet Parametri
A1: PARAMETRI GLOBALI — un singur loc pentru identitate și setări comune
A2: Completezi o dată. Toate foile Declarații_* citesc de aici. La client nou: schimbi doar aici.
A4: Identitate (date demonstrative — înlocuiește la utilizare reală)
A5: Denumire societate | B5: SC EXEMPLU SRL
A6: CUI | B6: RO00000000
A7: Luna curentă (YYYY-MM) | B7: 2026-07
A9: Setări contabile comune
A10: Cotă TVA standard | B10: 0.21
A11: Cotă TVA redusă | B11: 0.11
A13: Notă: valorile de mai sus sunt placeholder. Nu sunt date reale de client. Modulele Declarații_* referențiază Parametri!B5 / B6 / B7.

Sheet CatalogModule
A1: CATALOG MODULE DECLARATIVE — sumonare fluxuri
A2: Bifează / activează modulele pentru luna curentă. Fiecare modul activ își trage variabilele din Declarații și emite blocuri în Jurnale + NotaExport.
A3: Arhitectură: Declarații (input galben) → Reguli (tabele fixe) → Registru (dacă e cazul) → Jurnale (auto) → NotaExport (1 rând = 1 înregistrare).
A5: Activ | B5: Cod modul | C5: Flux(uri) acoperite | D5: Tip | E5: Variabile obligatorii | F5: Porți declarative | G5: Blocuri jurnal emise | H5: Status
A6: DA | B6: MOD_INCHIDERE_TVA | C6: F-21 | D6: Lunar (fără linii) | E6: Rulaj 4426, Rulaj 4427, Luna | F6: — | G6: B1 Închidere 4426/4427 → 4423/4424 | H6: IMPLEMENTAT
A7: DA | B7: MOD_APROV_TRANZIT | C7: F-02 (+408 simetric) | D7: Eveniment + stingere | E7: Sumă netă, TVA, Cont stoc, Furnizor, Data factură, Data recepție | F7: Tranzit vs. direct | G7: B1 Factură→32x; B2 Recepție 30x=32x | H7: IMPLEMENTAT
A8: NU | B8: MOD_SALARII | C8: F-32 | D8: Lunar + plăți | E8: Brut, Tichete, Avans, Angajat, Luna — vezi fișierul Salarii AS Kids | F8: — | G8: B1 Costuri; B2 Plăți net+taxe; B3 Tichete — EXEMPLU EXTERN complet | H8: EXEMPLU EXTERN
A9: NU | B9: MOD_DECONT | C9: F-35 + deplasări | D9: Pe decont | E9: Linii decont, Titular, Avans, Cotă TVA — vezi Deconturi AS Kids | F9: Platitor TVA, % ded. vehicule | G9: B1 Avans; B2 Cheltuieli; B3 Regularizare; B4 Plată — EXEMPLU EXTERN complet | H9: EXEMPLU EXTERN
A10: NU | B10: MOD_LEASING_FIN | C10: F-26 + F-28 + reeval | D10: Pe contract + lună | E10: Contract, Scadențar, Regim vehicul, Curs BNR — vezi Template_leasing_financiar_auto | F10: MIXT/EXCLUSIV/EXCEPTAT; Capitalizare vs Cheltuială TVA neded. | G10: B1–B7 pe momente — EXEMPLU EXTERN complet | H10: EXEMPLU EXTERN
A11: DA | B11: MOD_VANZ_AMANUNT | C11: F-14 | D11: Pe gestiune + cotă | E11: Cost, Adaos %, Cotă TVA, Gestiune | F11: En-gros vs Amănunt | G11: B1 Aprovizionare PVA; B2 TVA ded.; B3 Descărcare; B4 Venit; B5 Corelații; B6 Închidere TVA | H11: IMPLEMENTAT
A12: DA | B12: MOD_TVA_INCASARE | C12: F-17 | D12: Pe factură | E12: Sumă netă, TVA, Tip (achiziție/vânzare), Data plată/încasare | F12: 4428.INC activ | G12: B1 Factură→4428.INC; B2 Plată/Încasare→4426/4427 | H12: IMPLEMENTAT
A13: DA | B13: MOD_INCHIDERE_EX | C13: F-37 | D13: Anual | E13: Rulaje cls.6, Rulaje cls.7, Impozit/IMCA | F13: — | G13: B1 Închidere 6xx; B2 Închidere 7xx; B3 Impozit; B4 Repartizare 129; B5 Report 117 | H13: IMPLEMENTAT
A14: DA | B14: MOD_INTERMEDIAR | C14: F-23, F-33, F-34 | D14: Eveniment discret | E14: Sumă, Cont intermediar (408/418/581/473), Cont final, Document | F14: — | G14: B1 Deschidere intermediar; B2 Stingere | H14: IMPLEMENTAT
A15: DA | B15: MOD_NEUTRALIZARE | C15: F-05, F-07, F-28 | D15: Pe stadiu producție | E15: Cost acumulat, Cont stoc (331/332/231), Cont venit (711/712/722) | F15: — | G15: B1 Costuri→stoc; B2 Neutralizare; B3 Finalizare/livrare | H15: IMPLEMENTAT
A17: REGULĂ DE SUMONARE
A18: 1. În CatalogModule setezi Activ=DA doar pe modulele necesare lunii.
A19: 2. Completezi variabilele din foaia Declarații_Modul (galben).
A20: 3. Jurnalele și NotaExport se populează automat doar pentru modulele active.
A21: 4. Verifici Check=0 pe fiecare bloc; filtrezi NotaExport pe Include=DA și imporți.
A22: Nu se creează conturi noi din modul — se folosesc doar conturile din politica declarată + planul de conturi pe rol.

Sheet Declarații_INCHIDERE_TVA
A1: MOD_INCHIDERE_TVA — Declarații (input)
A2: Completează doar celulele galbene cu scris albastru. Restul sunt formule sau text fix.
A4: 1. Antet
A5: Societate | B5: =Parametri!B5 -> SC EXEMPLU SRL
A6: CUI | B6: =Parametri!B6 -> RO00000000
A7: Luna (AAAA-LL) | B7: 2026-07
A8: Data jurnal (ultima zi a lunii) | B8: 2026-07-31
A10: 2. Rulaje TVA din jurnale (introducere manuală din balanță / jurnale SAGA)
A11: Rulaj debitor 4426 (TVA deductibilă) | B11: 10500
A12: Rulaj creditor 4427 (TVA colectată) | B12: 15750
A14: 3. Politică de conturi (din planul pe rol)
A15: Cont TVA deductibilă | B15: 4426
A16: Cont TVA colectată | B16: 4427
A17: Cont TVA de plată | B17: 4423
A18: Cont TVA de recuperat | B18: 4424
A20: 4. Calcul automat (nu edita)
A21: Sold net (4427 − 4426) | B21: =B12-B11 -> 5250
A22: Direcție | B22: =IF(B21>0,"TVA de plată (4423)","TVA de recuperat (4424)") -> TVA de plată (4423)
A23: Sumă pe 4423 | B23: =IF(B21>0,B21,0) -> 5250
A24: Sumă pe 4424 | B24: =IF(B21<0,-B21,0) -> 0
A26: 5. Sufix descriere (generat)
A27: Sufix | B27: ="— închidere TVA " & B7 -> — închidere TVA 2026-07
A29: 6. Control
A30: Check: 4426 și 4427 trebuie să aibă sold 0 după notă | B30: OK dacă nota e înregistrată integral
A31: Modul activ în CatalogModule? | B31: =IF(CatalogModule!A6="DA","ACTIV — jurnalele se generează","INACTIV — jurnalele rămân goale") -> ACTIV — jurnalele se generează

Sheet Reguli_INCHIDERE_TVA
A1: MOD_INCHIDERE_TVA — Reguli (tabele fixe)
A2: Regula fiscală/contabilă este dată, nu formulă. Se editează doar când se schimbă legea sau politica firmei.
A4: Tabel A — Secvența de închidere
A5: Pas | B5: Cont Dr | C5: Cont Cr | D5: Sumă (sursă) | E5: Condiție | F5: Temei / observație
A6: 1 | B6: 4427 | C6: 4426 | D6: MIN(rulaj 4426, rulaj 4427) | E6: Întotdeauna | F6: Stingere reciprocă a rulajelor — fără sold intermediar
A7: 2 | B7: 4427 | C7: 4423 | D7: MAX(0, 4427−4426) | E7: Dacă 4427 > 4426 | F7: Sold net = TVA de plată către buget
A8: 3 | B8: 4424 | C8: 4426 | D8: MAX(0, 4426−4427) | E8: Dacă 4426 > 4427 | F8: Sold net = TVA de recuperat / de rambursat
A10: Tabel B — Conturi din planul pe rol (referință)
A11: Cont | B11: Denumire | C11: Rol | D11: Observație din Plan de conturi
A12: 4426 | B12: TVA deductibilă | C12: Tranzit / reflectare | D12: Jurnal cumpărări; se închide lunar; fără sold
A13: 4427 | B13: TVA colectată | C13: Tranzit / reflectare | D13: Jurnal vânzări; se închide lunar; fără sold
A14: 4423 | B14: TVA de plată | C14: Patrimonial — Datorie | D14: Sold datorie lunară către buget
A15: 4424 | B15: TVA de recuperat | C15: Patrimonial — Creanță | D15: Sold creanță / de rambursat
A17: Tabel C — Porți de calitate
A18: • ΣDr = ΣCr pe notă
A19: • După înregistrare: sold 4426 = 0 și sold 4427 = 0
A20: • Sold 4423 sau 4424 = |4427 − 4426|
A21: • Descrierile conțin sufixul generat (luna)
A22: • Modulul nu creează analitice noi — folosește conturile din Declarații

Sheet Jurnale_INCHIDERE_TVA
A1: MOD_INCHIDERE_TVA — Jurnale (generate automat)
A2: Nu se scrie nimic manual. Toate sumele și descrierile derivă din Declarații_INCHIDERE_TVA.
A4: Bloc 1 — Închiderea lunară 4426 / 4427
A5: Data jurnal: | B5: =Declarații_INCHIDERE_TVA!B8 -> 2026-07-31
A7: Înregistrări
A8: Nr | B8: Cont Dr | C8: Sumă Dr | D8: Descriere Dr | E8: Cont Cr | F8: Sumă Cr | G8: Descriere Cr
A9: 1 | B9: =Declarații_INCHIDERE_TVA!B16 -> 4427 | C9: =MIN(Declarații_INCHIDERE_TVA!B11,Declarații_INCHIDERE_TVA!B12) -> 10500 | D9: ="Stingere TVA colectată " & Declarații_INCHIDERE_TVA!B27 -> Stingere TVA colectată — închidere TVA 2026-07 | E9: =Declarații_INCHIDERE_TVA!B15 -> 4426 | F9: =MIN(Declarații_INCHIDERE_TVA!B11,Declarații_INCHIDERE_TVA!B12) -> 10500 | G9: ="Stingere TVA deductibilă " & Declarații_INCHIDERE_TVA!B27 -> Stingere TVA deductibilă — închidere TVA 2026-07
A10: 2 | B10: =Declarații_INCHIDERE_TVA!B16 -> 4427 | C10: =Declarații_INCHIDERE_TVA!B23 -> 5250 | D10: ="TVA de plată (sold net) " & Declarații_INCHIDERE_TVA!B27 -> TVA de plată (sold net) — închidere TVA 2026-07 | E10: =Declarații_INCHIDERE_TVA!B17 -> 4423 | F10: =Declarații_INCHIDERE_TVA!B23 -> 5250 | G10: ="Datorie TVA buget " & Declarații_INCHIDERE_TVA!B27 -> Datorie TVA buget — închidere TVA 2026-07
A11: 3 | B11: =Declarații_INCHIDERE_TVA!B18 -> 4424 | C11: =Declarații_INCHIDERE_TVA!B24 -> 0 | D11: ="TVA de recuperat (sold net) " & Declarații_INCHIDERE_TVA!B27 -> TVA de recuperat (sold net) — închidere TVA 2026-07 | E11: =Declarații_INCHIDERE_TVA!B15 -> 4426 | F11: =Declarații_INCHIDERE_TVA!B24 -> 0 | G11: ="Stingere rest TVA deductibilă " & Declarații_INCHIDERE_TVA!B27 -> Stingere rest TVA deductibilă — închidere TVA 2026-07
A13: Sumar
A14: Total Dr | B14: =C9+C10+C11 -> 15750
A15: Total Cr | B15: =F9+F10+F11 -> 15750
A16: Check Σ (structural) | B16: =B14-B15 -> 0 | C16: =IF(ABS(B16)<0.01,"OK — notă se închide","EROARE") -> OK — notă se închide
A17: Check net (REAL) | B17: =ABS(Declarații_INCHIDERE_TVA!B12-Declarații_INCHIDERE_TVA!B11)-(C10+C11) -> 0 | C17: =IF(ABS(B17)<0.01,"OK — net repartizat pe 4423/4424","EROARE — net ≠ |4427−4426|") -> OK — net repartizat pe 4423/4424
A18: Check exclusivitate 4423/4424 | B18: =IF(AND(C10>0.01,C11>0.01),1,0) -> 0 | C18: =IF(B18=0,"OK — un singur cont de sold","EROARE — 4423 și 4424 ambele >0") -> OK — un singur cont de sold
A19: Stare terminală așteptată: sold 4426=0, sold 4427=0, sold 4423 sau 4424 = |4427−4426|

Sheet NotaExport_INCHIDERE_TVA
A1: MOD_INCHIDERE_TVA — Notă pentru import (1 rând = 1 înregistrare)
A2: Filtrează pe coloana Include = DA înainte de import în SAGA / alt program. Echilibrul se verifică pe bloc în Jurnale, nu pe totalul listei.
A4: Nr | B4: Bloc | C4: Data | D4: Cont Dr | E4: Cont Cr | F4: Sumă | G4: Descriere | H4: Document | I4: Include
A5: 1 | B5: Bloc 1 — Închidere TVA | C5: =Declarații_INCHIDERE_TVA!B8 -> 2026-07-31 | D5: =Jurnale_INCHIDERE_TVA!B9 -> 4427 | E5: =Jurnale_INCHIDERE_TVA!E9 -> 4426 | F5: =Jurnale_INCHIDERE_TVA!C9 -> 10500 | G5: =Jurnale_INCHIDERE_TVA!D9 -> Stingere TVA colectată — închidere TVA 2026-07 | H5: Închidere lunară TVA | I5: =IF(F5>0,"DA","NU") -> DA
A6: 2 | B6: Bloc 1 — Închidere TVA | C6: =Declarații_INCHIDERE_TVA!B8 -> 2026-07-31 | D6: =Jurnale_INCHIDERE_TVA!B10 -> 4427 | E6: =Jurnale_INCHIDERE_TVA!E10 -> 4423 | F6: =Jurnale_INCHIDERE_TVA!C10 -> 5250 | G6: =Jurnale_INCHIDERE_TVA!D10 -> TVA de plată (sold net) — închidere TVA 2026-07 | H6: Închidere lunară TVA | I6: =IF(F6>0,"DA","NU") -> DA
A7: 3 | B7: Bloc 1 — Închidere TVA | C7: =Declarații_INCHIDERE_TVA!B8 -> 2026-07-31 | D7: =Jurnale_INCHIDERE_TVA!B11 -> 4424 | E7: =Jurnale_INCHIDERE_TVA!E11 -> 4426 | F7: =Jurnale_INCHIDERE_TVA!C11 -> 0 | G7: =Jurnale_INCHIDERE_TVA!D11 -> TVA de recuperat (sold net) — închidere TVA 2026-07 | H7: Închidere lunară TVA | I7: =IF(F7>0,"DA","NU") -> NU
A9: Rânduri de importat (Include=DA) | B9: =COUNTIF(I5:I7,"DA") -> 2
A10: Check global (trebuie 0) | B10: =Jurnale_INCHIDERE_TVA!B16 -> 0 | C10: =IF(ABS(B10)<0.01,"OK","EROARE") -> OK

Sheet Declarații_APROV_TRANZIT
A1: MOD_APROV_TRANZIT — Declarații (input)
A2: Completează doar celulele galbene. Modulul acoperă: factură înainte de recepție (32x) + stingere la recepție. Cazul simetric 408 (marfă înainte de factură) se notează, dar se activează separat dacă e nevoie.
A4: 1. Antet
A5: Societate | B5: =Parametri!B5 -> SC EXEMPLU SRL
A6: CUI | B6: =Parametri!B6 -> RO00000000
A7: Luna (AAAA-LL) | B7: 2026-07
A8: Data factură (jurnal B1) | B8: 2026-07-10
A9: Data recepție NIR (jurnal B2) | B9: 2026-07-18
A10: Furnizor (denumire scurtă) | B10: Furnizor DEMO
A11: Nr. factură / document | B11: F-1234/10.07.2026
A13: 2. Sume factură
A14: Valoare netă (fără TVA) | B14: 8000
A15: Cota TVA | B15: 0.21
A16: TVA (calculat) | B16: =B14*B15 -> 1680
A17: Total factură | B17: =B14+B16 -> 9680
A19: 3. Politică de conturi
A20: Cont stoc final (după recepție) | B20: 371
A21: Cont tranzit (32x) | B21: 327
A22: Cont furnizor | B22: 401.RO
A23: Cont TVA deductibilă | B23: 4426
A24: Platitor TVA? (DA/NU) | B24: DA
A26: 4. Poartă — tip eveniment
A27: Factură înainte de marfă? (DA = tranzit 32x) | B27: DA
A28: Marfă înainte de factură? (DA = 408 — nu e acoperit de acest modul) | B28: NU
A29: Notă poartă | B29: =IF(AND(B27="DA",B28="NU"),"Cale standard F-02: 32x → stoc","Verifică: dacă ambele DA sau ambele NU, situația nu e tranzit clasic") -> Cale standard F-02: 32x → stoc
A31: 5. Sufix descriere (generat)
A32: Sufix | B32: ="— " & B7 & " — " & B10 & " — " & B11 -> — 2026-07 — Furnizor DEMO — F-1234/10.07.2026
A34: 6. Control modul
A35: Modul activ în Catalog? | B35: =IF(CatalogModule!A7="DA","ACTIV","INACTIV") -> ACTIV

Sheet Reguli_APROV_TRANZIT
A1: MOD_APROV_TRANZIT — Reguli (tabele fixe)
A2: Regula este dată, nu formulă. Se editează doar la schimbare de lege sau politică.
A4: Tabel A — Secvența de înregistrare (calea standard F-02)
A5: Pas | B5: Moment | C5: Cont Dr | D5: Cont Cr | E5: Sumă | F5: Temei / observație
A6: 1 | B6: Factură (marfă pe drum) | C6: 327 (tranzit) | D6: 401.RO | E6: Netă | F6: Rol: Tranzit / reflectare — destinația cunoscută, așteaptă recepția
A7: 2 | B7: Factură — TVA | C7: 4426 | D7: 401.RO | E7: TVA | F7: Tranzit TVA; se închide lunar în 4423/4424
A8: 3 | B8: Recepție NIR | C8: 371 (sau 301) | D8: 327 | E8: Netă | F8: Stingere tranzit → stoc real (pas revelator)
A10: Tabel B — Conturi din planul pe rol
A11: Cont | B11: Denumire | C11: Rol | D11: Observație
A12: 327 | B12: Mărfuri în curs de aprovizionare | C12: Tranzit / reflectare | D12: Se stinge 371=327 la recepție. Fără pasul de stingere → stoc subevaluat + 327 deschis
A13: 321-328 | B13: Familia 32x | C13: Tranzit / reflectare | D13: 321 materii, 322 consumabile, 323 obiecte inventar, 327 mărfuri, 328 ambalaje
A14: 371 / 301 | B14: Stoc real | C14: Patrimonial — Stoc | D14: Destinația finală după recepție
A15: 401.RO | B15: Furnizori RO | C15: Patrimonial — Datorie | D15: Analitic pe rezidență pentru D394
A16: 4426 | B16: TVA deductibilă | C16: Tranzit / reflectare | D16: Fără sold după închiderea lunară
A17: 408 | B17: Furnizori — facturi nesosite | C17: Intermediar / clarificare | D17: Cazul SIMETRIC (marfă înainte de factură) — modul separat MOD_INTERMEDIAR
A19: Tabel C — Porți de calitate
A20: • ΣDr = ΣCr pe fiecare bloc (B1 factură, B2 recepție)
A21: • După B2: sold 327 = 0
A22: • Dacă poarta „Factură înainte de marfă” = NU → modulul nu ar trebui activat (calea e F-01 direct)
A23: • 408 nu se folosește în acest modul (e oglinda simetrică)

Sheet Jurnale_APROV_TRANZIT
A1: MOD_APROV_TRANZIT — Jurnale (generate automat)
A2: Nu se scrie nimic manual. Sumele și descrierile vin din Declarații_APROV_TRANZIT.
A4: Bloc 1 — Factură (marfă pe drum) — rol Tranzit
A5: Data jurnal: | B5: =Declarații_APROV_TRANZIT!B8 -> 2026-07-10
A7: Nr | B7: Cont Dr | C7: Sumă Dr | D7: Descriere Dr | E7: Cont Cr | F7: Sumă Cr | G7: Descriere Cr
A8: 1 | B8: =Declarații_APROV_TRANZIT!B21 -> 327 | C8: =Declarații_APROV_TRANZIT!B14 -> 8000 | D8: ="Marfă în curs de aprovizionare " & Declarații_APROV_TRANZIT!B32 -> Marfă în curs de aprovizionare — 2026-07 — Furnizor DEMO — F-1234/10.07.2026 | E8: =Declarații_APROV_TRANZIT!B22 -> 401.RO | F8: =Declarații_APROV_TRANZIT!B14 -> 8000 | G8: ="Datorie furnizor (net) " & Declarații_APROV_TRANZIT!B32 -> Datorie furnizor (net) — 2026-07 — Furnizor DEMO — F-1234/10.07.2026
A9: 2 | B9: =Declarații_APROV_TRANZIT!B23 -> 4426 | C9: =IF(Declarații_APROV_TRANZIT!B24="DA",Declarații_APROV_TRANZIT!B16,0) -> 1680 | D9: ="TVA deductibilă pe factură în tranzit " & Declarații_APROV_TRANZIT!B32 -> TVA deductibilă pe factură în tranzit — 2026-07 — Furnizor DEMO — F-1234/10.07.2026 | E9: =Declarații_APROV_TRANZIT!B22 -> 401.RO | F9: =IF(Declarații_APROV_TRANZIT!B24="DA",Declarații_APROV_TRANZIT!B16,0) -> 1680 | G9: ="Datorie furnizor (TVA) " & Declarații_APROV_TRANZIT!B32 -> Datorie furnizor (TVA) — 2026-07 — Furnizor DEMO — F-1234/10.07.2026
A11: Sumar Bloc 1
A12: Total Dr | B12: =C8+C9 -> 9680
A13: Total Cr | B13: =F8+F9 -> 9680
A14: Check B1 | B14: =B12-B13 -> 0 | C14: =IF(ABS(B14)<0.01,"OK","EROARE") -> OK
A16: Bloc 2 — Recepție NIR — stingere tranzit (pas revelator)
A17: Data jurnal: | B17: =Declarații_APROV_TRANZIT!B9 -> 2026-07-18
A19: Nr | B19: Cont Dr | C19: Sumă Dr | D19: Descriere Dr | E19: Cont Cr | F19: Sumă Cr | G19: Descriere Cr
A20: 1 | B20: =Declarații_APROV_TRANZIT!B20 -> 371 | C20: =Declarații_APROV_TRANZIT!B14 -> 8000 | D20: ="Recepție stoc real (stingere tranzit) " & Declarații_APROV_TRANZIT!B32 -> Recepție stoc real (stingere tranzit) — 2026-07 — Furnizor DEMO — F-1234/10.07.2026 | E20: =Declarații_APROV_TRANZIT!B21 -> 327 | F20: =Declarații_APROV_TRANZIT!B14 -> 8000 | G20: ="Stingere 32x " & Declarații_APROV_TRANZIT!B32 -> Stingere 32x — 2026-07 — Furnizor DEMO — F-1234/10.07.2026
A22: Sumar Bloc 2
A23: Total Dr | B23: =C20 -> 8000
A24: Total Cr | B24: =F20 -> 8000
A25: Check B2 | B25: =B23-B24 -> 0 | C25: =IF(ABS(B25)<0.01,"OK","EROARE") -> OK
A27: Stare terminală așteptată
A28: Sold 327 = 0 | Stoc 371 (sau 301) reflectă marfa | 401 = total factură | 4426 conține TVA (se închide la final de lună cu MOD_INCHIDERE_TVA)
A30: Check global (toate blocurile) | B30: =ABS(B14)+ABS(B25) -> 0 | C30: =IF(B30<0.01,"OK — toate blocurile se închid","EROARE — cel puțin un bloc dezechilibrat") -> OK — toate blocurile se închid

Sheet NotaExport_APROV_TRANZIT
A1: MOD_APROV_TRANZIT — Notă pentru import
A2: Filtrează Include=DA. Bloc 1 = data facturii; Bloc 2 = data recepției (pot fi luni diferite).
A4: Nr | B4: Bloc | C4: Data | D4: Cont Dr | E4: Cont Cr | F4: Sumă | G4: Descriere | H4: Document | I4: Include
A5: 1 | B5: Bloc 1 — Factură tranzit | C5: =Declarații_APROV_TRANZIT!B8 -> 2026-07-10 | D5: =Jurnale_APROV_TRANZIT!B8 -> 327 | E5: =Jurnale_APROV_TRANZIT!E8 -> 401.RO | F5: =Jurnale_APROV_TRANZIT!C8 -> 8000 | G5: =Jurnale_APROV_TRANZIT!D8 -> Marfă în curs de aprovizionare — 2026-07 — Furnizor DEMO — F-1234/10.07.2026 | H5: =Declarații_APROV_TRANZIT!B11 -> F-1234/10.07.2026 | I5: =IF(F5>0,"DA","NU") -> DA
A6: 2 | B6: Bloc 1 — Factură tranzit | C6: =Declarații_APROV_TRANZIT!B8 -> 2026-07-10 | D6: =Jurnale_APROV_TRANZIT!B9 -> 4426 | E6: =Jurnale_APROV_TRANZIT!E9 -> 401.RO | F6: =Jurnale_APROV_TRANZIT!C9 -> 1680 | G6: =Jurnale_APROV_TRANZIT!D9 -> TVA deductibilă pe factură în tranzit — 2026-07 — Furnizor DEMO — F-1234/10.07.2026 | H6: =Declarații_APROV_TRANZIT!B11 -> F-1234/10.07.2026 | I6: =IF(F6>0,"DA","NU") -> DA
A7: 3 | B7: Bloc 2 — Recepție | C7: =Declarații_APROV_TRANZIT!B9 -> 2026-07-18 | D7: =Jurnale_APROV_TRANZIT!B20 -> 371 | E7: =Jurnale_APROV_TRANZIT!E20 -> 327 | F7: =Jurnale_APROV_TRANZIT!C20 -> 8000 | G7: =Jurnale_APROV_TRANZIT!D20 -> Recepție stoc real (stingere tranzit) — 2026-07 — Furnizor DEMO — F-1234/10.07.2026 | H7: NIR | I7: =IF(F7>0,"DA","NU") -> DA
A9: Rânduri de importat | B9: =COUNTIF(I5:I7,"DA") -> 3
A10: Check global | B10: =Jurnale_APROV_TRANZIT!B30 -> 0 | C10: =IF(ABS(B10)<0.01,"OK","EROARE") -> OK

Sheet Declarații_INTERMEDIAR
A1: MOD_INTERMEDIAR — Declarații (input)
A2: Modul generic pentru conturi de tip Intermediar / clarificare: 408, 418, 581, 473. Alege tipul, completează sumele și conturile — jurnalele se generează pe cele două momente (deschidere + stingere).
A4: 1. Antet
A5: Societate | B5: =Parametri!B5 -> SC EXEMPLU SRL
A6: CUI | B6: =Parametri!B6 -> RO00000000
A7: Luna (AAAA-LL) | B7: 2026-07
A9: 2. Tip intermediar (poartă principală)
A10: Tip (408 / 418 / 581 / 473) | B10: 473
A11: Descriere tip (auto) | B11: =IF(B10="408","Furnizori — facturi nesosite",IF(B10="418","Clienți — facturi de întocmit",IF(B10="581","Viramente interne",IF(B10="473","Operațiuni în curs de clarificare","Tip necunoscut — verifică")))) -> Operațiuni în curs de clarificare
A13: 3. Moment deschidere (Bloc 1)
A14: Data deschidere | B14: 2026-07-15
A15: Sumă | B15: 2350
A16: Cont intermediar (Dr sau Cr după tip) | B16: 473
A17: Cont contrapartidă deschidere | B17: 5121
A18: Sens deschidere (Dr_intermediar / Cr_intermediar) | B18: Cr_intermediar
A19: Document / referință deschidere | B19: Extras bancă 15.07 — sumă neidentificată
A21: 4. Moment stingere (Bloc 2)
A22: Data stingere | B22: 2026-07-22
A23: Cont final (după clarificare) | B23: 411.RO
A24: Document / referință stingere | B24: Identificat: client X, factura Y
A26: 5. Sufix descriere (generat)
A27: Sufix | B27: ="— " & B7 & " — " & B10 & " — " & B19 -> — 2026-07 — 473 — Extras bancă 15.07 — sumă neidentificată
A29: 6. Control
A30: Modul activ? | B30: =IF(CatalogModule!A14="DA","ACTIV","INACTIV") -> ACTIV
A31: Regulă 473 | B31: =IF(B10=473,"Sold 473 la 31.12 = suspect — clarificare obligatorie","—") -> —

Sheet Reguli_INTERMEDIAR
A1: MOD_INTERMEDIAR — Reguli (tabele fixe)
A2: Pattern comun: deschidere pe cont intermediar → stingere pe cont final când evenimentul discret (document, identificare, confirmare) are loc.
A4: Tabel A — Tipuri și sensuri standard
A5: Tip | B5: Denumire | C5: Rol | D5: Deschidere tipică | E5: Stingere tipică | F5: Pas revelator / red flag
A6: 408 | B6: Furnizori — facturi nesosite | C6: Intermediar | D6: Dr stoc / 4426 = Cr 408 | E6: Dr 408 = Cr 401 | F6: Sold 408 la 31.12 = facturi încă nesosite
A7: 418 | B7: Clienți — facturi de întocmit | C7: Intermediar | D7: Dr 418 = Cr venit / 4427 | E7: Dr 411 = Cr 418 | F7: Sold 418 = livrat nefacturat
A8: 581 | B8: Viramente interne | C8: Intermediar | D8: Dr 581 = Cr 512 (ieșire) | E8: Dr 531/512 = Cr 581 (intrare) | F8: Sold 581 = transfer neconfirmat
A9: 473 | B9: Operațiuni în curs de clarificare | C9: Intermediar | D9: Dr 512 = Cr 473 (intrare neid.) | E9: Dr 473 = Cr 411/401/768 | F9: Sold 473 la 31.12 = SUSPECT — clarificare obligatorie
A11: Tabel B — Secvența generică a modulului
A12: Pas | B12: Moment | C12: Logică | D12: Condiție
A13: 1 | B13: Deschidere | C13: Cont intermediar ↔ Cont contrapartidă (bancă/stoc/venit) | D13: Sensul (Dr/Cr intermediar) se alege în Declarații
A14: 2 | B14: Stingere | C14: Cont intermediar ↔ Cont final (401/411/512/531/768…) | D14: Când documentul / identificarea / confirmarea există
A16: Tabel C — Porți de calitate
A17: • ΣDr = ΣCr pe fiecare bloc
A18: • După stingere: sold cont intermediar = 0 pe această operațiune
A19: • Pentru 473: dacă data stingerii e goală sau > 31.12 → semnalează red flag
A20: • Modulul nu amestecă tipurile — un set de Declarații = un tip + o operațiune

Sheet Jurnale_INTERMEDIAR
A1: MOD_INTERMEDIAR — Jurnale (generate automat)
A2: Sensul deschiderii (Dr sau Cr pe intermediar) se citește din Declarații. Stingerea inversează sensul.
A4: Bloc 1 — Deschidere intermediar
A5: Data: | B5: =Declarații_INTERMEDIAR!B14 -> 2026-07-15
A6: Tip: | B6: =Declarații_INTERMEDIAR!B10 & " — " & Declarații_INTERMEDIAR!B11 -> 473 — Operațiuni în curs de clarificare
A8: Nr | B8: Cont Dr | C8: Sumă Dr | D8: Descriere Dr | E8: Cont Cr | F8: Sumă Cr | G8: Descriere Cr
A9: 1 | B9: =IF(Declarații_INTERMEDIAR!B18="Cr_intermediar",Declarații_INTERMEDIAR!B17,Declarații_INTERMEDIAR!B16) -> 5121 | C9: =Declarații_INTERMEDIAR!B15 -> 2350 | D9: =IF(Declarații_INTERMEDIAR!B18="Cr_intermediar","Contrapartidă deschidere ","Deschidere intermediar ") & Declarații_INTERMEDIAR!B27 -> Contrapartidă deschidere — 2026-07 — 473 — Extras bancă 15.07 — sumă neidentificată | E9: =IF(Declarații_INTERMEDIAR!B18="Cr_intermediar",Declarații_INTERMEDIAR!B16,Declarații_INTERMEDIAR!B17) -> 473 | F9: =Declarații_INTERMEDIAR!B15 -> 2350 | G9: =IF(Declarații_INTERMEDIAR!B18="Cr_intermediar","Deschidere intermediar ","Contrapartidă deschidere ") & Declarații_INTERMEDIAR!B27 -> Deschidere intermediar — 2026-07 — 473 — Extras bancă 15.07 — sumă neidentificată
A11: Check B1 | B11: =C9-F9 -> 0 | C11: =IF(ABS(B11)<0.01,"OK","EROARE") -> OK
A13: Bloc 2 — Stingere intermediar (pas revelator)
A14: Data: | B14: =Declarații_INTERMEDIAR!B22 -> 2026-07-22
A16: Nr | B16: Cont Dr | C16: Sumă Dr | D16: Descriere Dr | E16: Cont Cr | F16: Sumă Cr | G16: Descriere Cr
A17: 1 | B17: =IF(Declarații_INTERMEDIAR!B18="Cr_intermediar",Declarații_INTERMEDIAR!B16,Declarații_INTERMEDIAR!B23) -> 473 | C17: =Declarații_INTERMEDIAR!B15 -> 2350 | D17: =IF(Declarații_INTERMEDIAR!B18="Cr_intermediar","Stingere intermediar ","Cont final (stingere) ") & Declarații_INTERMEDIAR!B27 -> Stingere intermediar — 2026-07 — 473 — Extras bancă 15.07 — sumă neidentificată | E17: =IF(Declarații_INTERMEDIAR!B18="Cr_intermediar",Declarații_INTERMEDIAR!B23,Declarații_INTERMEDIAR!B16) -> 411.RO | F17: =Declarații_INTERMEDIAR!B15 -> 2350 | G17: =IF(Declarații_INTERMEDIAR!B18="Cr_intermediar","Cont final (stingere) ","Stingere intermediar ") & Declarații_INTERMEDIAR!B27 -> Cont final (stingere) — 2026-07 — 473 — Extras bancă 15.07 — sumă neidentificată
A19: Check B2 | B19: =C17-F17 -> 0 | C19: =IF(ABS(B19)<0.01,"OK","EROARE") -> OK
A21: Stare terminală
A22: Sold intermediar pe această operațiune = 0. Pentru 473: dacă rămâne sold la 31.12 → red flag audit.
A24: Check global | B24: =ABS(B11)+ABS(B19) -> 0 | C24: =IF(B24<0.01,"OK — toate blocurile se închid","EROARE — cel puțin un bloc dezechilibrat") -> OK — toate blocurile se închid

Sheet NotaExport_INTERMEDIAR
A1: MOD_INTERMEDIAR — Notă pentru import
A2: Filtrează Include=DA. Cele două blocuri pot avea date diferite (deschidere vs. stingere).
A4: Nr | B4: Bloc | C4: Data | D4: Cont Dr | E4: Cont Cr | F4: Sumă | G4: Descriere | H4: Document | I4: Include
A5: 1 | B5: Bloc 1 — Deschidere | C5: =Declarații_INTERMEDIAR!B14 -> 2026-07-15 | D5: =Jurnale_INTERMEDIAR!B9 -> 5121 | E5: =Jurnale_INTERMEDIAR!E9 -> 473 | F5: =Jurnale_INTERMEDIAR!C9 -> 2350 | G5: =Jurnale_INTERMEDIAR!D9 -> Contrapartidă deschidere — 2026-07 — 473 — Extras bancă 15.07 — sumă neidentificată | H5: =Declarații_INTERMEDIAR!B19 -> Extras bancă 15.07 — sumă neidentificată | I5: =IF(F5>0,"DA","NU") -> DA
A6: 2 | B6: Bloc 2 — Stingere | C6: =Declarații_INTERMEDIAR!B22 -> 2026-07-22 | D6: =Jurnale_INTERMEDIAR!B17 -> 473 | E6: =Jurnale_INTERMEDIAR!E17 -> 411.RO | F6: =Jurnale_INTERMEDIAR!C17 -> 2350 | G6: =Jurnale_INTERMEDIAR!D17 -> Stingere intermediar — 2026-07 — 473 — Extras bancă 15.07 — sumă neidentificată | H6: =Declarații_INTERMEDIAR!B24 -> Identificat: client X, factura Y | I6: =IF(F6>0,"DA","NU") -> DA
A8: Rânduri de importat | B8: =COUNTIF(I5:I6,"DA") -> 2
A9: Check global | B9: =Jurnale_INTERMEDIAR!B24 -> 0 | C9: =IF(ABS(B9)<0.01,"OK","EROARE") -> OK

Sheet Declarații_INCHIDERE_EX
A1: MOD_INCHIDERE_EX — Declarații (input)
A2: Modul anual. Completezi rulajele din balanță (sau totaluri din SAGA). Jurnalele închid cls.6 → 121, cls.7 → 121, calculează impozit / IMCA, repartizează 129 și reportează 117.
A4: 1. Antet
A5: Societate | B5: =Parametri!B5 -> SC EXEMPLU SRL
A6: CUI | B6: =Parametri!B6 -> RO00000000
A7: An exercițiu | B7: 2026
A8: Data jurnal închidere (31.12) | B8: 2026-12-31
A10: 2. Rulaje de închis (din balanță / totaluri SAGA)
A11: Total rulaj debitor cls.6 (cheltuieli) | B11: 185000
A12: Total rulaj creditor cls.7 (venituri) | B12: 245000
A14: 3. Impozit pe profit / IMCA
A15: Regim (PROFIT / MICRO / IMCA) | B15: PROFIT
A16: Baza impozabilă (sau cifră afaceri IMCA) | B16: 60000
A17: Cotă (0.16 / 0.01 / 0.03 etc.) | B17: 0.16
A18: Impozit calculat | B18: =B16*B17 -> 9600
A19: Cont cheltuială impozit (691 / 697 / 4417) | B19: 691
A20: Cont datorie impozit (441 / 4417) | B20: 441
A22: 4. Repartizare rezultat
A23: Rezultat înainte de impozit (7−6) | B23: =B12-B11 -> 60000
A24: Rezultat net (după impozit) | B24: =B23-B18 -> 50400
A25: Repartizare la rezerve / dividende etc. (opțional) | B25: 0
A26: Reportat pe 117 (sold final 121/129) | B26: =B24-B25 -> 50400
A28: 5. Politică conturi rezultat
A29: Cont profit și pierdere | B29: 121
A30: Cont repartizare profit | B30: 129
A31: Cont rezultat reportat | B31: 117
A33: 6. Sufix
A34: Sufix | B34: ="— închidere exercițiu " & B7 -> — închidere exercițiu 2026
A36: 7. Control
A37: Modul activ? | B37: =IF(CatalogModule!A13="DA","ACTIV","INACTIV") -> ACTIV
A38: Notă | B38: În practică se închid conturile de cheltuieli/venituri pe analitice (sau pe grupe). Aici se lucrează pe totaluri — un singur rând pe clasă.

Sheet Reguli_INCHIDERE_EX
A1: MOD_INCHIDERE_EX — Reguli (tabele fixe)
A2: Secvența de închidere e standard OMFP 1802. Detalierea pe conturi analitice se face în SAGA; modulul lucrează pe totaluri de clasă pentru generarea notei de principiu.
A4: Tabel A — Secvența de închidere
A5: Pas | B5: Bloc | C5: Cont Dr | D5: Cont Cr | E5: Sumă | F5: Observație
A6: 1 | B6: B1 Închidere cheltuieli | C6: 121 | D6: 6xx (total) | E6: Rulaj D cls.6 | F6: Neutralizare rezultat — cheltuieli
A7: 2 | B7: B2 Închidere venituri | C7: 7xx (total) | D7: 121 | E7: Rulaj C cls.7 | F7: Neutralizare rezultat — venituri
A8: 3 | B8: B3 Impozit | C8: 691/697 | D8: 441/4417 | E8: Impozit calculat | F8: Cheltuială cu impozitul → datorie
A9: 4 | B9: B3b Închidere 691 | C9: 121 | D9: 691 | E9: Impozit | F9: Impozitul intră în rezultatul net
A10: 5 | B10: B4 Repartizare (opțional) | C10: 129 | D10: 106/457… | E10: Sumă repartizată | F10: Doar dacă AGA / decizie există
A11: 6 | B11: B5 Report | C11: 121 | D11: 117 | E11: Sold final 121 | F11: Dacă profit; invers dacă pierdere
A13: Tabel B — Conturi din plan pe rol
A14: Cont | B14: Denumire | C14: Rol | D14: Observație
A15: 121 | B15: Profit sau pierdere | C15: Colectare rezultat | D15: Se închide anual; fără sold după report pe 117
A16: 129 | B16: Repartizarea profitului | C16: Colectare / tranzit | D16: Se folosește doar la repartizare formală
A17: 117 | B17: Rezultatul reportat | C17: Patrimonial — Capital | D17: Sold permanent până la acoperire / repartizare
A18: 691 | B18: Cheltuieli cu impozitul pe profit | C18: Neutralizare rezultat | D18: Se închide în 121
A19: 697 | B19: Cheltuieli cu impozitul pe venit micro | C19: Neutralizare rezultat | D19: Alternativă la 691
A20: 441 | B20: Impozit pe profit | C20: Patrimonial — Datorie | D20: Datorie către buget
A21: 4417 | B21: Impozit pe venit micro / alte impozite | C21: Patrimonial — Datorie | D21: Conform OMF actualizat
A23: Tabel C — Porți de calitate
A24: • ΣDr = ΣCr pe fiecare bloc
A25: • După B1+B2: sold 6xx = 0, sold 7xx = 0
A26: • Sold 121 înainte de report = rezultat net
A27: • După B5: sold 121 = 0, sold 117 reflectă reportul
A28: • Modulul nu înlocuiește D101 / declarația de impozit — produce doar nota contabilă

Sheet Jurnale_INCHIDERE_EX
A1: MOD_INCHIDERE_EX — Jurnale (generate automat)
A2: Toate sumele derivă din Declarații. În SAGA se detaliază pe conturi analitice; aici e nota de principiu pe totaluri de clasă.
A4: Data jurnal: | B4: =Declarații_INCHIDERE_EX!B8 -> 2026-12-31
A6: Bloc 1 — Închidere cheltuieli (cls.6 → 121)
A7: Nr | B7: Cont Dr | C7: Sumă Dr | D7: Descriere Dr | E7: Cont Cr | F7: Sumă Cr | G7: Descriere Cr
A8: 1 | B8: =Declarații_INCHIDERE_EX!B29 -> 121 | C8: =Declarații_INCHIDERE_EX!B11 -> 185000 | D8: ="Închidere cheltuieli cls.6 " & Declarații_INCHIDERE_EX!B34 -> Închidere cheltuieli cls.6 — închidere exercițiu 2026 | E8: 6xx | F8: =Declarații_INCHIDERE_EX!B11 -> 185000 | G8: ="Stingere rulaj cheltuieli " & Declarații_INCHIDERE_EX!B34 -> Stingere rulaj cheltuieli — închidere exercițiu 2026
A9: Check B1 | B9: =C8-F8 -> 0 | C9: =IF(ABS(B9)<0.01,"OK","EROARE") -> OK
A11: Bloc 2 — Închidere venituri (cls.7 → 121)
A12: Nr | B12: Cont Dr | C12: Sumă Dr | D12: Descriere Dr | E12: Cont Cr | F12: Sumă Cr | G12: Descriere Cr
A13: 1 | B13: 7xx | C13: =Declarații_INCHIDERE_EX!B12 -> 245000 | D13: ="Închidere venituri cls.7 " & Declarații_INCHIDERE_EX!B34 -> Închidere venituri cls.7 — închidere exercițiu 2026 | E13: =Declarații_INCHIDERE_EX!B29 -> 121 | F13: =Declarații_INCHIDERE_EX!B12 -> 245000 | G13: ="Stingere rulaj venituri " & Declarații_INCHIDERE_EX!B34 -> Stingere rulaj venituri — închidere exercițiu 2026
A14: Check B2 | B14: =C13-F13 -> 0 | C14: =IF(ABS(B14)<0.01,"OK","EROARE") -> OK
A16: Bloc 3 — Cheltuială cu impozitul + închiderea ei în 121
A17: Nr | B17: Cont Dr | C17: Sumă Dr | D17: Descriere Dr | E17: Cont Cr | F17: Sumă Cr | G17: Descriere Cr
A18: 1 | B18: =Declarații_INCHIDERE_EX!B19 -> 691 | C18: =Declarații_INCHIDERE_EX!B18 -> 9600 | D18: ="Cheltuială impozit " & Declarații_INCHIDERE_EX!B34 -> Cheltuială impozit — închidere exercițiu 2026 | E18: =Declarații_INCHIDERE_EX!B20 -> 441 | F18: =Declarații_INCHIDERE_EX!B18 -> 9600 | G18: ="Datorie impozit buget " & Declarații_INCHIDERE_EX!B34 -> Datorie impozit buget — închidere exercițiu 2026
A19: 2 | B19: =Declarații_INCHIDERE_EX!B29 -> 121 | C19: =Declarații_INCHIDERE_EX!B18 -> 9600 | D19: ="Închidere cheltuială impozit în rezultat " & Declarații_INCHIDERE_EX!B34 -> Închidere cheltuială impozit în rezultat — închidere exercițiu 2026 | E19: =Declarații_INCHIDERE_EX!B19 -> 691 | F19: =Declarații_INCHIDERE_EX!B18 -> 9600 | G19: ="Stingere 691 " & Declarații_INCHIDERE_EX!B34 -> Stingere 691 — închidere exercițiu 2026
A20: Check B3 | B20: =(C18+C19)-(F18+F19) -> 0 | C20: =IF(ABS(B20)<0.01,"OK","EROARE") -> OK
A22: Bloc 4 — Report rezultat net pe 117
A23: Nr | B23: Cont Dr | C23: Sumă Dr | D23: Descriere Dr | E23: Cont Cr | F23: Sumă Cr | G23: Descriere Cr
A24: 1 | B24: =IF(Declarații_INCHIDERE_EX!B26>=0,Declarații_INCHIDERE_EX!B29,Declarații_INCHIDERE_EX!B31) -> 121 | C24: =ABS(Declarații_INCHIDERE_EX!B26) -> 50400 | D24: =IF(Declarații_INCHIDERE_EX!B26>=0,"Report profit pe 117 ","Report pierdere pe 117 ") & Declarații_INCHIDERE_EX!B34 -> Report profit pe 117 — închidere exercițiu 2026 | E24: =IF(Declarații_INCHIDERE_EX!B26>=0,Declarații_INCHIDERE_EX!B31,Declarații_INCHIDERE_EX!B29) -> 117 | F24: =ABS(Declarații_INCHIDERE_EX!B26) -> 50400 | G24: =IF(Declarații_INCHIDERE_EX!B26>=0,"Rezultat reportat (profit) ","Rezultat reportat (pierdere) ") & Declarații_INCHIDERE_EX!B34 -> Rezultat reportat (profit) — închidere exercițiu 2026
A25: Check B4 | B25: =C24-F24 -> 0 | C25: =IF(ABS(B25)<0.01,"OK","EROARE") -> OK
A27: Stare terminală așteptată
A28: Sold 6xx=0 | Sold 7xx=0 | Sold 121=0 | Sold 691=0 | 441 = impozit datorat | 117 = rezultat net reportat
A30: Check global | B30: =ABS(B9)+ABS(B14)+ABS(B20)+ABS(B25) -> 0 | C30: =IF(B30<0.01,"OK — toate blocurile se închid","EROARE — cel puțin un bloc dezechilibrat") -> OK — toate blocurile se închid

Sheet NotaExport_INCHIDERE_EX
A1: MOD_INCHIDERE_EX — Notă pentru import
A2: Filtrează Include=DA. În SAGA se detaliază 6xx/7xx pe conturi individuale; aceste rânduri sunt nota de principiu.
A4: Nr | B4: Bloc | C4: Data | D4: Cont Dr | E4: Cont Cr | F4: Sumă | G4: Descriere | H4: Document | I4: Include
A5: 1 | B5: B1 Cheltuieli | C5: =Declarații_INCHIDERE_EX!B8 -> 2026-12-31 | D5: =Jurnale_INCHIDERE_EX!B8 -> 121 | E5: =Jurnale_INCHIDERE_EX!E8 -> 6xx | F5: =Jurnale_INCHIDERE_EX!C8 -> 185000 | G5: =Jurnale_INCHIDERE_EX!D8 -> Închidere cheltuieli cls.6 — închidere exercițiu 2026 | H5: Închidere exercițiu | I5: =IF(F5>0,"DA","NU") -> DA
A6: 2 | B6: B2 Venituri | C6: =Declarații_INCHIDERE_EX!B8 -> 2026-12-31 | D6: =Jurnale_INCHIDERE_EX!B13 -> 7xx | E6: =Jurnale_INCHIDERE_EX!E13 -> 121 | F6: =Jurnale_INCHIDERE_EX!C13 -> 245000 | G6: =Jurnale_INCHIDERE_EX!D13 -> Închidere venituri cls.7 — închidere exercițiu 2026 | H6: Închidere exercițiu | I6: =IF(F6>0,"DA","NU") -> DA
A7: 3 | B7: B3 Impozit | C7: =Declarații_INCHIDERE_EX!B8 -> 2026-12-31 | D7: =Jurnale_INCHIDERE_EX!B18 -> 691 | E7: =Jurnale_INCHIDERE_EX!E18 -> 441 | F7: =Jurnale_INCHIDERE_EX!C18 -> 9600 | G7: =Jurnale_INCHIDERE_EX!D18 -> Cheltuială impozit — închidere exercițiu 2026 | H7: Închidere exercițiu | I7: =IF(F7>0,"DA","NU") -> DA
A8: 4 | B8: B3 Înch.691 | C8: =Declarații_INCHIDERE_EX!B8 -> 2026-12-31 | D8: =Jurnale_INCHIDERE_EX!B19 -> 121 | E8: =Jurnale_INCHIDERE_EX!E19 -> 691 | F8: =Jurnale_INCHIDERE_EX!C19 -> 9600 | G8: =Jurnale_INCHIDERE_EX!D19 -> Închidere cheltuială impozit în rezultat — închidere exercițiu 2026 | H8: Închidere exercițiu | I8: =IF(F8>0,"DA","NU") -> DA
A9: 5 | B9: B4 Report 117 | C9: =Declarații_INCHIDERE_EX!B8 -> 2026-12-31 | D9: =Jurnale_INCHIDERE_EX!B24 -> 121 | E9: =Jurnale_INCHIDERE_EX!E24 -> 117 | F9: =Jurnale_INCHIDERE_EX!C24 -> 50400 | G9: =Jurnale_INCHIDERE_EX!D24 -> Report profit pe 117 — închidere exercițiu 2026 | H9: Închidere exercițiu | I9: =IF(F9>0,"DA","NU") -> DA
A11: Rânduri de importat | B11: =COUNTIF(I5:I9,"DA") -> 5
A12: Check global | B12: =Jurnale_INCHIDERE_EX!B30 -> 0 | C12: =IF(ABS(B12)<0.01,"OK","EROARE") -> OK

Sheet Declarații_NEUTRALIZARE
A1: MOD_NEUTRALIZARE — Declarații (input)
A2: Acoperă F-05 (bunuri/711), F-07 (servicii/712), F-28 (imobilizări/722). Alege tipul — conturile și lanțul se adaptează. Principiu: costurile lovesc cls.6, apoi contul de venit de producție capitalizează și neutralizează.
A4: 1. Antet
A5: Societate | B5: =Parametri!B5 -> SC EXEMPLU SRL
A6: CUI | B6: =Parametri!B6 -> RO00000000
A7: Luna / proiect | B7: 2026-07
A8: Data costuri (B1) | B8: 2026-07-05
A9: Data finalizare stoc (B2-B3) | B9: 2026-07-20
A10: Data vânzare / recepție MF (B4) | B10: 2026-07-25
A12: 2. Tip producție (poartă principală)
A13: Tip (BUNURI / SERVICII / MF) | B13: BUNURI
A14: Cont venit neutralizare (auto) | B14: =IF(B13="BUNURI",711,IF(B13="SERVICII",712,IF(B13="MF",722,"?"))) -> 711
A15: Cont stoc intermediar (auto) | B15: =IF(B13="BUNURI",331,IF(B13="SERVICII",332,IF(B13="MF",231,"?"))) -> 331
A16: Cont stoc final (auto) | B16: =IF(B13="BUNURI",345,IF(B13="SERVICII","(nu e cazul — se stinge la livrare)",IF(B13="MF",213,"?"))) -> 345
A17: Cont venit vânzare (auto) | B17: =IF(B13="BUNURI",701,IF(B13="SERVICII",704,IF(B13="MF","(nu e vânzare — e activ)","?"))) -> 701
A19: 3. Costuri (cls.6)
A20: Cost materiale (→ 601) | B20: 4500
A21: Cost manoperă (→ 641) | B21: 0
A22: Alte costuri (→ 6xx) | B22: 0
A23: Cost total | B23: =B20+B21+B22 -> 4500
A25: 4. Vânzare (doar BUNURI / SERVICII)
A26: Preț vânzare (fără TVA) | B26: 7000
A27: Cota TVA | B27: 0.21
A28: TVA | B28: =IF(OR(B13="BUNURI",B13="SERVICII"),B26*B27,0) -> 1470
A29: Total factură | B29: =B26+B28 -> 8470
A31: 5. Conturi suplimentare
A32: Cont materii prime | B32: 301
A33: Cont client | B33: 411.RO
A34: Cont TVA colectată | B34: 4427
A36: 6. Sufix
A37: Sufix | B37: ="— " & B7 & " — " & B13 & " — " & B14 -> — 2026-07 — BUNURI — 711
A39: 7. Control
A40: Marjă (vânzare − cost) | B40: =IF(OR(B13="BUNURI",B13="SERVICII"),B26-B23,"n/a (MF)") -> 2500
A41: Notă principiu | B41: Costurile lovesc cls.6; contul de venit de producție (711/712/722) capitalizează și neutralizează. Descărcarea la vânzare (bunuri) e prin 711=345, nu prin 607.

Sheet Reguli_NEUTRALIZARE
A1: MOD_NEUTRALIZARE — Reguli (tabele fixe)
A2: Principiul comun F-05 / F-07 / F-28: cost → cls.6 → stoc intermediar = venit neutralizare → stoc final / livrare. 711/712/722 nu se stinge greșit în stocul final fără pasul de obținere.
A4: Tabel A — Lanț pe tip
A5: Tip | B5: Cost → | C5: Stoc intermediar | D5: Venit neut. | E5: Stoc final / livrare | F5: Descărcare la vânzare
A6: BUNURI | B6: 601=301 | C6: 331=711 | D6: 711=331 apoi 345=711 | E6: 345 | F6: 711=345 (NU 607)
A7: SERVICII | B7: 641/601=… | C7: 332=712 | D7: 712=332 | E7: (nu e stoc final) | F7: 712 stins la livrare
A8: MF | B8: 601=301, 641=421 | C8: 231=722 | D8: — | E8: 213=231 | F8: (nu e vânzare — e activ)
A10: Tabel B — Porți de calitate
A11: • ΣD=ΣC pe fiecare bloc
A12: • Cont venit neutralizare: rulaj D = rulaj C la final (sold 0)
A13: • Stoc intermediar sold 0 după finalizare
A14: • Pentru BUNURI: 345 un singur D și un singur C; descărcare prin 711, nu 607
A15: • Pentru MF: impact net pe 121 din capitalizare = 0 (cheltuieli = 722)
A17: Tabel C — Ce NU se face
A18: • 345 creditat de două ori fără un debit de obținere (eroarea F-05 veche)
A19: • 722 = 231 (ar stinge activul — eroare F-28 veche); corect e 231 = 722
A20: • 607 la descărcarea produselor finite (607 e doar mărfuri)
A21: • „711 sau 712” la servicii — pentru servicii e strict 712

Sheet Jurnale_NEUTRALIZARE
A1: MOD_NEUTRALIZARE — Jurnale (generate automat)
A2: Lanțul se adaptează după Tip. Pentru MF, blocul de vânzare rămâne 0. Pentru SERVICII, stocul final e gol.
A4: Bloc 1 — Costuri pe cls.6
A5: Data: | B5: =Declarații_NEUTRALIZARE!B8 -> 2026-07-05
A6: Nr | B6: Cont Dr | C6: Sumă Dr | D6: Descriere Dr | E6: Cont Cr | F6: Sumă Cr | G6: Descriere Cr
A7: 1 | B7: 601 | C7: =Declarații_NEUTRALIZARE!B20 -> 4500 | D7: ="Consum materiale " & Declarații_NEUTRALIZARE!B37 -> Consum materiale — 2026-07 — BUNURI — 711 | E7: =Declarații_NEUTRALIZARE!B32 -> 301 | F7: =Declarații_NEUTRALIZARE!B20 -> 4500 | G7: ="Stingere stoc materii " & Declarații_NEUTRALIZARE!B37 -> Stingere stoc materii — 2026-07 — BUNURI — 711
A8: 2 | B8: 641 | C8: =Declarații_NEUTRALIZARE!B21 -> 0 | D8: ="Manoperă pe proiect " & Declarații_NEUTRALIZARE!B37 -> Manoperă pe proiect — 2026-07 — BUNURI — 711 | E8: 421 | F8: =Declarații_NEUTRALIZARE!B21 -> 0 | G8: ="Datorie salarii " & Declarații_NEUTRALIZARE!B37 -> Datorie salarii — 2026-07 — BUNURI — 711
A9: Check B1 | B9: =(C7+C8)-(F7+F8) -> 0 | C9: =IF(ABS(B9)<0.01,"OK","EROARE") -> OK
A11: Bloc 2 — Stoc intermediar = venit neutralizare (pas revelator)
A12: Data: | B12: =Declarații_NEUTRALIZARE!B9 -> 2026-07-20
A13: Nr | B13: Cont Dr | C13: Sumă Dr | D13: Descriere Dr | E13: Cont Cr | F13: Sumă Cr | G13: Descriere Cr
A14: 1 | B14: =Declarații_NEUTRALIZARE!B15 -> 331 | C14: =Declarații_NEUTRALIZARE!B23 -> 4500 | D14: ="Stoc intermediar (PN/servicii/MF în curs) " & Declarații_NEUTRALIZARE!B37 -> Stoc intermediar (PN/servicii/MF în curs) — 2026-07 — BUNURI — 711 | E14: =Declarații_NEUTRALIZARE!B14 -> 711 | F14: =Declarații_NEUTRALIZARE!B23 -> 4500 | G14: ="Venit producție / neutralizare " & Declarații_NEUTRALIZARE!B37 -> Venit producție / neutralizare — 2026-07 — BUNURI — 711
A15: Check B2 | B15: =C14-F14 -> 0 | C15: =IF(ABS(B15)<0.01,"OK","EROARE") -> OK
A17: Bloc 3 — Finalizare (obținere stoc final / stingere intermediar)
A18: Data: | B18: =Declarații_NEUTRALIZARE!B9 -> 2026-07-20
A19: Nr | B19: Cont Dr | C19: Sumă Dr | D19: Descriere Dr | E19: Cont Cr | F19: Sumă Cr | G19: Descriere Cr
A20: 1 | B20: =IF(Declarații_NEUTRALIZARE!B13="BUNURI",Declarații_NEUTRALIZARE!B14,IF(Declarații_NEUTRALIZARE!B13="SERVICII",Declarații_NEUTRALIZARE!B14,Declarații_NEUTRALIZARE!B16)) -> 711 | C20: =Declarații_NEUTRALIZARE!B23 -> 4500 | D20: =IF(Declarații_NEUTRALIZARE!B13="BUNURI","Reluare PN (711 debitat #1) ",IF(Declarații_NEUTRALIZARE!B13="SERVICII","Stingere servicii în curs ","Transfer MF final ")) & Declarații_NEUTRALIZARE!B37 -> Reluare PN (711 debitat #1) — 2026-07 — BUNURI — 711 | E20: =IF(Declarații_NEUTRALIZARE!B13="MF",Declarații_NEUTRALIZARE!B15,Declarații_NEUTRALIZARE!B15) -> 331 | F20: =Declarații_NEUTRALIZARE!B23 -> 4500 | G20: ="Stingere stoc intermediar " & Declarații_NEUTRALIZARE!B37 -> Stingere stoc intermediar — 2026-07 — BUNURI — 711
A21: 2 | B21: =IF(Declarații_NEUTRALIZARE!B13="BUNURI",Declarații_NEUTRALIZARE!B16,0) -> 345 | C21: =IF(Declarații_NEUTRALIZARE!B13="BUNURI",Declarații_NEUTRALIZARE!B23,0) -> 4500 | D21: =IF(Declarații_NEUTRALIZARE!B13="BUNURI","Obținere produs finit (345=711) " & Declarații_NEUTRALIZARE!B37,"") -> Obținere produs finit (345=711) — 2026-07 — BUNURI — 711 | E21: =IF(Declarații_NEUTRALIZARE!B13="BUNURI",Declarații_NEUTRALIZARE!B14,0) -> 711 | F21: =IF(Declarații_NEUTRALIZARE!B13="BUNURI",Declarații_NEUTRALIZARE!B23,0) -> 4500 | G21: =IF(Declarații_NEUTRALIZARE!B13="BUNURI","Neutralizare (711 creditat #2) " & Declarații_NEUTRALIZARE!B37,"") -> Neutralizare (711 creditat #2) — 2026-07 — BUNURI — 711
A22: Check B3 | B22: =(C20+C21)-(F20+F21) -> 0 | C22: =IF(ABS(B22)<0.01,"OK","EROARE") -> OK
A24: Bloc 4 — Vânzare + descărcare (BUNURI/SERVICII; 0 pentru MF)
A25: Data: | B25: =Declarații_NEUTRALIZARE!B10 -> 2026-07-25
A26: Nr | B26: Cont Dr | C26: Sumă Dr | D26: Descriere Dr | E26: Cont Cr | F26: Sumă Cr | G26: Descriere Cr
A27: 1 | B27: =IF(OR(Declarații_NEUTRALIZARE!B13="BUNURI",Declarații_NEUTRALIZARE!B13="SERVICII"),Declarații_NEUTRALIZARE!B33,0) -> 411.RO | C27: =IF(OR(Declarații_NEUTRALIZARE!B13="BUNURI",Declarații_NEUTRALIZARE!B13="SERVICII"),Declarații_NEUTRALIZARE!B29,0) -> 8470 | D27: ="Creanță client " & Declarații_NEUTRALIZARE!B37 -> Creanță client — 2026-07 — BUNURI — 711 | E27: =IF(OR(Declarații_NEUTRALIZARE!B13="BUNURI",Declarații_NEUTRALIZARE!B13="SERVICII"),Declarații_NEUTRALIZARE!B17,0) -> 701 | F27: =IF(OR(Declarații_NEUTRALIZARE!B13="BUNURI",Declarații_NEUTRALIZARE!B13="SERVICII"),Declarații_NEUTRALIZARE!B26,0) -> 7000 | G27: ="Venit din vânzare " & Declarații_NEUTRALIZARE!B37 -> Venit din vânzare — 2026-07 — BUNURI — 711
A28: 2 | B28: 0 | C28: 0 | E28: =IF(OR(Declarații_NEUTRALIZARE!B13="BUNURI",Declarații_NEUTRALIZARE!B13="SERVICII"),Declarații_NEUTRALIZARE!B34,0) -> 4427 | F28: =IF(OR(Declarații_NEUTRALIZARE!B13="BUNURI",Declarații_NEUTRALIZARE!B13="SERVICII"),Declarații_NEUTRALIZARE!B28,0) -> 1470 | G28: ="TVA colectată " & Declarații_NEUTRALIZARE!B37 -> TVA colectată — 2026-07 — BUNURI — 711
A29: 3 | B29: =IF(Declarații_NEUTRALIZARE!B13="BUNURI",Declarații_NEUTRALIZARE!B14,IF(Declarații_NEUTRALIZARE!B13="SERVICII",Declarații_NEUTRALIZARE!B14,0)) -> 711 | C29: =IF(OR(Declarații_NEUTRALIZARE!B13="BUNURI",Declarații_NEUTRALIZARE!B13="SERVICII"),Declarații_NEUTRALIZARE!B23,0) -> 4500 | D29: =IF(Declarații_NEUTRALIZARE!B13="BUNURI","Descărcare PF prin 711 (NU 607) ",IF(Declarații_NEUTRALIZARE!B13="SERVICII","Stingere 712 la livrare ","")) & Declarații_NEUTRALIZARE!B37 -> Descărcare PF prin 711 (NU 607) — 2026-07 — BUNURI — 711 | E29: =IF(Declarații_NEUTRALIZARE!B13="BUNURI",Declarații_NEUTRALIZARE!B16,0) -> 345 | F29: =IF(Declarații_NEUTRALIZARE!B13="BUNURI",Declarații_NEUTRALIZARE!B23,0) -> 4500 | G29: =IF(Declarații_NEUTRALIZARE!B13="BUNURI","Stingere stoc PF " & Declarații_NEUTRALIZARE!B37,"") -> Stingere stoc PF — 2026-07 — BUNURI — 711
A30: Check B4 | B30: =(C27+C28+C29)-(F27+F28+F29) -> 0 | C30: =IF(ABS(B30)<0.01,"OK","EROARE") -> OK
A32: Check global | B32: =ABS(B9)+ABS(B15)+ABS(B22)+ABS(B30) -> 0 | C32: =IF(B32<0.01,"OK — toate blocurile se închid","EROARE — cel puțin un bloc dezechilibrat") -> OK — toate blocurile se închid
A34: Stare terminală
A35: Cont venit neut. sold 0 | Stoc intermediar 0 | Pentru BUNURI: 345 sold 0, descărcare prin 711 | Pentru MF: 213=cost, impact 121 din capitalizare = 0

Sheet NotaExport_NEUTRALIZARE
A1: MOD_NEUTRALIZARE — Notă pentru import
A2: Filtrează Include=DA. Rândurile cu sumă 0 (ex. manoperă 0, sau blocuri MF fără vânzare) apar ca NU.
A4: Nr | B4: Bloc | C4: Data | D4: Cont Dr | E4: Cont Cr | F4: Sumă | G4: Descriere | H4: Document | I4: Include
A5: 1 | B5: B1 Costuri | C5: =Declarații_NEUTRALIZARE!B8 -> 2026-07-05 | D5: =Jurnale_NEUTRALIZARE!B7 -> 601 | E5: =Jurnale_NEUTRALIZARE!E7 -> 301 | F5: =Jurnale_NEUTRALIZARE!C7 -> 4500 | G5: =Jurnale_NEUTRALIZARE!D7 -> Consum materiale — 2026-07 — BUNURI — 711 | H5: Producție / neutralizare | I5: =IF(AND(ISNUMBER(F5),F5>0),"DA","NU") -> DA
A6: 2 | B6: B1 Costuri | C6: =Declarații_NEUTRALIZARE!B8 -> 2026-07-05 | D6: =Jurnale_NEUTRALIZARE!B8 -> 641 | E6: =Jurnale_NEUTRALIZARE!E8 -> 421 | F6: =Jurnale_NEUTRALIZARE!C8 -> 0 | G6: =Jurnale_NEUTRALIZARE!D8 -> Manoperă pe proiect — 2026-07 — BUNURI — 711 | H6: Producție / neutralizare | I6: =IF(AND(ISNUMBER(F6),F6>0),"DA","NU") -> NU
A7: 3 | B7: B2 Neutralizare | C7: =Declarații_NEUTRALIZARE!B9 -> 2026-07-20 | D7: =Jurnale_NEUTRALIZARE!B14 -> 331 | E7: =Jurnale_NEUTRALIZARE!E14 -> 711 | F7: =Jurnale_NEUTRALIZARE!C14 -> 4500 | G7: =Jurnale_NEUTRALIZARE!D14 -> Stoc intermediar (PN/servicii/MF în curs) — 2026-07 — BUNURI — 711 | H7: Producție / neutralizare | I7: =IF(AND(ISNUMBER(F7),F7>0),"DA","NU") -> DA
A8: 4 | B8: B3 Finalizare | C8: =Declarații_NEUTRALIZARE!B9 -> 2026-07-20 | D8: =Jurnale_NEUTRALIZARE!B20 -> 711 | E8: =Jurnale_NEUTRALIZARE!E20 -> 331 | F8: =Jurnale_NEUTRALIZARE!C20 -> 4500 | G8: =Jurnale_NEUTRALIZARE!D20 -> Reluare PN (711 debitat #1) — 2026-07 — BUNURI — 711 | H8: Producție / neutralizare | I8: =IF(AND(ISNUMBER(F8),F8>0),"DA","NU") -> DA
A9: 5 | B9: B3 Finalizare | C9: =Declarații_NEUTRALIZARE!B9 -> 2026-07-20 | D9: =Jurnale_NEUTRALIZARE!B21 -> 345 | E9: =Jurnale_NEUTRALIZARE!E21 -> 711 | F9: =Jurnale_NEUTRALIZARE!C21 -> 4500 | G9: =Jurnale_NEUTRALIZARE!D21 -> Obținere produs finit (345=711) — 2026-07 — BUNURI — 711 | H9: Producție / neutralizare | I9: =IF(AND(ISNUMBER(F9),F9>0),"DA","NU") -> DA
A10: 6 | B10: B4 Vânzare | C10: =Declarații_NEUTRALIZARE!B10 -> 2026-07-25 | D10: =Jurnale_NEUTRALIZARE!B27 -> 411.RO | E10: =Jurnale_NEUTRALIZARE!E27 -> 701 | F10: =Jurnale_NEUTRALIZARE!F27 -> 7000 | G10: =Jurnale_NEUTRALIZARE!D27 -> Creanță client — 2026-07 — BUNURI — 711 | H10: Producție / neutralizare | I10: =IF(AND(ISNUMBER(F10),F10>0),"DA","NU") -> DA
A11: 7 | B11: B4 TVA | C11: =Declarații_NEUTRALIZARE!B10 -> 2026-07-25 | D11: =Jurnale_NEUTRALIZARE!B27 -> 411.RO | E11: =Jurnale_NEUTRALIZARE!E28 -> 4427 | F11: =Jurnale_NEUTRALIZARE!F28 -> 1470 | G11: =Jurnale_NEUTRALIZARE!G28 -> TVA colectată — 2026-07 — BUNURI — 711 | H11: Producție / neutralizare | I11: =IF(AND(ISNUMBER(F11),F11>0),"DA","NU") -> DA
A12: 8 | B12: B4 Descărcare | C12: =Declarații_NEUTRALIZARE!B10 -> 2026-07-25 | D12: =Jurnale_NEUTRALIZARE!B29 -> 711 | E12: =Jurnale_NEUTRALIZARE!E29 -> 345 | F12: =Jurnale_NEUTRALIZARE!C29 -> 4500 | G12: =Jurnale_NEUTRALIZARE!D29 -> Descărcare PF prin 711 (NU 607) — 2026-07 — BUNURI — 711 | H12: Producție / neutralizare | I12: =IF(AND(ISNUMBER(F12),F12>0),"DA","NU") -> DA
A14: Rânduri de importat | B14: =COUNTIF(I5:I12,"DA") -> 7
A15: Check global | B15: =Jurnale_NEUTRALIZARE!B32 -> 0 | C15: =IF(ABS(B15)<0.01,"OK","EROARE") -> OK

Sheet Declarații_AMANUNT
A1: MOD_VANZ_AMANUNT — Declarații (input)
A2: Gestiune amănunt la PVA. Corelații: 371×c/(100+c)=4428 și 707−607=rulaj D 378. Completează galben.
A4: 1. Antet
A5: Societate | B5: =Parametri!B5 -> SC EXEMPLU SRL
A6: Gestiune (analitic) | B6: AM.21
A7: Luna | B7: 2026-07
A8: Data aprovizionare | B8: 2026-07-05
A9: Data vânzare (Z-report) | B9: 2026-07-31
A11: 2. Aprovizionare
A12: Cost (fără TVA) | B12: 10000
A13: Adaos % | B13: 0.3
A14: Cotă TVA | B14: 0.21
A15: Adaos (lei) | B15: =B12*B13 -> 3000
A16: Bază PVA (cost+adaos) | B16: =B12+B15 -> 13000
A17: TVA în PVA | B17: =B16*B14 -> 2730
A18: PVA total (371) | B18: =B16+B17 -> 15730
A19: TVA deductibilă (pe cost) | B19: =B12*B14 -> 2100
A21: 3. Conturi
A22: Cont stoc (371.gest.cotă) | B22: 371.AM.21
A23: Cont adaos (378) | B23: 378.AM.21
A24: Cont TVA neexigibilă (4428) | B24: 4428.AM
A25: Cont furnizor | B25: 401.RO
A26: Cont TVA deductibilă | B26: 4426
A27: Cont cheltuială (607) | B27: 607
A28: Cont venit (707) | B28: 707
A29: Cont TVA colectată | B29: 4427
A30: Cont casă / bancă | B30: 531.1
A31: Cont TVA de plată | B31: 4423
A33: 4. Corelații (auto)
A34: Corelație 1: 371×c/(100+c) =? | B34: =B18*B14/(1+B14) -> 2730
A35: Trebuie = 4428 | B35: =IF(ABS(B34-B17)<0.01,"OK — corelație 1 ține","EROARE") -> OK — corelație 1 ține
A36: Corelație 2: 707−607 =? | B36: =B16-B12 -> 3000
A37: Trebuie = adaos (rulaj D 378) | B37: =IF(ABS(B36-B15)<0.01,"OK — corelație 2 ține","EROARE") -> OK — corelație 2 ține
A39: 5. Sufix
A40: Sufix | B40: ="— amănunt " & B6 & " — " & B7 -> — amănunt AM.21 — 2026-07

Sheet Reguli_AMANUNT
A1: MOD_VANZ_AMANUNT — Reguli (tabele fixe)
A2: Regula e dată, nu formulă. Se editează doar când se schimbă politica de gestiune sau cotele.
A4: Tabel A — Secvența operațională
A5: Pas | B5: Cont Dr | C5: Cont Cr | D5: Sumă (sursă) | E5: Condiție | F5: Temei / observație
A6: 1 | B6: 371.gest.cotă | C6: 401 + 378 + 4428 | D6: PVA = cost+adaos+TVA_PVA | E6: La aprovizionare amănunt | F6: Stoc la preț de vânzare cu amănuntul
A7: 2 | B7: 4426 | C7: 401 | D7: cost × cotă | E7: Din factură furnizor | F7: TVA deductibilă ≠ TVA din PVA
A8: 3 | B8: 607 + 378 + 4428 | C8: 371.gest.cotă | D8: proporțional pe PVA vândut | E8: La vânzare / Z-report | F8: Descărcare proporțională (nu doar cost)
A9: 4 | B9: 531/512 | C9: 707 + 4427 | D9: bază + TVA = PVA vândut | E9: La vânzare | F9: Venit pe bază (cost+adaos), TVA colectată
A10: 5 | B10: 4427 | C10: 4426 + 4423 | D10: rulaje lunare | E10: La închidere TVA | F10: Vezi MOD_INCHIDERE_TVA
A11: 6 | B11: 707 + 4427 | C11: 411/531 | D11: proporțional retur | E11: La retur client | F11: Storno venit+TVA; apoi reîncarcă 371+378+4428 (F-40)
A13: Tabel B — Corelații de control (obligatorii pe cifre)
A14: ID | B14: Formulă | C14: Când | D14: Ce o rupe legitim | E14: Ce o rupe suspect | F14: Flux
A15: C-01 | B15: sold 371 × c/(100+c) = sold 4428 | C15: Pe gestiune+cotă, oricând | D15: Vânzare parțială, retur, transfer gestiuni | E15: 4428 omis; descărcare fără 378/4428 | F15: F-14, F-40, F-43
A16: C-02 | B16: 707 − 607 = rulaj D 378 | C16: Pe perioadă | D16: Retur, 709, discount furnizor pe stoc vândut | E16: 607 greșit; 378 nestins | F16: F-14, F-40, F-43
A18: Tabel C — Porți
A19: • ΣDr=ΣCr pe fiecare bloc (verificare cu ABS la global — erorile nu se anulează)
A20: • După vânzare integrală: sold 371=378=4428=0 pe gestiune
A21: • Vânzare parțială: C-01 pe soldul RĂMAS, nu pe rulajul de la intrare
A22: • Retur: reîncarcă proporțional 371+378+4428 — omisiunea 378/4428 = ruptură suspectă C-01

Sheet Jurnale_AMANUNT
A1: MOD_VANZ_AMANUNT — Jurnale
A3: Bloc 1 — Aprovizionare la PVA
A4: Data: | B4: =Declarații_AMANUNT!B8 -> 2026-07-05
A5: Nr | B5: Cont Dr | C5: Sumă Dr | D5: Descriere Dr | E5: Cont Cr | F5: Sumă Cr | G5: Descriere Cr
A6: 1 | B6: =Declarații_AMANUNT!B22 -> 371.AM.21 | C6: =Declarații_AMANUNT!B18 -> 15730 | D6: ="Intrare stoc la PVA " & Declarații_AMANUNT!B40 -> Intrare stoc la PVA — amănunt AM.21 — 2026-07 | E6: =Declarații_AMANUNT!B25 -> 401.RO | F6: =Declarații_AMANUNT!B12 -> 10000 | G6: ="Datorie furnizor (cost) " & Declarații_AMANUNT!B40 -> Datorie furnizor (cost) — amănunt AM.21 — 2026-07
A7: 2 | B7: 0 | C7: 0 | E7: =Declarații_AMANUNT!B23 -> 378.AM.21 | F7: =Declarații_AMANUNT!B15 -> 3000 | G7: ="Adaos comercial " & Declarații_AMANUNT!B40 -> Adaos comercial — amănunt AM.21 — 2026-07
A8: 3 | B8: 0 | C8: 0 | E8: =Declarații_AMANUNT!B24 -> 4428.AM | F8: =Declarații_AMANUNT!B17 -> 2730 | G8: ="TVA neexigibilă în PVA " & Declarații_AMANUNT!B40 -> TVA neexigibilă în PVA — amănunt AM.21 — 2026-07
A9: Check B1 (371 = cost+adaos+TVA PVA) | B9: =C6-(F6+F7+F8) -> 0 | C9: =IF(ABS(B9)<0.01,"OK","EROARE") -> OK
A11: Bloc 2 — TVA deductibilă din factură
A12: Nr | B12: Cont Dr | C12: Sumă Dr | D12: Descriere Dr | E12: Cont Cr | F12: Sumă Cr | G12: Descriere Cr
A13: 1 | B13: =Declarații_AMANUNT!B26 -> 4426 | C13: =Declarații_AMANUNT!B19 -> 2100 | D13: ="TVA deductibilă pe cost " & Declarații_AMANUNT!B40 -> TVA deductibilă pe cost — amănunt AM.21 — 2026-07 | E13: =Declarații_AMANUNT!B25 -> 401.RO | F13: =Declarații_AMANUNT!B19 -> 2100 | G13: ="Datorie furnizor (TVA) " & Declarații_AMANUNT!B40 -> Datorie furnizor (TVA) — amănunt AM.21 — 2026-07
A14: Check B2 | B14: =C13-F13 -> 0 | C14: =IF(ABS(B14)<0.01,"OK","EROARE") -> OK
A16: Bloc 3 — Descărcare gestiune la PVA
A17: Data: | B17: =Declarații_AMANUNT!B9 -> 2026-07-31
A18: Nr | B18: Cont Dr | C18: Sumă Dr | D18: Descriere Dr | E18: Cont Cr | F18: Sumă Cr | G18: Descriere Cr
A19: 1 | B19: =Declarații_AMANUNT!B27 -> 607 | C19: =Declarații_AMANUNT!B12 -> 10000 | D19: ="Descărcare la cost " & Declarații_AMANUNT!B40 -> Descărcare la cost — amănunt AM.21 — 2026-07 | E19: =Declarații_AMANUNT!B22 -> 371.AM.21 | F19: =Declarații_AMANUNT!B18 -> 15730 | G19: ="Stingere stoc PVA " & Declarații_AMANUNT!B40 -> Stingere stoc PVA — amănunt AM.21 — 2026-07
A20: 2 | B20: =Declarații_AMANUNT!B23 -> 378.AM.21 | C20: =Declarații_AMANUNT!B15 -> 3000 | D20: ="Stingere adaos " & Declarații_AMANUNT!B40 -> Stingere adaos — amănunt AM.21 — 2026-07 | E20: 0 | F20: 0
A21: 3 | B21: =Declarații_AMANUNT!B24 -> 4428.AM | C21: =Declarații_AMANUNT!B17 -> 2730 | D21: ="Stingere TVA neexigibilă " & Declarații_AMANUNT!B40 -> Stingere TVA neexigibilă — amănunt AM.21 — 2026-07 | E21: 0 | F21: 0
A22: Check B3 | B22: =(C19+C20+C21)-F19 -> 0 | C22: =IF(ABS(B22)<0.01,"OK","EROARE") -> OK
A24: Bloc 4 — Venit + TVA colectată
A25: Nr | B25: Cont Dr | C25: Sumă Dr | D25: Descriere Dr | E25: Cont Cr | F25: Sumă Cr | G25: Descriere Cr
A26: 1 | B26: =Declarații_AMANUNT!B30 -> 531.1 | C26: =Declarații_AMANUNT!B18 -> 15730 | D26: ="Încasare amănunt " & Declarații_AMANUNT!B40 -> Încasare amănunt — amănunt AM.21 — 2026-07 | E26: =Declarații_AMANUNT!B28 -> 707 | F26: =Declarații_AMANUNT!B16 -> 13000 | G26: ="Venit amănunt (bază) " & Declarații_AMANUNT!B40 -> Venit amănunt (bază) — amănunt AM.21 — 2026-07
A27: 2 | B27: 0 | C27: 0 | E27: =Declarații_AMANUNT!B29 -> 4427 | F27: =Declarații_AMANUNT!B17 -> 2730 | G27: ="TVA colectată " & Declarații_AMANUNT!B40 -> TVA colectată — amănunt AM.21 — 2026-07
A28: Check B4 | B28: =C26-(F26+F27) -> 0 | C28: =IF(ABS(B28)<0.01,"OK","EROARE") -> OK
A30: Bloc 5 — Închidere TVA
A31: Nr | B31: Cont Dr | C31: Sumă Dr | D31: Descriere Dr | E31: Cont Cr | F31: Sumă Cr | G31: Descriere Cr
A32: 1 | B32: =Declarații_AMANUNT!B29 -> 4427 | C32: =Declarații_AMANUNT!B17 -> 2730 | D32: ="Închidere TVA colectată " & Declarații_AMANUNT!B40 -> Închidere TVA colectată — amănunt AM.21 — 2026-07 | E32: =Declarații_AMANUNT!B26 -> 4426 | F32: =Declarații_AMANUNT!B19 -> 2100 | G32: ="Închidere TVA deductibilă " & Declarații_AMANUNT!B40 -> Închidere TVA deductibilă — amănunt AM.21 — 2026-07
A33: 2 | B33: 0 | C33: 0 | E33: =Declarații_AMANUNT!B31 -> 4423 | F33: =Declarații_AMANUNT!B17-Declarații_AMANUNT!B19 -> 630 | G33: ="TVA de plată " & Declarații_AMANUNT!B40 -> TVA de plată — amănunt AM.21 — 2026-07
A34: Check B5 | B34: =C32-(F32+F33) -> 0 | C34: =IF(ABS(B34)<0.01,"OK","EROARE") -> OK
A36: Check global | B36: =ABS(B9)+ABS(B14)+ABS(B22)+ABS(B28)+ABS(B34) -> 0 | C36: =IF(B36<0.01,"OK — toate blocurile se închid","EROARE — cel puțin un bloc dezechilibrat") -> OK — toate blocurile se închid
A38: Corelații (din Declarații)
A39: =Declarații_AMANUNT!B35 -> OK — corelație 1 ține
A40: =Declarații_AMANUNT!B37 -> OK — corelație 2 ține

Sheet NotaExport_AMANUNT
A1: MOD_VANZ_AMANUNT — Notă pentru import
A4: Nr | B4: Bloc | C4: Data | D4: Cont Dr | E4: Cont Cr | F4: Sumă | G4: Descriere | H4: Document | I4: Include
A5: 1 | B5: B1 | C5: =Declarații_AMANUNT!B8 -> 2026-07-05 | D5: =Jurnale_AMANUNT!B6 -> 371.AM.21 | E5: =Jurnale_AMANUNT!E6 -> 401.RO | F5: =Jurnale_AMANUNT!F6 -> 10000 | G5: Cost | H5: Amănunt | I5: =IF(AND(ISNUMBER(F5),F5>0),"DA","NU") -> DA
A6: 2 | B6: B1 | C6: =Declarații_AMANUNT!B8 -> 2026-07-05 | D6: =Jurnale_AMANUNT!B6 -> 371.AM.21 | E6: =Jurnale_AMANUNT!E7 -> 378.AM.21 | F6: =Jurnale_AMANUNT!F7 -> 3000 | G6: Adaos | H6: Amănunt | I6: =IF(AND(ISNUMBER(F6),F6>0),"DA","NU") -> DA
