Workbook
Name param_proc_rezerva: Parametri!$B$18
Name param_plafon_rezerva: Parametri!$B$19
Name param_prag_mf: Parametri!$B$20
Name param_proc_vehicul: Parametri!$B$21
Name param_plafon_amo_auto: Parametri!$B$22
Name param_cota_cas: Parametri!$B$23
Name param_cota_cass: Parametri!$B$24
Name param_cota_impozit: Parametri!$B$25
Name param_cota_cam: Parametri!$B$26
Name param_cota_impozit_profit: Parametri!$B$27
Name param_cota_impozit_dividend: Parametri!$B$28

Sheet Instructiuni
A1: MODULE DECLARATIVE — instrucțiuni de utilizare
A3: Ce este acest fișier
A4: Cele 23 module declarative care execută fluxurile din „Plan de conturi”. Fluxul explică de ce; modulul face înregistrarea. Completezi câteva variabile într-o foaie de input și ies jurnalele și nota de export.
A5: Toate foile se generează din depozit, la fiecare build. Nu se editează structura aici: o modificare făcută în fișier se pierde la următorul `make`.
A7: Cum se folosește ORICE modul
A8: 1. CatalogModule — pune Activ=DA pe modulele de care ai nevoie luna asta.
A9: 2. Declarații_<MODUL> — completează doar celulele galbene cu scris albastru. Restul sunt formule.
A10: 3. Reguli_<MODUL> — nu se completează. E regula contabilă sau fiscală, cu temeiul ei, plus ce anume rupe corelațiile. Se citește când rezultatul te surprinde.
A11: 4. Jurnale_<MODUL> — verifică fiecare celulă Check. Trebuie OK înainte de a lua rezultatul de bun.
A12: 5. NotaExport_<MODUL> — filtrează Include=DA și înregistrează în program.
A14: Două tipare de foi
A15: Declarații → Reguli → Jurnale → NotaExport — tiparul obișnuit, pentru modulele care produc înregistrări.
... A24: Modulul nu inventează conturi. Folosește doar conturile din politica declarată + rolurile din Plan de conturi. Porțile de calitate (ΣDr=ΣCr, stare terminală, pas revelator) rămân aceleași ca în foaia Fluxuri.

Sheet Parametri
A1: PARAMETRI GLOBALI — un singur loc pentru identitate și setări comune
A2: Completezi o dată. Toate foile Declarații_* citesc de aici. La client nou: schimbi doar aici.
A4: Identitate (date demonstrative — înlocuiește la utilizare reală)
A5: Denumire societate | B5: SC EXEMPLU SRL
A6: CUI | B6: RO00000000
A7: Luna curentă (YYYY-MM) | B7: 2026-07
A9: Setări contabile comune
A10: Cotă TVA standard | B10: 0.21
A11: Cotă TVA redusă | B11: 0.11
A13: Notă: valorile de mai sus sunt placeholder. Nu sunt date reale de client. Modulele Declarații_* referențiază Parametri!B5 / B6 / B7.
A15: Parametri globali — referiți prin nume definit (param_*)
A16: Numele din coloana C se folosește direct în formule. Schimbă valoarea aici o singură dată; toate modulele o preiau.
A17: Parametru | B17: Valoare | C17: Nume definit · temei
A18: Procent rezervă legală (din profitul brut) | B18: 0.05 | C18: param_proc_rezerva — art. 26 alin. (1) lit. a) Cod fiscal
A19: Plafon rezervă legală (din capitalul vărsat) | B19: 0.2 | C19: param_plafon_rezerva — art. 183 Legea 31/1990 — capital subscris ȘI VĂRSAT
A20: Prag mijloc fix (lei) | B20: 5000 | C20: param_prag_mf — OUG 8/2026, de la 25.02.2026; se actualizează anual cu inflația
A21: Procent de deducere vehicule (regim mixt) | B21: 0.5 | C21: param_proc_vehicul — art. 298 CF (TVA) și art. 25 alin. (3) lit. l) CF (cheltuieli)
A22: Plafon amortizare autoturism (lei/lună) | B22: 1500 | C22: param_plafon_amo_auto — art. 28 alin. (14) CF — NU se cumulează cu limitarea de 50%
A23: CAS — pensie (pe brut) | B23: 0.25 | C23: param_cota_cas — art. 138 CF
A24: CASS — sănătate (pe brut + tichete) | B24: 0.1 | C24: param_cota_cass — art. 156 CF — tichetele intră în bază, dar NU în baza CAS
A25: Impozit pe venit (pe venit net + tichete) | B25: 0.1 | C25: param_cota_impozit — art. 78 CF
A26: CAM — asigurare de muncă (pe brut) | B26: 0.0225 | C26: param_cota_cam — art. 220^3 CF — cheltuiala angajatorului, nu reținere
A27: Impozit pe profit | B27: 0.16 | C27: param_cota_impozit_profit — art. 17 CF — folosit la cuantificarea efectului unei cheltuieli nedeductibile
A28: Impozit pe dividende | B28: 0.16 | C28: param_cota_impozit_dividend — art. 43 CF, modificat prin L. 141/2025 — cota urmează data DISTRIBUIRII

Sheet CatalogModule
A1: CATALOG MODULE DECLARATIVE — sumonare fluxuri
A2: Bifează / activează modulele pentru luna curentă. Fiecare modul activ își trage variabilele din Declarații și emite blocuri în Jurnale + NotaExport.
A3: Arhitectură: Declarații (input galben) → Reguli (tabele fixe) → Registru (dacă e cazul) → Jurnale (auto) → NotaExport (1 rând = 1 înregistrare).
A5: Activ | B5: Cod modul | C5: Flux(uri) acoperite | D5: Tip | E5: Variabile obligatorii | F5: Porți declarative | G5: Blocuri jurnal emise | H5: Status
A6: DA | B6: MOD_INCHIDERE_TVA | C6: F-405 | D6: Lunar (fără linii) | E6: Rulaj 4426, Rulaj 4427, Luna | F6: — | G6: B1 Închidere 4426/4427 → 4423/4424 | H6: IMPLEMENTAT
A7: NU | B7: MOD_APROV_TRANZIT | C7: F-302 | D7: Eveniment + stingere | E7: Sumă netă, TVA, Cont stoc, Furnizor, Data factură, Data recepție | F7: Tranzit vs. direct | G7: B1 Factură→32x; B2 Recepție 30x=32x | H7: IMPLEMENTAT
A8: DA | B8: MOD_SALARII | C8: F-413 | D8: Lunar, pe registru de angajați | E8: Brut, tichete, avans, pe angajat; cotele CAS/CASS/impozit/CAM | F8: Fără deducere personală și fără facilități sectoriale — vezi Reguli, tabelul C | G8: B1 Plata avansului; B2 Costurile lunii; B3 Plăți (net, taxe, CAM) | H8: IMPLEMENTAT
A9: NU | B9: MOD_DECONT | C9: F-502 | D9: Pe decont | E9: Linii de decont (furnizor, sumă, natură, tip document, CUI), avans, cote | F9: Plătitor de TVA; % deducere vehicule; matricea document × CUI | G9: B1 Avans; B2 Cheltuieli + TVA; B3 Regularizare avans; B4 Plată / restituire | H9: IMPLEMENTAT
A10: NU | B10: MOD_LEASING_FIN | C10: F-108 | D10: Pe contract + lunar | E10: Valoare contract, avans, rată, dobândă, comision, CASCO, regim vehicul, durată | F10: MIXT 50% / EXCLUSIV 100% / EXCEPTAT; capitalizare vs. cheltuială pentru TVA nededusă | G10: B1 Avans; B2 TVA avans; B3 Intrare + 167; B4 Stingere avans; B5 Factura lunară; B6 Corecție TVA 50%; B7 Limitare 50% cheltuieli; B8 Amortizare | H10: IMPLEMENTAT
A11: NU | B11: MOD_VANZ_AMANUNT | C11: F-316, F-318, F-317 | D11: Pe gestiune + cotă | E11: Cost, Adaos %, Cotă TVA, Gestiune | F11: En-gros vs Amănunt | G11: B1 Aprovizionare PVA; B2 TVA ded.; B3 Descărcare; B4 Venit; B5 Închidere TVA | H11: IMPLEMENTAT
A12: NU | B12: MOD_TVA_INCASARE | C12: F-401 | D12: Pe factură | E12: Sumă netă, TVA, Tip (achiziție/vânzare), Data plată/încasare | F12: 4428.INC activ | G12: B1 Factură→4428.INC; B2 Plată/Încasare→4426/4427 | H12: IMPLEMENTAT
A13: NU | B13: MOD_INCHIDERE_EX | C13: F-104 | D13: Anual | E13: Rulaje cls.6, Rulaje cls.7, Impozit/IMCA | F13: — | G13: B1 Închidere 6xx; B2 Închidere 7xx; B3 Impozit; B4 Report 117 | H13: IMPLEMENTAT
A14: NU | B14: MOD_INTERMEDIAR | C14: F-408, F-501, F-411 | D14: Eveniment discret | E14: Sumă, Cont intermediar (408/418/581/473), Cont final, Document | F14: Un set de Declarații = un tip + o operațiune; modulul nu amestecă tipurile | G14: B1 Deschidere intermediar; B2 Stingere | H14: IMPLEMENTAT
A15: NU | B15: MOD_NEUTRALIZARE | C15: F-311, F-312, F-209 | D15: Pe stadiu producție | E15: Cost acumulat, Cont stoc (331/332/231), Cont venit (711/712/722) | F15: — | G15: B1 Costuri→stoc; B2 Neutralizare; B3 Finalizare/livrare | H15: IMPLEMENTAT
A17: NU | B17: MOD_CAPITALURI | C17: F-103, F-105 | D17: Anual (31.12 + ianuarie) | E17: Sold 121, rulaj 691, capital vărsat 1012, sold 1061, pierdere reportată | F17: Dublu plafon rezervă legală; pierdere reportată de acoperit înainte de dividende | G17: B1 Rezervă legală; B2 Închidere 121; B3 Dividende; B4 Corecție 1174 | H17: IMPLEMENTAT
... A29: DA | B29: MOD_INCHIDERE_LUNARA | C29: F-422, F-413 | D29: Lunar, pe balanța de verificare | E29: Rulaj debitor, rulaj creditor și sold pentru conturile cu cadență; restul de plată de pe stat; soldul din decontul de TVA | F29: Verifică solduri, nu documente — vezi Reguli, tabelul C | G29: V1 Obligații lunare (rulaj = sold); V2 Datoria față de salariați; V3 Conturi care trebuie golite; V4 Verificarea CAM pe cifre | H29: IMPLEMENTAT
A31: REGULĂ DE SUMONARE
A32: 1. În CatalogModule setezi Activ=DA doar pe modulele necesare lunii.
A33: 2. Completezi variabilele din foaia Declarații_Modul (galben).
A34: 3. Jurnalele și NotaExport se populează automat doar pentru modulele active.
A35: 4. Verifici Check=0 pe fiecare bloc; filtrezi NotaExport pe Include=DA și imporți.
A36: Nu se creează conturi noi din modul — se folosesc doar conturile din politica declarată + planul de conturi pe rol.

Sheet Declarații_CAPITALURI
A1: MOD_CAPITALURI — Declarații (input)
A2: Completează doar celulele galbene cu scris albastru. Restul sunt formule sau text fix.
A4: 1. Antet
A5: Societate | B5: =Parametri!B5 -> SC EXEMPLU SRL
A6: Exercițiu financiar (anul N) | B6: 2026
A7: Data notei de repartizare (31.12.N) | B7: 2026-12-31
A8: Data notei de închidere (ianuarie N+1) | B8: 2027-01-05
A10: 2. Date din balanță
A11: Sold creditor 121 (după închiderea cls. 6 și 7) | B11: 2500
A12: Rulaj 691 (cheltuiala cu impozitul pe profit) | B12: 0
A13: Capital social subscris ȘI VĂRSAT (1012) | B13: 5000 | C13: Partea nevărsată din 1011 NU intră în plafon
A14: Sold 1061 deja constituit | B14: 0
A15: Pierdere contabilă reportată de acoperit (1171 sold D) | B15: 0
A16: Capitaluri proprii (activ net) din bilanț | B16: 5000 | C16: Se ia din bilanț, nu din balanță — vezi C-20
A18: 3. Rezerva legală — dublul plafon (nu edita)
A19: Profit contabil brut (121 + 691) | B19: =B11+B12 -> 2500
A20: Limita fiscală: 5% din profitul brut | B20: =B19*param_proc_rezerva -> 125 | C20: art. 26 alin. (1) lit. a) Cod fiscal
A21: Limita juridică: 20% din capitalul vărsat | B21: =B13*param_plafon_rezerva -> 1000 | C21: art. 183 Legea 31/1990
A22: Spațiu rămas până la plafon | B22: =MAX(0,B21-B14) -> 1000
A23: Rezervă legală de constituit | B23: =MIN(B20,B22) -> 125
A24: Check plafon rezervă | B24: =B14+B23 -> 125 | C24: =IF(B14+B23<=B21+0.001,"OK — sub plafonul de 20%","EROARE — depășire plafon") -> OK — sub plafonul de 20%
A26: 4. Repartizare
A27: Profit rămas după rezerva legală | B27: =B11-B23 -> 2375
A28: Disponibil de distribuit ca dividende | B28: =MAX(0,B27-B15) -> 2375
A29: Check pierdere reportată | B29: =B15 -> 0 | C29: =IF(B15>0,"ATENȚIE — acoperă întâi pierderea reportată (L. 239/2025)","OK — fără pierdere reportată") -> OK — fără pierdere reportată
A30: Check activ net ≥ ½ capital social (C-20) | B30: =B16 -> 5000 | C30: =IF(B16>=B13/2,"OK — activ net ≥ ½ capital social","BLOCAJ — L. 239/2025: fără dividende și fără restituiri de împrumuturi de la asociați până la reîntregire") -> OK — activ net ≥ ½ capital social
A32: 5. Corecție erori exerciții anterioare (1174)
A33: Bază corecție, fără TVA (0 dacă nu e cazul) | B33: 0
A34: TVA aferentă corecției | B34: 0
A35: Check 1174 | B35: =B33 -> 0 | C35: =IF(B33=0,"— fără corecție în această perioadă","1174 se închide obligatoriu în 1171 până la 31.12 (C-18) + D101 rectificativ") -> — fără corecție în această perioadă
A37: 6. Conturi (din planul pe rol)
A38: Cont rezultat | B38: 121
A39: Cont repartizarea profitului | B39: 129
A40: Cont rezervă legală | B40: 1061
A41: Cont rezultat reportat (analitic pe an) | B41: 1171.2026
A42: Cont dividende de plată | B42: 457
A43: Cont corecții exerciții anterioare | B43: 1174
A44: Cont furnizor | B44: 401.RO
A45: Cont TVA deductibilă | B45: 4426
A47: 7. Sufix generat
...

Sheet Reguli_CAPITALURI
A1: MOD_CAPITALURI — Reguli (tabele fixe)
A2: Regula juridică/fiscală e dată, nu formulă. Se editează doar când se schimbă legea.
A4: Tabel A — Secvența de repartizare
A5: Pas | B5: Cont Dr | C5: Cont Cr | D5: Sumă (sursă) | E5: Condiție | F5: Temei / observație
A6: 1 | B6: 129 | C6: 1061 | D6: MIN(5% × profit brut; 20% × capital vărsat − rezerva existentă) | E6: La 31.12.N | F6: art. 183 L. 31/1990 + art. 26 alin. (1) lit. a) CF
A7: 2 | B7: 121 | C7: 129 | D7: cât rezerva constituită | E7: În ianuarie N+1 | F7: 129 are sold DEBITOR → se închide prin creditare. NU `129 = 1171`
A8: 3 | B8: 121 | C8: 1171 | D8: profit rămas nerepartizat | E8: În ianuarie N+1 | F8: 1171 cu analitic PE AN (C-21)
A9: 4 | B9: 1171 | C9: 457 | D9: dividende aprobate | E9: După hotărârea AGA | F9: Impozit 16% pentru distribuiri de la 01.01.2026 (L. 141/2025); cota urmează data DISTRIBUIRII, nu a plății
A10: 5 | B10: 1174 | C10: 401 | D10: corecție eroare semnificativă an anterior | E10: Dacă e cazul | F10: Nu prin 628. Obligatoriu D101 rectificativ
A11: 6 | B11: 1171 | C11: 1174 | D11: cât baza corecției | E11: După AGA | F11: 1174 e tranzitoriu — nu poate rămâne cu sold (C-18)
A13: Tabel B — Ordinea condițiilor înainte de dividende
A14: # | B14: Condiție | C14: Efect dacă nu e îndeplinită | F14: Temei
A15: 1 | B15: Rezerva legală constituită | C15: Nu se pot distribui dividende | F15: art. 183 L. 31/1990
A16: 2 | B16: Pierderea contabilă reportată acoperită integral | C16: Nu se pot distribui dividende | F16: art. 67 L. 31/1990
A17: 3 | B17: Activ net ≥ ½ din capitalul social subscris | C17: Blocaj dividende ȘI blocaj restituire împrumuturi de la asociați; amenzi 10.000–300.000 lei; răspundere solidară pentru obligațiile fiscale | F17: L. 239/2025 (modifică L. 31/1990)
A19: Tabel C — Porți de calitate
A20: • ΣDr = ΣCr pe fiecare bloc
A21: • După înregistrare: sold 121 = 0 și sold 129 = 0 (C-16)
A22: • Sold 1061 ≤ 20% × capital vărsat (C-17)
A23: • Sold 1174 = 0 la 31.12 (C-18)
A24: • 1171 are analitic pe an, cu sens D/C explicit (C-21)
A25: • Modulul nu creează conturi noi — folosește conturile din Declarații

Sheet Jurnale_CAPITALURI
A1: MOD_CAPITALURI — Jurnale (generate automat)
A2: Nu se scrie nimic manual. Toate sumele și descrierile derivă din Declarații_CAPITALURI.
A4: Bloc 1 — Constituirea rezervei legale (31.12.N)
A5: Data jurnal: | B5: =Declarații_CAPITALURI!B7 -> 2026-12-31
A7: Nr | B7: Cont Dr | C7: Sumă Dr | D7: Descriere Dr | E7: Cont Cr | F7: Sumă Cr | G7: Descriere Cr
A8: 1 | B8: =Declarații_CAPITALURI!B39 -> 129 | C8: =Declarații_CAPITALURI!B23 -> 125 | D8: ="Repartizare profit la rezerva legală " & Declarații_CAPITALURI!B48 -> Repartizare profit la rezerva legală — repartizare rezultat 2026 | E8: =Declarații_CAPITALURI!B40 -> 1061 | F8: =Declarații_CAPITALURI!B23 -> 125 | G8: ="Rezervă legală constituită " & Declarații_CAPITALURI!B48 -> Rezervă legală constituită — repartizare rezultat 2026
A10: Bloc 2 — Închiderea contului 121 (ianuarie N+1)
A11: Data jurnal: | B11: =Declarații_CAPITALURI!B8 -> 2027-01-05
A13: Nr | B13: Cont Dr | C13: Sumă Dr | D13: Descriere Dr | E13: Cont Cr | F13: Sumă Cr | G13: Descriere Cr
A14: 1 | B14: =Declarații_CAPITALURI!B38 -> 121 | C14: =Declarații_CAPITALURI!B23 -> 125 | D14: ="Închidere 121 — partea repartizată " & Declarații_CAPITALURI!B48 -> Închidere 121 — partea repartizată — repartizare rezultat 2026 | E14: =Declarații_CAPITALURI!B39 -> 129 | F14: =Declarații_CAPITALURI!B23 -> 125 | G14: ="Stingere repartizare " & Declarații_CAPITALURI!B48 -> Stingere repartizare — repartizare rezultat 2026
A15: 2 | B15: =Declarații_CAPITALURI!B38 -> 121 | C15: =Declarații_CAPITALURI!B27 -> 2375 | D15: ="Închidere 121 — profit reportat " & Declarații_CAPITALURI!B48 -> Închidere 121 — profit reportat — repartizare rezultat 2026 | E15: =Declarații_CAPITALURI!B41 -> 1171.2026 | F15: =Declarații_CAPITALURI!B27 -> 2375 | G15: ="Report rezultat pe an " & Declarații_CAPITALURI!B48 -> Report rezultat pe an — repartizare rezultat 2026
A17: Bloc 3 — Dividende (după hotărârea AGA)
A18: Nr | B18: Cont Dr | C18: Sumă Dr | D18: Descriere Dr | E18: Cont Cr | F18: Sumă Cr | G18: Descriere Cr
A19: 1 | B19: =Declarații_CAPITALURI!B41 -> 1171.2026 | C19: =Declarații_CAPITALURI!B28 -> 2375 | D19: ="Dividende aprobate AGA " & Declarații_CAPITALURI!B48 -> Dividende aprobate AGA — repartizare rezultat 2026 | E19: =Declarații_CAPITALURI!B42 -> 457 | F19: =Declarații_CAPITALURI!B28 -> 2375 | G19: ="Dividende de plată " & Declarații_CAPITALURI!B48 -> Dividende de plată — repartizare rezultat 2026
A21: Bloc 4 — Corecție eroare exercițiu anterior (1174)
A22: Nr | B22: Cont Dr | C22: Sumă Dr | D22: Descriere Dr | E22: Cont Cr | F22: Sumă Cr | G22: Descriere Cr
A23: 1 | B23: =Declarații_CAPITALURI!B43 -> 1174 | C23: =Declarații_CAPITALURI!B33 -> 0 | D23: ="Corecție eroare exercițiu anterior " & Declarații_CAPITALURI!B48 -> Corecție eroare exercițiu anterior — repartizare rezultat 2026 | E23: =Declarații_CAPITALURI!B44 -> 401.RO | F23: =Declarații_CAPITALURI!B33 -> 0 | G23: ="Datorie furnizor din corecție " & Declarații_CAPITALURI!B48 -> Datorie furnizor din corecție — repartizare rezultat 2026
A24: 2 | B24: =Declarații_CAPITALURI!B45 -> 4426 | C24: =Declarații_CAPITALURI!B34 -> 0 | D24: ="TVA din corecție — se deduce în decontul curent " & Declarații_CAPITALURI!B48 -> TVA din corecție — se deduce în decontul curent — repartizare rezultat 2026 | E24: =Declarații_CAPITALURI!B44 -> 401.RO | F24: =Declarații_CAPITALURI!B34 -> 0 | G24: ="Datorie furnizor — TVA " & Declarații_CAPITALURI!B48 -> Datorie furnizor — TVA — repartizare rezultat 2026
A25: 3 | B25: =Declarații_CAPITALURI!B41 -> 1171.2026 | C25: =Declarații_CAPITALURI!B33 -> 0 | D25: ="Închiderea contului tranzitoriu 1174 " & Declarații_CAPITALURI!B48 -> Închiderea contului tranzitoriu 1174 — repartizare rezultat 2026 | E25: =Declarații_CAPITALURI!B43 -> 1174 | F25: =Declarații_CAPITALURI!B33 -> 0 | G25: ="Stingere 1174 " & Declarații_CAPITALURI!B48 -> Stingere 1174 — repartizare rezultat 2026
A27: Sumar și controale
A28: Total Dr | B28: =C8+C14+C15+C19+C23+C24+C25 -> 5000
A29: Total Cr | B29: =F8+F14+F15+F19+F23+F24+F25 -> 5000
A30: Check Σ (structural) | B30: =B28-B29 -> 0 | C30: =IF(ABS(B28-B29)<0.01,"OK — notele se închid","EROARE") -> OK — notele se închid
A31: Check închidere 121 (C-16) | B31: =Declarații_CAPITALURI!B11-(C14+C15) -> 0 | C31: =IF(ABS(Declarații_CAPITALURI!B11-(C14+C15))<0.01,"OK — 121 se închide integral","EROARE — 121 rămâne cu sold") -> OK — 121 se închide integral
A32: Check plafon rezervă (C-17) | B32: =Declarații_CAPITALURI!B14+C8 -> 125 | C32: =IF(Declarații_CAPITALURI!B14+C8<=Declarații_CAPITALURI!B21+0.001,"OK — sub 20% din capitalul vărsat","EROARE — depășire plafon") -> OK — sub 20% din capitalul vărsat
A33: Check 1174 (C-18) | B33: =C23-C25 -> 0 | C33: =IF(ABS(C23-C25)<0.01,"OK — 1174 se închide în 1171","EROARE — 1174 rămâne cu sold") -> OK — 1174 se închide în 1171
A34: Stare terminală așteptată: sold 121 = 0, sold 129 = 0, sold 1174 = 0, sold 1061 ≤ 20% × capital vărsat, 1171 cu analitic pe an.

Sheet NotaExport_CAPITALURI
A1: MOD_CAPITALURI — Notă pentru import (1 rând = 1 înregistrare)
A2: Filtrează pe coloana Include = DA înainte de import. Echilibrul se verifică pe bloc în Jurnale, nu pe totalul listei.
A4: Nr | B4: Bloc | C4: Data | D4: Cont Dr | E4: Cont Cr | F4: Sumă | G4: Descriere | H4: Document | I4: Include
A5: 1 | B5: Bloc 1 — Rezervă legală | C5: =Declarații_CAPITALURI!B7 -> 2026-12-31 | D5: =Jurnale_CAPITALURI!B8 -> 129 | E5: =Jurnale_CAPITALURI!E8 -> 1061 | F5: =Jurnale_CAPITALURI!C8 -> 125 | G5: =Jurnale_CAPITALURI!D8 -> Repartizare profit la rezerva legală — repartizare rezultat 2026 | H5: Notă contabilă 31.12 | I5: =IF(F5>0,"DA","NU") -> DA
A6: 2 | B6: Bloc 2 — Închidere 121 | C6: =Declarații_CAPITALURI!B8 -> 2027-01-05 | D6: =Jurnale_CAPITALURI!B14 -> 121 | E6: =Jurnale_CAPITALURI!E14 -> 129 | F6: =Jurnale_CAPITALURI!C14 -> 125 | G6: =Jurnale_CAPITALURI!D14 -> Închidere 121 — partea repartizată — repartizare rezultat 2026 | H6: Notă de închidere | I6: =IF(F6>0,"DA","NU") -> DA
A7: 3 | B7: Bloc 2 — Închidere 121 | C7: =Declarații_CAPITALURI!B8 -> 2027-01-05 | D7: =Jurnale_CAPITALURI!B15 -> 121 | E7: =Jurnale_CAPITALURI!E15 -> 1171.2026 | F7: =Jurnale_CAPITALURI!C15 -> 2375 | G7: =Jurnale_CAPITALURI!D15 -> Închidere 121 — profit reportat — repartizare rezultat 2026 | H7: Notă de închidere | I7: =IF(F7>0,"DA","NU") -> DA
A8: 4 | B8: Bloc 3 — Dividende | C8: =Declarații_CAPITALURI!B8 -> 2027-01-05 | D8: =Jurnale_CAPITALURI!B19 -> 1171.2026 | E8: =Jurnale_CAPITALURI!E19 -> 457 | F8: =Jurnale_CAPITALURI!C19 -> 2375 | G8: =Jurnale_CAPITALURI!D19 -> Dividende aprobate AGA — repartizare rezultat 2026 | H8: Hotărâre AGA | I8: =IF(F8>0,"DA","NU") -> DA
A9: 5 | B9: Bloc 4 — Corecție 1174 | C9: =Declarații_CAPITALURI!B8 -> 2027-01-05 | D9: =Jurnale_CAPITALURI!B23 -> 1174 | E9: =Jurnale_CAPITALURI!E23 -> 401.RO | F9: =Jurnale_CAPITALURI!C23 -> 0 | G9: =Jurnale_CAPITALURI!D23 -> Corecție eroare exercițiu anterior — repartizare rezultat 2026 | H9: Factură an anterior | I9: =IF(F9>0,"DA","NU") -> NU
A10: 6 | B10: Bloc 4 — Corecție 1174 | C10: =Declarații_CAPITALURI!B8 -> 2027-01-05 | D10: =Jurnale_CAPITALURI!B24 -> 4426 | E10: =Jurnale_CAPITALURI!E24 -> 401.RO | F10: =Jurnale_CAPITALURI!C24 -> 0 | G10: =Jurnale_CAPITALURI!D24 -> TVA din corecție — se deduce în decontul curent — repartizare rezultat 2026 | H10: Factură an anterior | I10: =IF(F10>0,"DA","NU") -> NU
A11: 7 | B11: Bloc 4 — Corecție 1174 | C11: =Declarații_CAPITALURI!B8 -> 2027-01-05 | D11: =Jurnale_CAPITALURI!B25 -> 1171.2026 | E11: =Jurnale_CAPITALURI!E25 -> 1174 | F11: =Jurnale_CAPITALURI!C25 -> 0 | G11: =Jurnale_CAPITALURI!D25 -> Închiderea contului tranzitoriu 1174 — repartizare rezultat 2026 | H11: Notă contabilă | I11: =IF(F11>0,"DA","NU") -> NU
A13: Rânduri de importat (Include=DA) | B13: =COUNTIF(I5:I11,"DA") -> 4
A14: Check global (trebuie 0) | B14: =Jurnale_CAPITALURI!B28-Jurnale_CAPITALURI!B29 -> 0 | C14: =IF(ABS(Jurnale_CAPITALURI!B28-Jurnale_CAPITALURI!B29)<0.01,"OK","EROARE") -> OK

Sheet Declarații_INCHIDERE_EX
A1: MOD_INCHIDERE_EX — Declarații (input)
A2: Modul anual. Completezi rulajele din balanță (sau totaluri din SAGA). Jurnalele închid cls.6 → 121, cls.7 → 121, calculează impozit / IMCA, repartizează 129 și reportează 117.
A4: 1. Antet
A5: Societate | B5: =Parametri!B5 -> SC EXEMPLU SRL
A6: CUI | B6: =Parametri!B6 -> RO00000000
A7: An exercițiu | B7: 2026
A8: Data jurnal închidere (31.12) | B8: 2026-12-31
A10: 2. Rulaje de închis (din balanță / totaluri SAGA)
A11: Total rulaj debitor cls.6 (cheltuieli) | B11: 185000
A12: Total rulaj creditor cls.7 (venituri) | B12: 245000
A14: 3. Impozit pe profit / IMCA
A15: Regim (PROFIT / MICRO / IMCA) | B15: PROFIT
A16: Baza impozabilă (sau cifră afaceri IMCA) | B16: 60000
A17: Cotă (0.16 / 0.01 / 0.03 etc.) | B17: 0.16
A18: Impozit calculat | B18: =B16*B17 -> 9600
A19: Cont cheltuială impozit (691 / 697 / 4417) | B19: 691
A20: Cont datorie impozit (441 / 4417) | B20: 441
A22: 4. Repartizare rezultat
A23: Rezultat înainte de impozit (7−6) | B23: =B12-B11 -> 60000
A24: Rezultat net (după impozit) | B24: =B23-B18 -> 50400
A25: Repartizare la rezerve / dividende etc. (opțional) | B25: 0
A26: Reportat pe 117 (sold final 121/129) | B26: =B24-B25 -> 50400
A28: 5. Politică conturi rezultat
A29: Cont profit și pierdere | B29: 121
A30: Cont repartizare profit | B30: 129
A31: Cont rezultat reportat | B31: 117
A33: 6. Sufix
A34: Sufix | B34: ="— închidere exercițiu " & B7 -> — închidere exercițiu 2026
A36: 7. Control
A37: Modul activ? | B37: =IF(INDEX(CatalogModule!$A$1:$A$200,MATCH("MOD_INCHIDERE_EX",CatalogModule!$B$1:$B$200,0))="DA","ACTIV","INACTIV") -> INACTIV
A38: Notă | B38: În practică se închid conturile de cheltuieli/venituri pe analitice (sau pe grupe). Aici se lucrează pe totaluri — un singur rând pe clasă.

Sheet Reguli_INCHIDERE_EX
A1: MOD_INCHIDERE_EX — Reguli (tabele fixe)
A2: Secvența de închidere e standard OMFP 1802. Detalierea pe conturi analitice se face în SAGA; modulul lucrează pe totaluri de clasă pentru generarea notei de principiu.
A4: Tabel A — Secvența de închidere
A5: Pas | B5: Bloc | C5: Cont Dr | D5: Cont Cr | E5: Sumă | F5: Observație
A6: 1 | B6: B1 Închidere cheltuieli | C6: 121 | D6: 6xx (total) | E6: Rulaj D cls.6 | F6: Neutralizare rezultat — cheltuieli
A7: 2 | B7: B2 Închidere venituri | C7: 7xx (total) | D7: 121 | E7: Rulaj C cls.7 | F7: Neutralizare rezultat — venituri
A8: 3 | B8: B3 Impozit | C8: 691/697 | D8: 441/4417 | E8: Impozit calculat | F8: Cheltuială cu impozitul → datorie
A9: 4 | B9: B3b Închidere 691 | C9: 121 | D9: 691 | E9: Impozit | F9: Impozitul intră în rezultatul net
A10: 5 | B10: B4 Repartizare (opțional) | C10: 129 | D10: 106/457… | E10: Sumă repartizată | F10: Doar dacă AGA / decizie există
A11: 6 | B11: B5 Report | C11: 121 | D11: 117 | E11: Sold final 121 | F11: Dacă profit; invers dacă pierdere
A13: Tabel B — Conturi din plan pe rol
A14: Cont | B14: Denumire | C14: Rol | D14: Observație
A15: 121 | B15: Profit sau pierdere | C15: Colectare rezultat | D15: Se închide anual; fără sold după report pe 117
A16: 129 | B16: Repartizarea profitului | C16: Colectare / tranzit | D16: Se folosește doar la repartizare formală
A17: 117 | B17: Rezultatul reportat | C17: Patrimonial — Capital | D17: Sold permanent până la acoperire / repartizare
A18: 691 | B18: Cheltuieli cu impozitul pe profit | C18: Neutralizare rezultat | D18: Se închide în 121
A19: 697 | B19: Cheltuieli cu impozitul pe venit micro | C19: Neutralizare rezultat | D19: Alternativă la 691
A20: 441 | B20: Impozit pe profit | C20: Patrimonial — Datorie | D20: Datorie către buget
A21: 4417 | B21: Impozit pe venit micro / alte impozite | C21: Patrimonial — Datorie | D21: Conform OMF actualizat
A23: Tabel C — Porți de calitate
A24: • ΣDr = ΣCr pe fiecare bloc
A25: • După B1+B2: sold 6xx = 0, sold 7xx = 0
A26: • Sold 121 înainte de report = rezultat net
A27: • După B5: sold 121 = 0, sold 117 reflectă reportul
A28: • Modulul nu înlocuiește D101 / declarația de impozit — produce doar nota contabilă
A30: Temei legal
A31: Ce se sprijină pe el | B31: Temei
A32: Veniturile și cheltuielile se închid prin 121 la sfârșitul exercițiului | B32: OMFP 1802/2014 — funcțiunea contului 121
A33: Cota de impozit pe profit | B33: art. 17 Cod fiscal
A34: Rezultatul rămas se reportează pe 117 până la repartizare sau acoperire | B34: OMFP 1802/2014 — funcțiunea contului 117

Sheet Jurnale_INCHIDERE_EX
A1: MOD_INCHIDERE_EX — Jurnale (generate automat)
A2: Toate sumele derivă din Declarații. În SAGA se detaliază pe conturi analitice; aici e nota de principiu pe totaluri de clasă.
A4: Data jurnal: | B4: =Declarații_INCHIDERE_EX!B8 -> 2026-12-31
A6: Bloc 1 — Închidere cheltuieli (cls.6 → 121)
A7: Nr | B7: Cont Dr | C7: Sumă Dr | D7: Descriere Dr | E7: Cont Cr | F7: Sumă Cr | G7: Descriere Cr
A8: 1 | B8: =Declarații_INCHIDERE_EX!B29 -> 121 | C8: =Declarații_INCHIDERE_EX!B11 -> 185000 | D8: ="Închidere cheltuieli cls.6 " & Declarații_INCHIDERE_EX!B34 -> Închidere cheltuieli cls.6 — închidere exercițiu 2026 | E8: 6xx | F8: =Declarații_INCHIDERE_EX!B11 -> 185000 | G8: ="Stingere rulaj cheltuieli " & Declarații_INCHIDERE_EX!B34 -> Stingere rulaj cheltuieli — închidere exercițiu 2026
A9: Check B1 | B9: =C8-F8 -> 0 | C9: =IF(ABS(B9)<0.01,"OK","EROARE") -> OK
A11: Bloc 2 — Închidere venituri (cls.7 → 121)
A12: Nr | B12: Cont Dr | C12: Sumă Dr | D12: Descriere Dr | E12: Cont Cr | F12: Sumă Cr | G12: Descriere Cr
A13: 1 | B13: 7xx | C13: =Declarații_INCHIDERE_EX!B12 -> 245000 | D13: ="Închidere venituri cls.7 " & Declarații_INCHIDERE_EX!B34 -> Închidere venituri cls.7 — închidere exercițiu 2026 | E13: =Declarații_INCHIDERE_EX!B29 -> 121 | F13: =Declarații_INCHIDERE_EX!B12 -> 245000 | G13: ="Stingere rulaj venituri " & Declarații_INCHIDERE_EX!B34 -> Stingere rulaj venituri — închidere exercițiu 2026
A14: Check B2 | B14: =C13-F13 -> 0 | C14: =IF(ABS(B14)<0.01,"OK","EROARE") -> OK
A16: Bloc 3 — Cheltuială cu impozitul + închiderea ei în 121
A17: Nr | B17: Cont Dr | C17: Sumă Dr | D17: Descriere Dr | E17: Cont Cr | F17: Sumă Cr | G17: Descriere Cr
A18: 1 | B18: =Declarații_INCHIDERE_EX!B19 -> 691 | C18: =Declarații_INCHIDERE_EX!B18 -> 9600 | D18: ="Cheltuială impozit " & Declarații_INCHIDERE_EX!B34 -> Cheltuială impozit — închidere exercițiu 2026 | E18: =Declarații_INCHIDERE_EX!B20 -> 441 | F18: =Declarații_INCHIDERE_EX!B18 -> 9600 | G18: ="Datorie impozit buget " & Declarații_INCHIDERE_EX!B34 -> Datorie impozit buget — închidere exercițiu 2026
A19: 2 | B19: =Declarații_INCHIDERE_EX!B29 -> 121 | C19: =Declarații_INCHIDERE_EX!B18 -> 9600 | D19: ="Închidere cheltuială impozit în rezultat " & Declarații_INCHIDERE_EX!B34 -> Închidere cheltuială impozit în rezultat — închidere exercițiu 2026 | E19: =Declarații_INCHIDERE_EX!B19 -> 691 | F19: =Declarații_INCHIDERE_EX!B18 -> 9600 | G19: ="Stingere 691 " & Declarații_INCHIDERE_EX!B34 -> Stingere 691 — închidere exercițiu 2026
A20: Check B3 | B20: =(C18+C19)-(F18+F19) -> 0 | C20: =IF(ABS(B20)<0.01,"OK","EROARE") -> OK
A22: Bloc 4 — Report rezultat net pe 117
A23: Nr | B23: Cont Dr | C23: Sumă Dr | D23: Descriere Dr | E23: Cont Cr | F23: Sumă Cr | G23: Descriere Cr
A24: 1 | B24: =IF(Declarații_INCHIDERE_EX!B26>=0,Declarații_INCHIDERE_EX!B29,Declarații_INCHIDERE_EX!B31) -> 121 | C24: =ABS(Declarații_INCHIDERE_EX!B26) -> 50400 | D24: =IF(Declarații_INCHIDERE_EX!B26>=0,"Report profit pe 117 ","Report pierdere pe 117 ") & Declarații_INCHIDERE_EX!B34 -> Report profit pe 117 — închidere exercițiu 2026 | E24: =IF(Declarații_INCHIDERE_EX!B26>=0,Declarații_INCHIDERE_EX!B31,Declarații_INCHIDERE_EX!B29) -> 117 | F24: =ABS(Declarații_INCHIDERE_EX!B26) -> 50400 | G24: =IF(Declarații_INCHIDERE_EX!B26>=0,"Rezultat reportat (profit) ","Rezultat reportat (pierdere) ") & Declarații_INCHIDERE_EX!B34 -> Rezultat reportat (profit) — închidere exercițiu 2026
A25: Check B4 | B25: =C24-F24 -> 0 | C25: =IF(ABS(B25)<0.01,"OK","EROARE") -> OK
A27: Stare terminală așteptată
A28: Sold 6xx=0 | Sold 7xx=0 | Sold 121=0 | Sold 691=0 | 441 = impozit datorat | 117 = rezultat net reportat
A30: Check global | B30: =ABS(B9)+ABS(B14)+ABS(B20)+ABS(B25) -> 0 | C30: =IF(B30<0.01,"OK — toate blocurile se închid","EROARE — cel puțin un bloc dezechilibrat") -> OK — toate blocurile se închid

Sheet NotaExport_INCHIDERE_EX
A1: MOD_INCHIDERE_EX — Notă pentru import
A2: Filtrează Include=DA. În SAGA se detaliază 6xx/7xx pe conturi individuale; aceste rânduri sunt nota de principiu.
A4: Nr | B4: Bloc | C4: Data | D4: Cont Dr | E4: Cont Cr | F4: Sumă | G4: Descriere | H4: Document | I4: Include
A5: 1 | B5: B1 Cheltuieli | C5: =Declarații_INCHIDERE_EX!B8 -> 2026-12-31 | D5: =Jurnale_INCHIDERE_EX!B8 -> 121 | E5: =Jurnale_INCHIDERE_EX!E8 -> 6xx | F5: =Jurnale_INCHIDERE_EX!C8 -> 185000 | G5: =Jurnale_INCHIDERE_EX!D8 -> Închidere cheltuieli cls.6 — închidere exercițiu 2026 | H5: Închidere exercițiu | I5: =IF(F5>0,"DA","NU") -> DA
A6: 2 | B6: B2 Venituri | C6: =Declarații_INCHIDERE_EX!B8 -> 2026-12-31 | D6: =Jurnale_INCHIDERE_EX!B13 -> 7xx | E6: =Jurnale_INCHIDERE_EX!E13 -> 121 | F6: =Jurnale_INCHIDERE_EX!C13 -> 245000 | G6: =Jurnale_INCHIDERE_EX!D13 -> Închidere venituri cls.7 — închidere exercițiu 2026 | H6: Închidere exercițiu | I6: =IF(F6>0,"DA","NU") -> DA
A7: 3 | B7: B3 Impozit | C7: =Declarații_INCHIDERE_EX!B8 -> 2026-12-31 | D7: =Jurnale_INCHIDERE_EX!B18 -> 691 | E7: =Jurnale_INCHIDERE_EX!E18 -> 441 | F7: =Jurnale_INCHIDERE_EX!C18 -> 9600 | G7: =Jurnale_INCHIDERE_EX!D18 -> Cheltuială impozit — închidere exercițiu 2026 | H7: Închidere exercițiu | I7: =IF(F7>0,"DA","NU") -> DA
A8: 4 | B8: B3 Înch.691 | C8: =Declarații_INCHIDERE_EX!B8 -> 2026-12-31 | D8: =Jurnale_INCHIDERE_EX!B19 -> 121 | E8: =Jurnale_INCHIDERE_EX!E19 -> 691 | F8: =Jurnale_INCHIDERE_EX!C19 -> 9600 | G8: =Jurnale_INCHIDERE_EX!D19 -> Închidere cheltuială impozit în rezultat — închidere exercițiu 2026 | H8: Închidere exercițiu | I8: =IF(F8>0,"DA","NU") -> DA
A9: 5 | B9: B4 Report 117 | C9: =Declarații_INCHIDERE_EX!B8 -> 2026-12-31 | D9: =Jurnale_INCHIDERE_EX!B24 -> 121 | E9: =Jurnale_INCHIDERE_EX!E24 -> 117 | F9: =Jurnale_INCHIDERE_EX!C24 -> 50400 | G9: =Jurnale_INCHIDERE_EX!D24 -> Report profit pe 117 — închidere exercițiu 2026 | H9: Închidere exercițiu | I9: =IF(F9>0,"DA","NU") -> DA
A11: Rânduri de importat | B11: =COUNTIF(I5:I9,"DA") -> 5
A12: Check global | B12: =Jurnale_INCHIDERE_EX!B30 -> 0 | C12: =IF(ABS(B12)<0.01,"OK","EROARE") -> OK

Sheet Declarații_PROVIZION
A1: MOD_PROVIZION — Declarații (input)
A2: Tipul provizionului comandă contul ȘI deductibilitatea. Valorile implicite reproduc monografia din F-106 (litigiu, 8.000 lei).
A4: 1. Antet
A5: Societate | B5: =Parametri!B5 -> SC EXEMPLU SRL
A6: Obiectul provizionului | B6: Litigiu comercial cu clientul X
A7: Data constituirii | B7: 2026-12-31 | C7: Exercițiul în care s-a NĂSCUT obligația, nu cel în care se plătește
A8: Data reluării | B8: 2027-04-30
A10: 2. Provizionul
A11: Tip (LITIGII / GARANTII / RESTRUCTURARE / IMPOZITE / TERMINARE / ALTE) | B11: LITIGII
A12: Sumă estimată | B12: 8000 | C12: Estimare credibilă la data bilanțului; se revizuiește la fiecare bilanț
A14: 3. Cheltuiala efectivă (anul următor)
A15: Sumă facturată efectiv | B15: 8000
A16: TVA pe factură | B16: =ROUND(B15*Parametri!B10,2) -> 1680
A18: 4. Calcul automat (nu edita)
A19: Cont provizion | B19: =IFERROR(VLOOKUP(B11,Reguli_PROVIZION!$A$6:$E$11,3,FALSE),"?") -> 1511
A20: Deductibil fiscal? | B20: =IFERROR(VLOOKUP(B11,Reguli_PROVIZION!$A$6:$E$11,4,FALSE),"?") -> NU
A21: Temei | B21: =IFERROR(VLOOKUP(B11,Reguli_PROVIZION!$A$6:$E$11,5,FALSE),"tip necunoscut") -> art. 26 CF nu îl enumeră printre cele deductibile
A22: Efect fiscal la constituire | B22: =IF(B20="DA",0,ROUND(B12*param_cota_impozit_profit,2)) -> 1280 | C22: Impozit suplimentar de plătit dacă provizionul e nedeductibil
A24: 5. Conturi
A25: Cont cheltuială cu provizioane | B25: 6812
A26: Cont venit din reluarea provizioanelor | B26: 7812
A27: Cont cheltuială efectivă | B27: 628 | C27: Contul real al cheltuielii — NU contul de provizion
A28: Cont TVA deductibilă | B28: 4426
A29: Cont furnizor | B29: 401
A31: 6. Controale
A32: Check tip recunoscut | B32: =B19 -> 1511 | C32: =IF(B19="?","EROARE — tip de provizion necunoscut","OK — cont " & B19) -> OK — cont 1511
A33: Check deductibilitate | B33: =B22 -> 1280 | C33: =IF(B20="DA","OK — deductibil: " & B21,"NEDEDUCTIBIL (" & B21 & "). Impozit suplimentar: " & TEXT(B22,"0.00") & " lei") -> NEDEDUCTIBIL (art. 26 CF nu îl enumeră printre cele deductibile). Impozit suplimentar: 1280.00 lei
A34: Reminder: NU e optimizare fiscală | B34: ="regulă" -> regulă | C34: =IF(B20="DA","Deductibil — dar tot nu e optimizare: doar mută cheltuiala în exercițiul corect.","Nedeductibil la constituire, iar reluarea e venit neimpozabil. Efect fiscal net pe doi ani: zero. Nu-l vinde clientului ca optimizare.") -> Nedeductibil la constituire, iar reluarea e venit neimpozabil. Efect fiscal net pe doi ani: zero. Nu-l vinde clientului ca optimizare.
A35: Reminder: factura NU atinge contul de provizion | B35: =B15 -> 8000 | C35: ="Blocul 2 înregistrează factura pe contul REAL de cheltuială. Provizionul se reia separat, în blocul 3. Cele două nu se compensează." -> Blocul 2 înregistrează factura pe contul REAL de cheltuială. Provizionul se reia separat, în blocul 3. Cele două nu se compensează.
A36: Check estimare vs. realizat | B36: =B15-B12 -> 0 | C36: =IF(ABS(B36)<0.01,"OK — estimarea s-a confirmat",IF(B36>0,"Cheltuiala a depășit provizionul cu " & TEXT(B36,"0.00") & " lei — diferența rămâne cheltuială a anului curent","Provizionul a fost supraestimat cu " & TEXT(-B36,"0.00") & " lei — reluarea rămâne la valoarea constituită")) -> OK — estimarea s-a confirmat
A38: 7. Sufix generat
A39: Sufix | B39: =" - " & B6 -> - Litigiu comercial cu clientul X

Sheet Reguli_PROVIZION
A1: MOD_PROVIZION — Reguli (tabele fixe)
A2: Tabelul A e citit de formulele din Declarații. Se editează doar când se schimbă art. 26 din Codul fiscal.
A4: Tabel A — Tipuri de provizion, cont și deductibilitate
A5: Cod | B5: Denumire | C5: Cont | D5: Deductibil | E5: Temei
A6: LITIGII | B6: Provizioane pentru litigii | C6: 1511 | D6: NU | E6: art. 26 CF nu îl enumeră printre cele deductibile
A7: GARANTII | B7: Provizioane pentru garanții acordate clienților | C7: 1512 | D7: DA | E7: art. 26 alin. (1) lit. b) CF — în limita cotei prevăzute în contracte
A8: RESTRUCTURARE | B8: Provizioane pentru restructurare | C8: 1514 | D8: NU | E8: nu figurează printre cele deductibile
A9: IMPOZITE | B9: Provizioane pentru impozite | C9: 1516 | D9: NU | E9: nu figurează printre cele deductibile
A10: TERMINARE | B10: Provizioane pentru terminarea contractului de muncă | C10: 1517 | D10: NU | E10: nu figurează printre cele deductibile
A11: ALTE | B11: Alte provizioane | C11: 1518 | D11: NU | E11: verifică art. 26 CF pentru cazul concret
A13: Tabel B — Condițiile de recunoaștere (toate trei, cumulativ)
A14: Condiție | B14: Ce înseamnă | E14: Dacă lipsește
A15: Obligație actuală | B15: din eveniment trecut, la data bilanțului | E15: Nu e provizion — e o intenție
A16: Ieșire probabilă de resurse | B16: mai degrabă da decât nu | E16: Rămâne datorie contingentă — se prezintă în note, nu se înregistrează
A17: Estimare credibilă | B17: suma se poate evalua rezonabil | E17: Se prezintă în note, fără sumă
A19: Tabel C — LIMITĂRI DECLARATE ale modulului
A20: Ce NU tratează | B20: De ce | C20: Ce faci | E20: Efect dacă îl ignori
A21: Actualizarea provizioanelor pe termen lung | B21: Provizioanele scadente peste un an se pot actualiza la valoarea prezentă. | C21: Dacă politica firmei o cere, actualizează și trece diferența pe 686/786. | E21: Provizionul e supraevaluat față de valoarea prezentă
A22: Revizuirea la fiecare bilanț | B22: Modulul tratează un ciclu constituire → reluare, nu ajustările intermediare. | C22: La fiecare bilanț, reevaluează și ajustează prin aceleași conturi. | E22: Provizionul rămâne la estimarea inițială, care poate fi depășită
A23: Provizioane pentru garanții cu cotă contractuală | B23: Deductibilitatea lor e limitată la cota din contracte, care variază. | C23: Verifică art. 26 alin. (1) lit. b) și cota din contractul concret. | E23: Partea peste cotă rămâne nedeductibilă și nesemnalată
A24: Utilizarea pentru altă cheltuială decât cea constituită | B24: Interzisă — provizionul e specific obligației. | C24: Reia provizionul vechi și constituie unul nou. | E24: Provizionul devine un cont-tampon, exact ce nu trebuie

Sheet Jurnale_PROVIZION
A1: MOD_PROVIZION — Jurnale (generate automat)
A2: Blocul 2 e INDEPENDENT de blocurile 1 și 3: factura se înregistrează pe contul real de cheltuială, nu pe contul de provizion.
A4: Bloc 1 — Constituirea provizionului (exercițiul N)
A5: Data jurnal: | B5: =Declarații_PROVIZION!B7 -> 2026-12-31
A7: Nr | B7: Cont Dr | C7: Sumă Dr | D7: Descriere Dr | E7: Cont Cr | F7: Sumă Cr | G7: Descriere Cr
A8: 1 | B8: =Declarații_PROVIZION!B25 -> 6812 | C8: =Declarații_PROVIZION!B12 -> 8000 | D8: ="Constituire provizion" & Declarații_PROVIZION!B39 -> Constituire provizion - Litigiu comercial cu clientul X | E8: =Declarații_PROVIZION!B19 -> 1511 | F8: =Declarații_PROVIZION!B12 -> 8000 | G8: ="Provizion constituit" & Declarații_PROVIZION!B39 -> Provizion constituit - Litigiu comercial cu clientul X
A10: Check Σ (structural) | B10: =C8-F8 -> 0 | C10: =IF(ABS(B10)<0.01,"OK — nota se închide","EROARE") -> OK — nota se închide
A11: Declarativ | B11: =Declarații_PROVIZION!B20 -> NU | C11: =IF(Declarații_PROVIZION!B20="DA","D101 — cheltuială deductibilă","D101 — cheltuială NEDEDUCTIBILĂ, se adaugă la rezultatul fiscal") -> D101 — cheltuială NEDEDUCTIBILĂ, se adaugă la rezultatul fiscal
A13: Bloc 2 — Factura efectivă (exercițiul N+1) — INDEPENDENT
A14: Data jurnal: | B14: =Declarații_PROVIZION!B8 -> 2027-04-30
A16: Nr | B16: Cont Dr | C16: Sumă Dr | D16: Descriere Dr | E16: Cont Cr | F16: Sumă Cr | G16: Descriere Cr
A17: 1 | B17: =Declarații_PROVIZION!B27 -> 628 | C17: =Declarații_PROVIZION!B15 -> 8000 | D17: ="Cheltuiala efectivă, pe contul ei real" & Declarații_PROVIZION!B39 -> Cheltuiala efectivă, pe contul ei real - Litigiu comercial cu clientul X | E17: =Declarații_PROVIZION!B29 -> 401 | F17: =Declarații_PROVIZION!B15+Declarații_PROVIZION!B16 -> 9680 | G17: ="Datorie față de furnizor" & Declarații_PROVIZION!B39 -> Datorie față de furnizor - Litigiu comercial cu clientul X
A18: 2 | B18: =Declarații_PROVIZION!B28 -> 4426 | C18: =Declarații_PROVIZION!B16 -> 1680 | D18: ="TVA deductibilă" & Declarații_PROVIZION!B39 -> TVA deductibilă - Litigiu comercial cu clientul X
A20: Check Σ (structural) | B20: =SUM(C17:C18)-SUM(F17:F18) -> 0 | C20: =IF(ABS(B20)<0.01,"OK — nota se închide","EROARE") -> OK — nota se închide
A21: Check: nu atinge contul de provizion | B21: =Declarații_PROVIZION!B19 -> 1511 | C21: ="Corect — factura se înregistrează pe contul real de cheltuială. Provizionul se reia separat, în blocul 3." -> Corect — factura se înregistrează pe contul real de cheltuială. Provizionul se reia separat, în blocul 3.
A23: Bloc 3 — Reluarea provizionului (exercițiul N+1)
A24: Data jurnal: | B24: =Declarații_PROVIZION!B8 -> 2027-04-30
A26: Nr | B26: Cont Dr | C26: Sumă Dr | D26: Descriere Dr | E26: Cont Cr | F26: Sumă Cr | G26: Descriere Cr
A27: 1 | B27: =Declarații_PROVIZION!B19 -> 1511 | C27: =Declarații_PROVIZION!B12 -> 8000 | D27: ="Reluarea provizionului, obligația s-a stins" & Declarații_PROVIZION!B39 -> Reluarea provizionului, obligația s-a stins - Litigiu comercial cu clientul X | E27: =Declarații_PROVIZION!B26 -> 7812 | F27: =Declarații_PROVIZION!B12 -> 8000 | G27: ="Venit din reluarea provizionului" & Declarații_PROVIZION!B39 -> Venit din reluarea provizionului - Litigiu comercial cu clientul X
A29: Check Σ (structural) | B29: =C27-F27 -> 0 | C29: =IF(ABS(B29)<0.01,"OK — nota se închide","EROARE") -> OK — nota se închide
A30: Check sold provizion după reluare | B30: =Declarații_PROVIZION!B12-Declarații_PROVIZION!B12 -> 0 | C30: =IF(ABS(B30)<0.01,"OK — soldul contului de provizion = 0","EROARE") -> OK — soldul contului de provizion = 0
A31: Efect fiscal pe cei doi ani | B31: =Declarații_PROVIZION!B22 -> 1280 | C31: =IF(Declarații_PROVIZION!B20="DA","Deductibil la constituire, impozabil la reluare — efect net zero.","Nedeductibil la constituire, neimpozabil la reluare — efect net zero. Provizionul mută cheltuiala în exercițiul corect, nu reduce impozitul.") -> Nedeductibil la constituire, neimpozabil la reluare — efect net zero. Provizionul mută cheltuiala în exercițiul corect, nu reduce impozitul.
A33: Stare terminală: contul de provizion = 0; efectul net pe rezultatul exercițiului N+1 ≈ 0, pentru că reluarea (venit) compensează cheltuiala reală.

Sheet NotaExport_PROVIZION
A1: MOD_PROVIZION — Notă pentru import (1 rând = 1 înregistrare)
A2: Blocurile 1 și 3 aparțin exercițiilor diferite. Filtrează pe Include = DA și pe dată înainte de import.
A4: Nr | B4: Bloc | C4: Data | D4: Cont Dr | E4: Cont Cr | F4: Sumă | G4: Descriere | H4: Document | I4: Include
A5: 1 | B5: Bloc 1 — Constituire | C5: =Declarații_PROVIZION!B7 -> 2026-12-31 | D5: =Jurnale_PROVIZION!B8 -> 6812 | E5: =Jurnale_PROVIZION!E8 -> 1511 | F5: =MAX(N(Jurnale_PROVIZION!C8),N(Jurnale_PROVIZION!F8)) -> 8000 | G5: =Jurnale_PROVIZION!D8 -> Constituire provizion - Litigiu comercial cu clientul X | H5: Hotărâre + estimare | I5: =IF(N(F5)>0.005,"DA","NU") -> DA
A6: 2 | B6: Bloc 2 — Factura efectivă | C6: =Declarații_PROVIZION!B8 -> 2027-04-30 | D6: =Jurnale_PROVIZION!B17 -> 628 | E6: =Jurnale_PROVIZION!E17 -> 401 | F6: =MAX(N(Jurnale_PROVIZION!C17),N(Jurnale_PROVIZION!F17)) -> 9680 | G6: =Jurnale_PROVIZION!D17 -> Cheltuiala efectivă, pe contul ei real - Litigiu comercial cu clientul X | H6: Factură furnizor | I6: =IF(N(F6)>0.005,"DA","NU") -> DA
A7: 3 | B7: Bloc 2 — Factura efectivă | C7: =Declarații_PROVIZION!B8 -> 2027-04-30 | D7: =Jurnale_PROVIZION!B18 -> 4426 | E7: =Jurnale_PROVIZION!E18 -> 0 | F7: =MAX(N(Jurnale_PROVIZION!C18),N(Jurnale_PROVIZION!F18)) -> 1680 | G7: =Jurnale_PROVIZION!D18 -> TVA deductibilă - Litigiu comercial cu clientul X | H7: Factură furnizor | I7: =IF(N(F7)>0.005,"DA","NU") -> DA
A8: 4 | B8: Bloc 3 — Reluare | C8: =Declarații_PROVIZION!B8 -> 2027-04-30 | D8: =Jurnale_PROVIZION!B27 -> 1511 | E8: =Jurnale_PROVIZION!E27 -> 7812 | F8: =MAX(N(Jurnale_PROVIZION!C27),N(Jurnale_PROVIZION!F27)) -> 8000 | G8: =Jurnale_PROVIZION!D27 -> Reluarea provizionului, obligația s-a stins - Litigiu comercial cu clientul X | H8: Notă contabilă | I8: =IF(N(F8)>0.005,"DA","NU") -> DA
A10: Rânduri de importat (Include=DA) | B10: =COUNTIF(I5:I8,"DA") -> 4

Sheet Declarații_CREDIT_VALUTA
A1: MOD_CREDIT_VALUTA — Declarații (input)
A2: Valorile implicite reproduc monografia din F-107. Rata și dobânda se iau din SCADENȚAR, nu din extras — extrasul le arată deseori cumulat.
A4: 1. Antet
A5: Societate | B5: =Parametri!B5 -> SC EXEMPLU SRL
A6: Număr contract de credit | B6: CR-2026-001 | C6: 1621 se ține analitic pe contract și pe valută
A7: Luna (AAAA-LL) | B7: 2026-07
A8: Data plății ratei | B8: 2026-07-15
A9: Data reevaluării (ultima zi bancară a lunii) | B9: 2026-07-31
A10: Valuta | B10: EUR
A12: 2. Soldul de la care pornim
A13: Sold inițial, în valută | B13: 20000
A14: Cursul la care e înregistrat soldul | B14: 4.97
A15: Sold inițial, în lei | B15: =ROUND(B13*B14,2) -> 99400
A17: 3. Mișcările lunii (din SCADENȚAR)
A18: Rata de capital, în valută | B18: 5000
A19: Dobânda, în valută | B19: 200
A20: Cursul de la data plății | B20: 4.99
A21: Comisioane bancare, în lei | B21: 50
A23: 4. Reevaluarea de la finalul lunii
A24: Curs BNR la data reevaluării | B24: 5.01
A26: 5. Calcul automat (nu edita)
A27: Rata, la cursul de înregistrare | B27: =ROUND(B18*B14,2) -> 24850
A28: Rata, la cursul de plată | B28: =ROUND(B18*B20,2) -> 24950
A29: MOMENTUL 1 — diferența la plată | B29: =B28-B27 -> 100 | C29: Pozitiv = nefavorabil (665); negativ = favorabil (765)
A30: Dobânda, în lei | B30: =ROUND(B19*B20,2) -> 998
A31: Sold rămas, în valută | B31: =B13-B18 -> 15000
A32: Sold rămas, la cursul de înregistrare | B32: =ROUND(B31*B14,2) -> 74550
A33: Sold rămas, la cursul BNR | B33: =ROUND(B31*B24,2) -> 75150
A34: MOMENTUL 2 — diferența din reevaluare | B34: =B33-B32 -> 600 | C34: Pozitiv = datoria crește = nefavorabil (665)
A36: 6. Conturi
A37: Cont credit (162x) | B37: 1621 | C37: 1621…1627 sunt sintetice DISTINCTE, nu analitice ale aceluiași cont
A38: Cont dobândă neajunsă la scadență | B38: 1682
A39: Cont trezorerie în valută | B39: 5124
A40: Cont trezorerie în lei | B40: 5121
A41: Cont cheltuială cu dobânda | B41: 666
A42: Cont cheltuială cu serviciile bancare | B42: 627
A43: Cont diferențe nefavorabile | B43: 665
A44: Cont diferențe favorabile | B44: 765
A46: 7. Controale
A47: Check FINAL: sold lei = sold valută × curs BNR | B47: =B32+B34-B33 -> 0 | C47: =IF(ABS(B47)<0.01,"OK — soldul în lei corespunde soldului în valută","EROARE — una dintre cele două diferențe de curs lipsește") -> OK — soldul în lei corespunde soldului în valută
...

Sheet Reguli_CREDIT_VALUTA
A1: MOD_CREDIT_VALUTA — Reguli (tabele fixe)
A3: Tabel A — Cele două momente de diferență de curs
A4: Moment | B4: Când apare | C4: Bază | D4: Formula | E4: Cont | F4: Temei / observație
A5: 1. La plată | B5: la fiecare rambursare de rată | C5: rata în valută | D5: (curs plată − curs înregistrare) × rată | E5: 665 / 765 | F5: Diferența dintre cursul la care e înregistrată datoria și cel la care se stinge
A6: 2. La reevaluare | B6: ultima zi bancară a FIECĂREI luni | C6: soldul rămas în valută | D6: (curs BNR − curs înregistrare) × sold rămas | E6: 665 / 765 | F6: OMFP 1802/2014 — obligatoriu lunar; „la 3 luni” e insuficient
A8: Tabel B — Ce se ia din scadențar, nu din extras
A9: Element | B9: Cont | F9: De ce contează
A10: Rata de capital | B10: 1621 | F10: Stinge datoria. Dacă o umfli cu dobânda, 1621 ajunge pe debit
A11: Dobânda | B11: 666 | F11: Cheltuială financiară. Dacă o pui pe 1621, rămâi cu sold la finalul creditului
A12: Comisioane | B12: 627 | F12: Cheltuială cu serviciile bancare, separată de dobândă
A13: Dobânda neajunsă la scadență | B13: 1682 | F13: Se calculează, nu se plătește încă
A15: Tabel C — LIMITĂRI DECLARATE ale modulului
A16: Ce NU tratează | B16: De ce | C16: Ce faci | F16: Efect dacă îl ignori
A17: Linii de credit revolving | B17: Soldul fluctuează în ambele sensuri în cursul lunii, deci nu există o „rată” unică. | C17: Reevaluează soldul la finalul lunii; tratează tragerile separat. | F17: Diferențele de curs pe trageri intermediare rămân neînregistrate
A18: Instrumente de acoperire a riscului valutar (hedging) | B18: Contabilitatea de acoperire are reguli proprii (OMFP 1802, cap. dedicat). | C18: Tratează separat; nu compensa în 665/765. | F18: Rezultatul financiar apare volatil fără motiv
A19: Credite cu dobândă variabilă recalculată retroactiv | B19: Recalculul schimbă scadențarul pe perioade deja înregistrate. | C19: Reia scadențarul nou și corectează perioadele afectate. | F19: Dobânda înregistrată nu corespunde cu cea datorată
A20: Costuri de tranzacție amortizate (metoda dobânzii efective) | B20: Comisioanele inițiale se pot amortiza pe durata creditului. | C20: Dacă politica firmei o cere, tratează prin 471. | F20: Cheltuiala e recunoscută integral în prima lună

Sheet Jurnale_CREDIT_VALUTA
A1: MOD_CREDIT_VALUTA — Jurnale (generate automat)
A2: Blocurile de diferență se activează după semn: nefavorabilă pe 665, favorabilă pe 765. Doar unul dintre ele are sumă.
A4: Bloc 1 — Rata de capital și diferența la plată
A5: Data jurnal: | B5: =Declarații_CREDIT_VALUTA!B8 -> 2026-07-15
A7: Nr | B7: Cont Dr | C7: Sumă Dr | D7: Descriere Dr | E7: Cont Cr | F7: Sumă Cr | G7: Descriere Cr
A8: 1 | B8: =Declarații_CREDIT_VALUTA!B37 -> 1621 | C8: =Declarații_CREDIT_VALUTA!B27 -> 24850 | D8: ="Rambursare rată de capital" & Declarații_CREDIT_VALUTA!B54 -> Rambursare rată de capital - CR-2026-001 - 2026-07 | E8: =Declarații_CREDIT_VALUTA!B39 -> 5124 | F8: =Declarații_CREDIT_VALUTA!B28 -> 24950 | G8: ="Plata ratei din contul în valută" & Declarații_CREDIT_VALUTA!B54 -> Plata ratei din contul în valută - CR-2026-001 - 2026-07
A9: 2 | B9: =Declarații_CREDIT_VALUTA!B43 -> 665 | C9: =MAX(0,Declarații_CREDIT_VALUTA!B29) -> 100 | D9: ="Diferență de curs nefavorabilă la plată" & Declarații_CREDIT_VALUTA!B54 -> Diferență de curs nefavorabilă la plată - CR-2026-001 - 2026-07
A10: 3 | E10: =Declarații_CREDIT_VALUTA!B44 -> 765 | F10: =MAX(0,-Declarații_CREDIT_VALUTA!B29) -> 0 | G10: ="Diferență de curs favorabilă la plată" & Declarații_CREDIT_VALUTA!B54 -> Diferență de curs favorabilă la plată - CR-2026-001 - 2026-07
A12: Check Σ (structural) | B12: =SUM(C8:C10)-SUM(F8:F10) -> 0 | C12: =IF(ABS(B12)<0.01,"OK — nota se închide","EROARE") -> OK — nota se închide
A13: Check exclusivitate 665/665 | B13: =IF(AND(C9>0.005,F10>0.005),1,0) -> 0 | C13: =IF(B13=0,"OK — o singură diferență, într-un singur sens","EROARE — 665 și 765 nu pot avea ambele sumă") -> OK — o singură diferență, într-un singur sens
A15: Bloc 2 — Dobânda
A16: Data jurnal: | B16: =Declarații_CREDIT_VALUTA!B8 -> 2026-07-15
A18: Nr | B18: Cont Dr | C18: Sumă Dr | D18: Descriere Dr | E18: Cont Cr | F18: Sumă Cr | G18: Descriere Cr
A19: 1 | B19: =Declarații_CREDIT_VALUTA!B41 -> 666 | C19: =Declarații_CREDIT_VALUTA!B30 -> 998 | D19: ="Dobândă aferentă creditului" & Declarații_CREDIT_VALUTA!B54 -> Dobândă aferentă creditului - CR-2026-001 - 2026-07 | E19: =Declarații_CREDIT_VALUTA!B39 -> 5124 | F19: =Declarații_CREDIT_VALUTA!B30 -> 998 | G19: ="Plata dobânzii din contul în valută" & Declarații_CREDIT_VALUTA!B54 -> Plata dobânzii din contul în valută - CR-2026-001 - 2026-07
A21: Check Σ (structural) | B21: =C19-F19 -> 0 | C21: =IF(ABS(B21)<0.01,"OK — nota se închide","EROARE") -> OK — nota se închide
A23: Bloc 3 — Comisioane bancare
A24: Data jurnal: | B24: =Declarații_CREDIT_VALUTA!B8 -> 2026-07-15
A26: Nr | B26: Cont Dr | C26: Sumă Dr | D26: Descriere Dr | E26: Cont Cr | F26: Sumă Cr | G26: Descriere Cr
A27: 1 | B27: =Declarații_CREDIT_VALUTA!B42 -> 627 | C27: =Declarații_CREDIT_VALUTA!B21 -> 50 | D27: ="Comisioane bancare aferente creditului" & Declarații_CREDIT_VALUTA!B54 -> Comisioane bancare aferente creditului - CR-2026-001 - 2026-07 | E27: =Declarații_CREDIT_VALUTA!B40 -> 5121 | F27: =Declarații_CREDIT_VALUTA!B21 -> 50 | G27: ="Plata comisioanelor" & Declarații_CREDIT_VALUTA!B54 -> Plata comisioanelor - CR-2026-001 - 2026-07
A29: Check Σ (structural) | B29: =C27-F27 -> 0 | C29: =IF(ABS(B29)<0.01,"OK — nota se închide","EROARE") -> OK — nota se închide
A31: Bloc 4 — Reevaluarea soldului (PASUL CARE SE UITĂ)
A32: Data jurnal: | B32: =Declarații_CREDIT_VALUTA!B9 -> 2026-07-31
A34: Nr | B34: Cont Dr | C34: Sumă Dr | D34: Descriere Dr | E34: Cont Cr | F34: Sumă Cr | G34: Descriere Cr
A35: 1 | B35: =Declarații_CREDIT_VALUTA!B43 -> 665 | C35: =MAX(0,Declarații_CREDIT_VALUTA!B34) -> 600 | D35: ="Reevaluare sold credit — diferență nefavorabilă" & Declarații_CREDIT_VALUTA!B54 -> Reevaluare sold credit — diferență nefavorabilă - CR-2026-001 - 2026-07 | E35: =Declarații_CREDIT_VALUTA!B37 -> 1621 | F35: =MAX(0,Declarații_CREDIT_VALUTA!B34) -> 600 | G35: ="Creșterea datoriei din reevaluare" & Declarații_CREDIT_VALUTA!B54 -> Creșterea datoriei din reevaluare - CR-2026-001 - 2026-07
A36: 2 | B36: =Declarații_CREDIT_VALUTA!B37 -> 1621 | C36: =MAX(0,-Declarații_CREDIT_VALUTA!B34) -> 0 | D36: ="Diminuarea datoriei din reevaluare" & Declarații_CREDIT_VALUTA!B54 -> Diminuarea datoriei din reevaluare - CR-2026-001 - 2026-07 | E36: =Declarații_CREDIT_VALUTA!B44 -> 765 | F36: =MAX(0,-Declarații_CREDIT_VALUTA!B34) -> 0 | G36: ="Reevaluare sold credit — diferență favorabilă" & Declarații_CREDIT_VALUTA!B54 -> Reevaluare sold credit — diferență favorabilă - CR-2026-001 - 2026-07
A38: Check Σ (structural) | B38: =SUM(C35:C36)-SUM(F35:F36) -> 0 | C38: =IF(ABS(B38)<0.01,"OK — nota se închide","EROARE") -> OK — nota se închide
A39: Check sold final | B39: =Declarații_CREDIT_VALUTA!B33 -> 75150 | C39: ="Sold 1621 după reevaluare = " & TEXT(B39,"0.00") & " lei = " & TEXT(Declarații_CREDIT_VALUTA!B31,"0") & " " & Declarații_CREDIT_VALUTA!B10 & " × " & TEXT(Declarații_CREDIT_VALUTA!B24,"0.0000") -> Sold 1621 după reevaluare = 75150.00 lei = 15000 EUR × 5.0100
A41: Stare terminală: soldul lui 1621 în lei = soldul în valută × cursul BNR de la data reevaluării. Dacă nu ține, unul dintre cele două momente lipsește.

Sheet NotaExport_CREDIT_VALUTA
A1: MOD_CREDIT_VALUTA — Notă pentru import (1 rând = 1 înregistrare)
A2: Filtrează pe Include = DA. Rândurile de diferență cu sumă zero ies singure.
A4: Nr | B4: Bloc | C4: Data | D4: Cont Dr | E4: Cont Cr | F4: Sumă | G4: Descriere | H4: Document | I4: Include
A5: 1 | B5: Bloc 1 — Rata + diferență | C5: =Declarații_CREDIT_VALUTA!B8 -> 2026-07-15 | D5: =Jurnale_CREDIT_VALUTA!B8 -> 1621 | E5: =Jurnale_CREDIT_VALUTA!E8 -> 5124 | F5: =MAX(N(Jurnale_CREDIT_VALUTA!C8),N(Jurnale_CREDIT_VALUTA!F8)) -> 24950 | G5: =Jurnale_CREDIT_VALUTA!D8 -> Rambursare rată de capital - CR-2026-001 - 2026-07 | H5: Scadențar + extras | I5: =IF(N(F5)>0.005,"DA","NU") -> DA
A6: 2 | B6: Bloc 1 — Rata + diferență | C6: =Declarații_CREDIT_VALUTA!B8 -> 2026-07-15 | D6: =Jurnale_CREDIT_VALUTA!B9 -> 665 | E6: =Jurnale_CREDIT_VALUTA!E9 -> 0 | F6: =MAX(N(Jurnale_CREDIT_VALUTA!C9),N(Jurnale_CREDIT_VALUTA!F9)) -> 100 | G6: =Jurnale_CREDIT_VALUTA!D9 -> Diferență de curs nefavorabilă la plată - CR-2026-001 - 2026-07 | H6: Scadențar + extras | I6: =IF(N(F6)>0.005,"DA","NU") -> DA
A7: 3 | B7: Bloc 1 — Rata + diferență | C7: =Declarații_CREDIT_VALUTA!B8 -> 2026-07-15 | D7: =Jurnale_CREDIT_VALUTA!B10 -> 0 | E7: =Jurnale_CREDIT_VALUTA!E10 -> 765 | F7: =MAX(N(Jurnale_CREDIT_VALUTA!C10),N(Jurnale_CREDIT_VALUTA!F10)) -> 0 | G7: =Jurnale_CREDIT_VALUTA!D10 -> 0 | H7: Scadențar + extras | I7: =IF(N(F7)>0.005,"DA","NU") -> NU
A8: 4 | B8: Bloc 2 — Dobânda | C8: =Declarații_CREDIT_VALUTA!B8 -> 2026-07-15 | D8: =Jurnale_CREDIT_VALUTA!B19 -> 666 | E8: =Jurnale_CREDIT_VALUTA!E19 -> 5124 | F8: =MAX(N(Jurnale_CREDIT_VALUTA!C19),N(Jurnale_CREDIT_VALUTA!F19)) -> 998 | G8: =Jurnale_CREDIT_VALUTA!D19 -> Dobândă aferentă creditului - CR-2026-001 - 2026-07 | H8: Scadențar + extras | I8: =IF(N(F8)>0.005,"DA","NU") -> DA
A9: 5 | B9: Bloc 3 — Comisioane | C9: =Declarații_CREDIT_VALUTA!B8 -> 2026-07-15 | D9: =Jurnale_CREDIT_VALUTA!B27 -> 627 | E9: =Jurnale_CREDIT_VALUTA!E27 -> 5121 | F9: =MAX(N(Jurnale_CREDIT_VALUTA!C27),N(Jurnale_CREDIT_VALUTA!F27)) -> 50 | G9: =Jurnale_CREDIT_VALUTA!D27 -> Comisioane bancare aferente creditului - CR-2026-001 - 2026-07 | H9: Scadențar + extras | I9: =IF(N(F9)>0.005,"DA","NU") -> DA
A10: 6 | B10: Bloc 4 — Reevaluare | C10: =Declarații_CREDIT_VALUTA!B9 -> 2026-07-31 | D10: =Jurnale_CREDIT_VALUTA!B35 -> 665 | E10: =Jurnale_CREDIT_VALUTA!E35 -> 1621 | F10: =MAX(N(Jurnale_CREDIT_VALUTA!C35),N(Jurnale_CREDIT_VALUTA!F35)) -> 600 | G10: =Jurnale_CREDIT_VALUTA!D35 -> Reevaluare sold credit — diferență nefavorabilă - CR-2026-001 - 2026-07 | H10: Scadențar + extras | I10: =IF(N(F10)>0.005,"DA","NU") -> DA
A11: 7 | B11: Bloc 4 — Reevaluare | C11: =Declarații_CREDIT_VALUTA!B9 -> 2026-07-31 | D11: =Jurnale_CREDIT_VALUTA!B36 -> 1621 | E11: =Jurnale_CREDIT_VALUTA!E36 -> 765 | F11: =MAX(N(Jurnale_CREDIT_VALUTA!C36),N(Jurnale_CREDIT_VALUTA!F36)) -> 0 | G11: =Jurnale_CREDIT_VALUTA!D36 -> Diminuarea datoriei din reevaluare - CR-2026-001 - 2026-07 | H11: Scadențar + extras | I11: =IF(N(F11)>0.005,"DA","NU") -> NU
A13: Rânduri de importat (Include=DA) | B13: =COUNTIF(I5:I11,"DA") -> 5

Sheet Declarații_LEASING_FIN
A1: MOD_LEASING_FIN — Declarații (input)
A2: Valorile implicite reproduc monografia din trainingul 07.08.2026 (contract 150.000, avans 50.000, rată 2.000, dobândă 500, comision 100, CASCO 20).
A4: 1. Antet
A5: Societate | B5: =Parametri!B5 -> SC EXEMPLU SRL
A6: Număr contract de leasing | B6: LF-2026-001 | C6: 167 este 1-la-1 cu contractul (C-19)
A7: Luna | B7: 2026-07
A8: Data facturii de avans | B8: 2026-07-01
A9: Data recepției bunului | B9: 2026-07-10
A10: Data facturii lunare | B10: 2026-07-31
A12: 2. Contract
A13: Valoare de intrare din contract (fără TVA) | B13: 150000
A14: Avans (fără TVA) | B14: 50000
A15: Durata de amortizare (luni) | B15: 60
A16: Cotă TVA | B16: =Parametri!B10 -> 0.21
A18: 3. Regim fiscal al vehiculului
A19: Regim (MIXT / EXCLUSIV / EXCEPTAT) | B19: MIXT | C19: MIXT = 50%. EXCLUSIV/EXCEPTAT = 100%, dar cere documentație (foi de parcurs, decizie internă)
A20: Procent de deducere aplicat | B20: =IF(B19="MIXT",param_proc_vehicul,1) -> 0.5
A21: TVA nededusă pe rata de capital: CAPITALIZEAZA / CHELTUIALA | B21: CAPITALIZEAZA | C21: ❓ De clarificat cu formatorul — practica e împărțită. Capitalizarea e coerentă cu tratamentul avansului (pct. 75 OMFP 1802)
A23: 4. Factura lunară de leasing
A24: Rata de capital | B24: 2000
A25: Dobândă | B25: 500
A26: Comision de administrare | B26: 100
A27: CASCO (fără TVA) | B27: 20
A29: 5. Calcul — intrarea bunului (nu edita)
A30: TVA pe avans | B30: =B14*B16 -> 10500
A31: TVA nedeductibilă pe avans (capitalizată) | B31: =ROUND(B30*(1-B20),2) -> 5250
A32: Valoare de intrare a mijlocului fix | B32: =B13+B31 -> 155250 | C32: 150.000 + 5.250 = 155.250 în exemplul din training
A33: Amortizare contabilă lunară | B33: =ROUND(B32/B15,2) -> 2587.5
A34: Amortizare deductibilă fiscal | B34: =MIN(B33,param_plafon_amo_auto) -> 1500 | C34: Plafon 1.500 lei/lună, art. 28 alin. (14) CF
A35: Amortizare NEdeductibilă lunară | B35: =B33-B34 -> 1087.5
A37: 6. Calcul — factura lunară (nu edita)
A38: TVA pe rata de capital | B38: =B24*B16 -> 420
A39: TVA pe dobândă | B39: =B25*B16 -> 105
A40: TVA pe comision | B40: =B26*B16 -> 21
A41: TVA total pe factură | B41: =B38+B39+B40 -> 546 | C41: CASCO e fără TVA
A42: Total factură | B42: =B24+B25+B26+B27+B41 -> 3166
A44: 7. Calcul — corecția TVA nedeductibilă (limitarea 1)
A45: TVA nededusă — rată | B45: =ROUND(B38*(1-B20),2) -> 210
A46: TVA nededusă — dobândă | B46: =ROUND(B39*(1-B20),2) -> 52.5
A47: TVA nededusă — comision | B47: =ROUND(B40*(1-B20),2) -> 10.5
...

Sheet Reguli_LEASING_FIN
A1: MOD_LEASING_FIN — Reguli (tabele fixe)
A2: Se editează doar când se schimbă legea.
A4: Tabel A — Cele trei limitări fiscale (se aplică simultan, pe baze diferite)
A5: # | B5: Limitare | C5: Bază de aplicare | D5: Procent / plafon | E5: Temei | F5: Observație
