Workbook
Name dec_sold_de_platit: Decont!$D$61
Name dec_total_datorat: Decont!$D$58
Name dec_total_neacceptat: Decont!$D$59
Name dec_tva_deductibil: Decont!$R$29
Name decl_avans: Declaratii!$E$35
Name decl_cont_avans: Declaratii!$E$28
Name decl_cont_datorie: Declaratii!$E$27
Name decl_cont_masa: Declaratii!$E$30
Name decl_cont_transport: Declaratii!$E$29
Name decl_cont_trezorerie: Declaratii!$E$31
Name decl_cota_redusa: Declaratii!$E$19
Name decl_cota_standard: Declaratii!$E$18
Name decl_cui: Declaratii!$E$10
Name decl_curs_eur: Declaratii!$E$21
Name decl_data_avans: Declaratii!$E$36
Name decl_data_decont: Declaratii!$E$12
Name decl_data_plata: Declaratii!$E$40
Name decl_ded_vehicule: Declaratii!$E$23
Name decl_moneda: Declaratii!$E$13
Name decl_nr_decont: Declaratii!#REF!
Name decl_plafon_eur: Declaratii!$E$20
Name decl_plafon_lei: Declaratii!$E$22
Name decl_platitor_tva: Declaratii!$E$17
Name decl_societate: Declaratii!$E$9
Name decl_sold_avans_balanta: Declaratii!$E$37
Name decl_titular: Declaratii!$E$11
Name desc_sufix: Declaratii!$E$44
Name lst_cont_avans: Reguli!$I$31:$I$32
Name lst_cont_datorie: Reguli!$E$31:$E$33
Name lst_cont_masa: Reguli!$G$31:$G$33
Name lst_cont_transport: Reguli!$F$31:$F$32
Name lst_cont_trezorerie: Reguli!$H$31:$H$32
Name lst_danu: Reguli!$D$31:$D$32
Name lst_natura: Reguli!$B$31:$B$41
Name lst_tipdoc: Reguli!$C$31:$C$33
Name tbl_deducere: Reguli!$B$21:$G$26
Name tbl_natura: Reguli!$B$7:$J$17

Sheet Instructiuni
B2: Template decont de cheltuieli — jurnale generate declarativ
B3: Expense claim template — journals generated from declarations
B5: Cum funcționează / How it works
C7: 1. Declarații — completezi o singură dată antetul, regimul de TVA și politica de conturi.
C8: 2. Reguli — tabelele fiscale: natura cheltuielii → cont + cotă TVA + regim; matricea dreptului de deducere.
C9: 3. Decont — lipești liniile din decontul primit; motorul clasifică fiecare rând automat.
C10: 4. Jurnale — se populează singure, pe momente contabile, cu Sumar și Check pe fiecare bloc.
C11: 5. NotaExport — o linie = o înregistrare, gata de import în programul de contabilitate.
B13: Ce se editează manual / What to fill in
C15: Doar celulele cu fond galben și scris albastru. Restul sunt formule — nu le suprascrie.
C16: Only the yellow cells with blue text. Everything else is a formula — do not overwrite.
B18: Variabilele care schimbă jurnalele / Levers that rewrite the journals
C20: decl_platitor_tva DA → NU colapsează 4426 la zero și trece TVA-ul integral în cheltuială.
C21: decl_cota_standard 21% → orice valoare: recalculează baza și TVA pe toate liniile la cotă standard.
C22: decl_cont_datorie 542 / 462 / 4281: schimbă contul de datorie față de titular în toate blocurile.
C23: decl_cont_transport 624 / 625: comută politica pentru bilete, parcări, taxi.
C24: decl_cont_masa 625 / 6231 / 6588: comută tratamentul consumațiilor din deplasare.
C25: decl_avans > 0 activează blocurile de acordare și regularizare a avansului.
C26: decl_ded_vehicule 50%: procentul de deducere TVA pentru cheltuielile cu vehiculele (art. 298).
B28: Controale încorporate / Built-in controls
C30: • Fiecare bloc de jurnal are rând Check = total Dr − total Cr, care trebuie să fie zero.
C31: • Decont!Control verifică: bază + TVA deductibil + sume neacceptate = total decont.
C32: • Declarații!Verdict control compară avansul declarat de titular cu soldul din balanță.
C33: • Coloana „Regula aplicată” din Decont arată de ce fiecare linie a primit tratamentul respectiv.
B35: Surse pentru constantele fiscale / Sources for the tax constants
C37: Cote TVA 21% / 11%: Legea 141/2025, aplicabile de la 01.08.2025 (art. 291 Cod fiscal).
C38: Scutire cu drept de deducere, transport internațional de persoane: art. 294 alin. (1) Cod fiscal.
C39: Factură simplificată / bon fiscal până la 100 EUR cu CUI: art. 319 Cod fiscal.
C40: Deducere TVA 50% pentru vehicule fără utilizare exclusivă: art. 298 Cod fiscal.
C41: Curs EUR și plafonul în lei: introduse de utilizator — de actualizat la data fiecărui decont.
B43: Limitare cunoscută / Known limitation
C45: Liniile fără document justificativ nu se înregistrează pe cheltuială. Dacă societatea decide
C46: totuși plata, suma devine avantaj de natură salarială și se tratează în statul de plată
C47: (impozit, CAS, CASS, CAM) — nu în acest template. Blocul 5 din Jurnale semnalează situația.

Sheet Declaratii
B2: Declarații / Declarations
C4: Se completează manual doar celulele galbene. Tot restul fișierului derivă din ele.
C5: Fill in only the yellow cells. Everything else in the workbook derives from them.
B7: 1. Antet decont / Claim header
C9: Societate | D9: Company | E9: SC AS KIDS TOYS SRL
C10: CUI | D10: Tax ID | E10: RO39195258
C11: Titular decont | D11: Expense claimant | E11: CHIRIACESCU DIANA
C12: Data decontului | D12: Claim date | E12: 46234
C13: Moneda | D13: Currency | E13: RON
B15: 2. Declarații fiscale / Tax declarations
C17: Societate plătitoare de TVA | D17: VAT registered | E17: DA | F17: DA / NU
C18: Cota TVA standard | D18: Standard VAT rate | E18: 0.21 | F18: Legea 141/2025, în vigoare de la 01.08.2025
C19: Cota TVA redusă | D19: Reduced VAT rate | E19: 0.11 | F19: HoReCa, transport de persoane, cazare
C20: Plafon factură simplificată (EUR) | D20: Simplified invoice cap (EUR) | E20: 100 | F20: art. 319 Cod fiscal
C21: Curs EUR la data decontului | D21: EUR rate at claim date | E21: 5.2473 | F21: introdus manual — de actualizat (curs BNR)
C22: Plafon în lei | D22: Cap in RON | E22: =E20*E21 -> 524.73 | F22: calculat
C23: Procent deducere TVA vehicule | D23: VAT deduction rate, vehicles | E23: 0.5 | F23: art. 298 — 50% dacă nu e utilizare exclusivă
B25: 3. Politica de conturi / Account policy
C27: Cont datorie față de titular | D27: Payable to claimant | E27: 542 | F27: 542 / 462 / 4281 — comutator
C28: Cont avans de trezorerie | D28: Cash advance account | E28: 542 | F28: 542 / 425
C29: Cont transport și parcare | D29: Transport & parking account | E29: 625 | F29: 624 / 625 — comutator
C30: Cont masă în deplasare | D30: Meals on business trip | E30: 625 | F30: 625 / 6231 / 6588 — comutator
C31: Cont trezorerie pentru plăți | D31: Treasury account for payments | E31: 5121 | F31: 5121 / 5311
B33: 4. Avans și control / Advance and control
C35: Avans primit (declarat în decont) | D35: Advance per claim form | E35: 0
C36: Data acordării avansului | D36: Advance date | F36: se completează doar dacă există avans
C37: Sold cont avans din balanță | D37: Advance balance per trial balance | E37: 0 | F37: din fișa contului la data decontului
C38: Diferență de verificat | D38: Difference to check | E38: =E37-E35 -> 0
C39: Verdict control | D39: Control verdict | E39: =IF(E38=0,"OK — avansul declarat corespunde balanței","ATENȚIE — verificați fișa contului de avans") -> OK — avansul declarat corespunde balanței | F39: compară declarația titularului cu evidența contabilă
C40: Data plății / restituirii | D40: Settlement date | E40: 46239
B42: 5. Sufix generat pentru descrieri / Generated description suffix
C44: Sufix descriere | D44: Description suffix | E44: =" - decont "&"/"&IF(DAY(E12)<10,"0","")&DAY(E12)&"."&IF(MONTH(E12)<10,"0","")&MONTH(E12)&"."&YEAR(E12)&" - "&E11 -> - decont /31.07.2026 - CHIRIACESCU DIANA

Sheet Reguli
B2: Reguli fiscale / Tax rules
C4: Regula fiscală este dată, nu formulă. Când se schimbă legea, se editează tabelul — nu jurnalele.
B5: Tabel A — Natura cheltuielii / Expense nature
B6: Cod | C6: Natura cheltuielii | D6: Expense nature | E6: Cont | F6: Cotă TVA | G6: Regim TVA | H6: % deducere | I6: Impozit pe profit | J6: Temei / observație
B7: TRANSP_INT | C7: Transport aerian internațional de persoane | D7: International air travel | E7: =decl_cont_transport -> 625 | F7: 0 | G7: Scutit cu drept de deducere | H7: 1 | I7: Deductibil | J7: art. 294 alin. (1) — scutire cu drept de deducere, TVA zero
B8: TRANSP_INTERN | C8: Transport intern de persoane | D8: Domestic passenger transport | E8: =decl_cont_transport -> 625 | F8: =decl_cota_redusa -> 0.11 | G8: Taxabil | H8: 1 | I8: Deductibil | J8: cotă redusă
B9: PARCARE | C9: Parcare, taxe de drum | D9: Parking, road tolls | E9: =decl_cont_transport -> 625 | F9: =decl_cota_standard -> 0.21 | G9: Taxabil | H9: 1 | I9: Deductibil | J9: cotă standard
B10: TAXI | C10: Taxi, transfer aeroport | D10: Taxi, airport transfer | E10: =decl_cont_transport -> 625 | F10: =decl_cota_redusa -> 0.11 | G10: Taxabil | H10: 1 | I10: Deductibil | J10: transport de persoane
B11: CAZARE | C11: Cazare hotelieră | D11: Hotel accommodation | E11: 625 | F11: =decl_cota_redusa -> 0.11 | G11: Taxabil | H11: 1 | I11: Deductibil | J11: cotă redusă HoReCa
B12: MASA | C12: Masă în deplasare | D12: Meals on business trip | E12: =decl_cont_masa -> 625 | F12: =decl_cota_redusa -> 0.11 | G12: Taxabil | H12: 1 | I12: Deductibil | J12: restaurant/catering; dacă se acordă diurnă, comută pe 6588
B13: PROTOCOL | C13: Protocol cu partener / client | D13: Client entertainment | E13: 6231 | F13: =decl_cota_redusa -> 0.11 | G13: Taxabil | H13: 1 | I13: Deductibil limitat 2% | J13: limita de 2% din profitul contabil
B14: COMBUSTIBIL | C14: Combustibil auto | D14: Vehicle fuel | E14: 6022 | F14: =decl_cota_standard -> 0.21 | G14: Taxabil | H14: =decl_ded_vehicule -> 0.5 | I14: Deductibil limitat 50% | J14: art. 298 — deducere TVA 50% fără utilizare exclusivă
B15: SERVICII | C15: Alte servicii executate de terți | D15: Other third-party services | E15: 628 | F15: =decl_cota_standard -> 0.21 | G15: Taxabil | H15: 1 | I15: Deductibil
B16: MATERIALE | C16: Materiale consumabile | D16: Consumables | E16: 6028 | F16: =decl_cota_standard -> 0.21 | G16: Taxabil | H16: 1 | I16: Deductibil
B17: PERSONAL | C17: Cheltuială personală / nejustificată | D17: Personal, unjustified | E17: 6588 | F17: 0 | G17: Fără drept de deducere | H17: 0 | I17: Nedeductibil | J17: nu se acceptă la deducere fiscală
B19: Tabel B — Matricea dreptului de deducere / VAT deduction matrix
B20: Cheie | C20: Tip document | D20: CUI pe document | E20: Deducere TVA | F20: Cheltuială acceptată | G20: Motivare
B21: Factura|DA | C21: Factura | D21: DA | E21: DA | F21: DA | G21: Factură completă conform art. 319 — TVA deductibil
B22: Factura|NU | C22: Factura | D22: NU | E22: NU | F22: DA | G22: Lipsesc datele cumpărătorului — TVA nedeductibil, cheltuiala rămâne
B23: Bon fiscal|DA | C23: Bon fiscal | D23: DA | E23: DA | F23: DA | G23: Factură simplificată — deducere permisă sub plafon
B24: Bon fiscal|NU | C24: Bon fiscal | D24: NU | E24: NU | F24: DA | G24: Bon fără CUI — TVA nedeductibil; justificare cu ordin de deplasare
B25: Lipsa document|DA | C25: Lipsa document | D25: DA | E25: NU | F25: NU | G25: Fără document justificativ — decontul nu se acceptă
B26: Lipsa document|NU | C26: Lipsa document | D26: NU | E26: NU | F26: NU | G26: Fără document justificativ — decontul nu se acceptă
B29: Liste pentru validare / Validation lists
B30: Cod natură | C30: Tip document | D30: DA / NU | E30: Cont datorie | F30: Cont transport | G30: Cont masă | H30: Cont trezorerie | I30: Cont avans
B31: TRANSP_INT | C31: Factura | D31: DA | E31: 542 | F31: 624 | G31: 625 | H31: 5121 | I31: 542
B32: TRANSP_INTERN | C32: Bon fiscal | D32: NU | E32: 462 | F32: 625 | G32: 6231 | H32: 5311 | I32: 425
B33: PARCARE | C33: Lipsa document | E33: 4281 | G33: 6588
B34: TAXI
B35: CAZARE
B36: MASA
B37: PROTOCOL
B38: COMBUSTIBIL
B39: SERVICII
B40: MATERIALE
B41: PERSONAL

Sheet Decont
B2: Registrul liniilor de decont / Expense claim line register
C4: Coloanele B–J se completează (galben). Coloanele K–U sunt motorul de clasificare — formule.
C5: Fill in columns B–J. Columns K–U are the classification engine — formulas only.
B7: Nr. | C7: Denumire furnizor | D7: Data doc. | E7: Sumă brută | F7: Monedă | G7: Natura chelt. | H7: Tip document | I7: CUI pe doc. | J7: Cont | K7: Cotă | L7: Regim TVA | M7: % ded. | N7: Deducere | O7: Acceptat | P7: Bază cheltuială | Q7: TVA deductibil | R7: TVA în cheltuială | S7: Impozit pe profit | T7: Regula aplicată
B8: 1 | C8: WIZZ AIR MALTA LIMITED | D8: 46223 | E8: 1780.38 | F8: RON | G8: TRANSP_INT | H8: Factura | I8: DA | J8: =IF($E8="","",IFERROR(VLOOKUP($G8,tbl_natura,4,FALSE()),"cod invalid")) -> 625 | K8: =IF($E8="","",IFERROR(VLOOKUP($G8,tbl_natura,5,FALSE()),0)) -> 0 | L8: =IF($E8="","",IFERROR(VLOOKUP($G8,tbl_natura,6,FALSE()),"")) -> Scutit cu drept de deducere | M8: =IF($E8="","",IFERROR(VLOOKUP($G8,tbl_natura,7,FALSE()),0)) -> 1 | N8: =IF($E8="","",IF(decl_platitor_tva<>"DA","NU",IF(IFERROR(VLOOKUP($H8&"|"&$I8,tbl_deducere,4,FALSE()),"NU")<>"DA","NU",IF(AND($H8="Bon fiscal",$E8>decl_plafon_lei),"NU",IF($K8=0,"NU","DA"))))) -> NU | O8: =IF($E8="","",IFERROR(VLOOKUP($H8&"|"&$I8,tbl_deducere,5,FALSE()),"NU")) -> DA | P8: =IF($E8="","",IF($O8<>"DA",0,$E8-$Q8)) -> 1780.38 | Q8: =IF($E8="","",IF($N8<>"DA",0,ROUND(($E8-$E8/(1+$K8))*$M8,2))) -> 0 | R8: =IF($E8="","",IF($O8<>"DA",0,ROUND($E8-$E8/(1+$K8),2)-$Q8)) -> 0 | S8: =IF($E8="","",IFERROR(VLOOKUP($G8,tbl_natura,8,FALSE()),"")) -> Deductibil | T8: =IF($E8="","",IFERROR(VLOOKUP($H8&"|"&$I8,tbl_deducere,6,FALSE()),"")&IF(AND($H8="Bon fiscal",$E8>decl_plafon_lei)," | peste plafonul facturii simplificate","")&IF(decl_platitor_tva<>"DA"," | societate neplătitoare de TVA","")&IF($L8="Scutit cu drept de deducere"," | operațiune scutită — TVA zero","")) -> Factură completă conform art. 319 — TVA deductibil | operațiune scutită — TVA zero
B9: 2 | C9: WIZZ AIR MALTA LIMITED | D9: 46232 | E9: 1720.38 | F9: RON | G9: TRANSP_INT | H9: Factura | I9: DA | J9: =IF($E9="","",IFERROR(VLOOKUP($G9,tbl_natura,4,FALSE()),"cod invalid")) -> 625 | K9: =IF($E9="","",IFERROR(VLOOKUP($G9,tbl_natura,5,FALSE()),0)) -> 0 | L9: =IF($E9="","",IFERROR(VLOOKUP($G9,tbl_natura,6,FALSE()),"")) -> Scutit cu drept de deducere | M9: =IF($E9="","",IFERROR(VLOOKUP($G9,tbl_natura,7,FALSE()),0)) -> 1 | N9: =IF($E9="","",IF(decl_platitor_tva<>"DA","NU",IF(IFERROR(VLOOKUP($H9&"|"&$I9,tbl_deducere,4,FALSE()),"NU")<>"DA","NU",IF(AND($H9="Bon fiscal",$E9>decl_plafon_lei),"NU",IF($K9=0,"NU","DA"))))) -> NU | O9: =IF($E9="","",IFERROR(VLOOKUP($H9&"|"&$I9,tbl_deducere,5,FALSE()),"NU")) -> DA | P9: =IF($E9="","",IF($O9<>"DA",0,$E9-$Q9)) -> 1720.38 | Q9: =IF($E9="","",IF($N9<>"DA",0,ROUND(($E9-$E9/(1+$K9))*$M9,2))) -> 0 | R9: =IF($E9="","",IF($O9<>"DA",0,ROUND($E9-$E9/(1+$K9),2)-$Q9)) -> 0 | S9: =IF($E9="","",IFERROR(VLOOKUP($G9,tbl_natura,8,FALSE()),"")) -> Deductibil | T9: =IF($E9="","",IFERROR(VLOOKUP($H9&"|"&$I9,tbl_deducere,6,FALSE()),"")&IF(AND($H9="Bon fiscal",$E9>decl_plafon_lei)," | peste plafonul facturii simplificate","")&IF(decl_platitor_tva<>"DA"," | societate neplătitoare de TVA","")&IF($L9="Scutit cu drept de deducere"," | operațiune scutită — TVA zero","")) -> Factură completă conform art. 319 — TVA deductibil | operațiune scutită — TVA zero
B10: 3 | C10: CITY CAFÉ EXPRESS | D10: 46217 | E10: 38 | F10: RON | G10: MASA | H10: Bon fiscal | I10: NU | J10: =IF($E10="","",IFERROR(VLOOKUP($G10,tbl_natura,4,FALSE()),"cod invalid")) -> 625 | K10: 0.21 | L10: =IF($E10="","",IFERROR(VLOOKUP($G10,tbl_natura,6,FALSE()),"")) -> Taxabil | M10: =IF($E10="","",IFERROR(VLOOKUP($G10,tbl_natura,7,FALSE()),0)) -> 1 | N10: =IF($E10="","",IF(decl_platitor_tva<>"DA","NU",IF(IFERROR(VLOOKUP($H10&"|"&$I10,tbl_deducere,4,FALSE()),"NU")<>"DA","NU",IF(AND($H10="Bon fiscal",$E10>decl_plafon_lei),"NU",IF($K10=0,"NU","DA"))))) -> NU | O10: =IF($E10="","",IFERROR(VLOOKUP($H10&"|"&$I10,tbl_deducere,5,FALSE()),"NU")) -> DA | P10: =IF($E10="","",IF($O10<>"DA",0,$E10-$Q10)) -> 38 | Q10: =IF($E10="","",IF($N10<>"DA",0,ROUND(($E10-$E10/(1+$K10))*$M10,2))) -> 0 | R10: =IF($E10="","",IF($O10<>"DA",0,ROUND($E10-$E10/(1+$K10),2)-$Q10)) -> 6.6 | S10: =IF($E10="","",IFERROR(VLOOKUP($G10,tbl_natura,8,FALSE()),"")) -> Deductibil | T10: =IF($E10="","",IFERROR(VLOOKUP($H10&"|"&$I10,tbl_deducere,6,FALSE()),"")&IF(AND($H10="Bon fiscal",$E10>decl_plafon_lei)," | peste plafonul facturii simplificate","")&IF(decl_platitor_tva<>"DA"," | societate neplătitoare de TVA","")&IF($L10="Scutit cu drept de deducere"," | operațiune scutită — TVA zero","")) -> Bon fără CUI — TVA nedeductibil; justificare cu ordin de deplasare
B11: 4 | C11: OLIMPIA PARKING | D11: 46219 | E11: 200 | F11: RON | G11: PARCARE | H11: Bon fiscal | I11: NU | J11: =IF($E11="","",IFERROR(VLOOKUP($G11,tbl_natura,4,FALSE()),"cod invalid")) -> 625 | K11: =IF($E11="","",IFERROR(VLOOKUP($G11,tbl_natura,5,FALSE()),0)) -> 0.21 | L11: =IF($E11="","",IFERROR(VLOOKUP($G11,tbl_natura,6,FALSE()),"")) -> Taxabil | M11: =IF($E11="","",IFERROR(VLOOKUP($G11,tbl_natura,7,FALSE()),0)) -> 1 | N11: =IF($E11="","",IF(decl_platitor_tva<>"DA","NU",IF(IFERROR(VLOOKUP($H11&"|"&$I11,tbl_deducere,4,FALSE()),"NU")<>"DA","NU",IF(AND($H11="Bon fiscal",$E11>decl_plafon_lei),"NU",IF($K11=0,"NU","DA"))))) -> NU | O11: =IF($E11="","",IFERROR(VLOOKUP($H11&"|"&$I11,tbl_deducere,5,FALSE()),"NU")) -> DA | P11: =IF($E11="","",IF($O11<>"DA",0,$E11-$Q11)) -> 200 | Q11: =IF($E11="","",IF($N11<>"DA",0,ROUND(($E11-$E11/(1+$K11))*$M11,2))) -> 0 | R11: =IF($E11="","",IF($O11<>"DA",0,ROUND($E11-$E11/(1+$K11),2)-$Q11)) -> 34.71 | S11: =IF($E11="","",IFERROR(VLOOKUP($G11,tbl_natura,8,FALSE()),"")) -> Deductibil | T11: =IF($E11="","",IFERROR(VLOOKUP($H11&"|"&$I11,tbl_deducere,6,FALSE()),"")&IF(AND($H11="Bon fiscal",$E11>decl_plafon_lei)," | peste plafonul facturii simplificate","")&IF(decl_platitor_tva<>"DA"," | societate neplătitoare de TVA","")&IF($L11="Scutit cu drept de deducere"," | operațiune scutită — TVA zero","")) -> Bon fără CUI — TVA nedeductibil; justificare cu ordin de deplasare
B12: 5 | C12: OLIMPIA PARKING | D12: 46233 | E12: 200 | F12: RON | G12: PARCARE | H12: Bon fiscal | I12: NU | J12: =IF($E12="","",IFERROR(VLOOKUP($G12,tbl_natura,4,FALSE()),"cod invalid")) -> 625 | K12: =IF($E12="","",IFERROR(VLOOKUP($G12,tbl_natura,5,FALSE()),0)) -> 0.21 | L12: =IF($E12="","",IFERROR(VLOOKUP($G12,tbl_natura,6,FALSE()),"")) -> Taxabil | M12: =IF($E12="","",IFERROR(VLOOKUP($G12,tbl_natura,7,FALSE()),0)) -> 1 | N12: =IF($E12="","",IF(decl_platitor_tva<>"DA","NU",IF(IFERROR(VLOOKUP($H12&"|"&$I12,tbl_deducere,4,FALSE()),"NU")<>"DA","NU",IF(AND($H12="Bon fiscal",$E12>decl_plafon_lei),"NU",IF($K12=0,"NU","DA"))))) -> NU | O12: =IF($E12="","",IFERROR(VLOOKUP($H12&"|"&$I12,tbl_deducere,5,FALSE()),"NU")) -> DA | P12: =IF($E12="","",IF($O12<>"DA",0,$E12-$Q12)) -> 200 | Q12: =IF($E12="","",IF($N12<>"DA",0,ROUND(($E12-$E12/(1+$K12))*$M12,2))) -> 0 | R12: =IF($E12="","",IF($O12<>"DA",0,ROUND($E12-$E12/(1+$K12),2)-$Q12)) -> 34.71 | S12: =IF($E12="","",IFERROR(VLOOKUP($G12,tbl_natura,8,FALSE()),"")) -> Deductibil | T12: =IF($E12="","",IFERROR(VLOOKUP($H12&"|"&$I12,tbl_deducere,6,FALSE()),"")&IF(AND($H12="Bon fiscal",$E12>decl_plafon_lei)," | peste plafonul facturii simplificate","")&IF(decl_platitor_tva<>"DA"," | societate neplătitoare de TVA","")&IF($L12="Scutit cu drept de deducere"," | operațiune scutită — TVA zero","")) -> Bon fără CUI — TVA nedeductibil; justificare cu ordin de deplasare
J13: =IF($E13="","",IFERROR(VLOOKUP($G13,tbl_natura,4,FALSE()),"cod invalid")) | K13: =IF($E13="","",IFERROR(VLOOKUP($G13,tbl_natura,5,FALSE()),0)) | L13: =IF($E13="","",IFERROR(VLOOKUP($G13,tbl_natura,6,FALSE()),"")) | M13: =IF($E13="","",IFERROR(VLOOKUP($G13,tbl_natura,7,FALSE()),0)) | N13: =IF($E13="","",IF(decl_platitor_tva<>"DA","NU",IF(IFERROR(VLOOKUP($H13&"|"&$I13,tbl_deducere,4,FALSE()),"NU")<>"DA","NU",IF(AND($H13="Bon fiscal",$E13>decl_plafon_lei),"NU",IF($K13=0,"NU","DA"))))) | O13: =IF($E13="","",IFERROR(VLOOKUP($H13&"|"&$I13,tbl_deducere,5,FALSE()),"NU")) | P13: =IF($E13="","",IF($O13<>"DA",0,$E13-$Q13)) | Q13: =IF($E13="","",IF($N13<>"DA",0,ROUND(($E13-$E13/(1+$K13))*$M13,2))) | R13: =IF($E13="","",IF($O13<>"DA",0,ROUND($E13-$E13/(1+$K13),2)-$Q13)) | S13: =IF($E13="","",IFERROR(VLOOKUP($G13,tbl_natura,8,FALSE()),"")) | T13: =IF($E13="","",IFERROR(VLOOKUP($H13&"|"&$I13,tbl_deducere,6,FALSE()),"")&IF(AND($H13="Bon fiscal",$E13>decl_plafon_lei)," | peste plafonul facturii simplificate","")&IF(decl_platitor_tva<>"DA"," | societate neplătitoare de TVA","")&IF($L13="Scutit cu drept de deducere"," | operațiune scutită — TVA zero",""))
J14: =IF($E14="","",IFERROR(VLOOKUP($G14,tbl_natura,4,FALSE()),"cod invalid")) | K14: =IF($E14="","",IFERROR(VLOOKUP($G14,tbl_natura,5,FALSE()),0)) | L14: =IF($E14="","",IFERROR(VLOOKUP($G14,tbl_natura,6,FALSE()),"")) | M14: =IF($E14="","",IFERROR(VLOOKUP($G14,tbl_natura,7,FALSE()),0)) | N14: =IF($E14="","",IF(decl_platitor_tva<>"DA","NU",IF(IFERROR(VLOOKUP($H14&"|"&$I14,tbl_deducere,4,FALSE()),"NU")<>"DA","NU",IF(AND($H14="Bon fiscal",$E14>decl_plafon_lei),"NU",IF($K14=0,"NU","DA"))))) | O14: =IF($E14="","",IFERROR(VLOOKUP($H14&"|"&$I14,tbl_deducere,5,FALSE()),"NU")) | P14: =IF($E14="","",IF($O14<>"DA",0,$E14-$Q14)) | Q14: =IF($E14="","",IF($N14<>"DA",0,ROUND(($E14-$E14/(1+$K14))*$M14,2))) | R14: =IF($E14="","",IF($O14<>"DA",0,ROUND($E14-$E14/(1+$K14),2)-$Q14)) | S14: =IF($E14="","",IFERROR(VLOOKUP($G14,tbl_natura,8,FALSE()),"")) | T14: =IF($E14="","",IFERROR(VLOOKUP($H14&"|"&$I14,tbl_deducere,6,FALSE()),"")&IF(AND($H14="Bon fiscal",$E14>decl_plafon_lei)," | peste plafonul facturii simplificate","")&IF(decl_platitor_tva<>"DA"," | societate neplătitoare de TVA","")&IF($L14="Scutit cu drept de deducere"," | operațiune scutită — TVA zero",""))
J15: =IF($E15="","",IFERROR(VLOOKUP($G15,tbl_natura,4,FALSE()),"cod invalid")) | K15: =IF($E15="","",IFERROR(VLOOKUP($G15,tbl_natura,5,FALSE()),0)) | L15: =IF($E15="","",IFERROR(VLOOKUP($G15,tbl_natura,6,FALSE()),"")) | M15: =IF($E15="","",IFERROR(VLOOKUP($G15,tbl_natura,7,FALSE()),0)) | N15: =IF($E15="","",IF(decl_platitor_tva<>"DA","NU",IF(IFERROR(VLOOKUP($H15&"|"&$I15,tbl_deducere,4,FALSE()),"NU")<>"DA","NU",IF(AND($H15="Bon fiscal",$E15>decl_plafon_lei),"NU",IF($K15=0,"NU","DA"))))) | O15: =IF($E15="","",IFERROR(VLOOKUP($H15&"|"&$I15,tbl_deducere,5,FALSE()),"NU")) | P15: =IF($E15="","",IF($O15<>"DA",0,$E15-$Q15)) | Q15: =IF($E15="","",IF($N15<>"DA",0,ROUND(($E15-$E15/(1+$K15))*$M15,2))) | R15: =IF($E15="","",IF($O15<>"DA",0,ROUND($E15-$E15/(1+$K15),2)-$Q15)) | S15: =IF($E15="","",IFERROR(VLOOKUP($G15,tbl_natura,8,FALSE()),"")) | T15: =IF($E15="","",IFERROR(VLOOKUP($H15&"|"&$I15,tbl_deducere,6,FALSE()),"")&IF(AND($H15="Bon fiscal",$E15>decl_plafon_lei)," | peste plafonul facturii simplificate","")&IF(decl_platitor_tva<>"DA"," | societate neplătitoare de TVA","")&IF($L15="Scutit cu drept de deducere"," | operațiune scutită — TVA zero",""))
J16: =IF($E16="","",IFERROR(VLOOKUP($G16,tbl_natura,4,FALSE()),"cod invalid")) | K16: =IF($E16="","",IFERROR(VLOOKUP($G16,tbl_natura,5,FALSE()),0)) | L16: =IF($E16="","",IFERROR(VLOOKUP($G16,tbl_natura,6,FALSE()),"")) | M16: =IF($E16="","",IFERROR(VLOOKUP($G16,tbl_natura,7,FALSE()),0)) | N16: =IF($E16="","",IF(decl_platitor_tva<>"DA","NU",IF(IFERROR(VLOOKUP($H16&"|"&$I16,tbl_deducere,4,FALSE()),"NU")<>"DA","NU",IF(AND($H16="Bon fiscal",$E16>decl_plafon_lei),"NU",IF($K16=0,"NU","DA"))))) | O16: =IF($E16="","",IFERROR(VLOOKUP($H16&"|"&$I16,tbl_deducere,5,FALSE()),"NU")) | P16: =IF($E16="","",IF($O16<>"DA",0,$E16-$Q16)) | Q16: =IF($E16="","",IF($N16<>"DA",0,ROUND(($E16-$E16/(1+$K16))*$M16,2))) | R16: =IF($E16="","",IF($O16<>"DA",0,ROUND($E16-$E16/(1+$K16),2)-$Q16)) | S16: =IF($E16="","",IFERROR(VLOOKUP($G16,tbl_natura,8,FALSE()),"")) | T16: =IF($E16="","",IFERROR(VLOOKUP($H16&"|"&$I16,tbl_deducere,6,FALSE()),"")&IF(AND($H16="Bon fiscal",$E16>decl_plafon_lei)," | peste plafonul facturii simplificate","")&IF(decl_platitor_tva<>"DA"," | societate neplătitoare de TVA","")&IF($L16="Scutit cu drept de deducere"," | operațiune scutită — TVA zero",""))
J17: =IF($E17="","",IFERROR(VLOOKUP($G17,tbl_natura,4,FALSE()),"cod invalid")) | K17: =IF($E17="","",IFERROR(VLOOKUP($G17,tbl_natura,5,FALSE()),0)) | L17: =IF($E17="","",IFERROR(VLOOKUP($G17,tbl_natura,6,FALSE()),"")) | M17: =IF($E17="","",IFERROR(VLOOKUP($G17,tbl_natura,7,FALSE()),0)) | N17: =IF($E17="","",IF(decl_platitor_tva<>"DA","NU",IF(IFERROR(VLOOKUP($H17&"|"&$I17,tbl_deducere,4,FALSE()),"NU")<>"DA","NU",IF(AND($H17="Bon fiscal",$E17>decl_plafon_lei),"NU",IF($K17=0,"NU","DA"))))) | O17: =IF($E17="","",IFERROR(VLOOKUP($H17&"|"&$I17,tbl_deducere,5,FALSE()),"NU")) | P17: =IF($E17="","",IF($O17<>"DA",0,$E17-$Q17)) | Q17: =IF($E17="","",IF($N17<>"DA",0,ROUND(($E17-$E17/(1+$K17))*$M17,2))) | R17: =IF($E17="","",IF($O17<>"DA",0,ROUND($E17-$E17/(1+$K17),2)-$Q17)) | S17: =IF($E17="","",IFERROR(VLOOKUP($G17,tbl_natura,8,FALSE()),"")) | T17: =IF($E17="","",IFERROR(VLOOKUP($H17&"|"&$I17,tbl_deducere,6,FALSE()),"")&IF(AND($H17="Bon fiscal",$E17>decl_plafon_lei)," | peste plafonul facturii simplificate","")&IF(decl_platitor_tva<>"DA"," | societate neplătitoare de TVA","")&IF($L17="Scutit cu drept de deducere"," | operațiune scutită — TVA zero",""))
J18: =IF($E18="","",IFERROR(VLOOKUP($G18,tbl_natura,4,FALSE()),"cod invalid")) | K18: =IF($E18="","",IFERROR(VLOOKUP($G18,tbl_natura,5,FALSE()),0)) | L18: =IF($E18="","",IFERROR(VLOOKUP($G18,tbl_natura,6,FALSE()),"")) | M18: =IF($E18="","",IFERROR(VLOOKUP($G18,tbl_natura,7,FALSE()),0)) | N18: =IF($E18="","",IF(decl_platitor_tva<>"DA","NU",IF(IFERROR(VLOOKUP($H18&"|"&$I18,tbl_deducere,4,FALSE()),"NU")<>"DA","NU",IF(AND($H18="Bon fiscal",$E18>decl_plafon_lei),"NU",IF($K18=0,"NU","DA"))))) | O18: =IF($E18="","",IFERROR(VLOOKUP($H18&"|"&$I18,tbl_deducere,5,FALSE()),"NU")) | P18: =IF($E18="","",IF($O18<>"DA",0,$E18-$Q18)) | Q18: =IF($E18="","",IF($N18<>"DA",0,ROUND(($E18-$E18/(1+$K18))*$M18,2))) | R18: =IF($E18="","",IF($O18<>"DA",0,ROUND($E18-$E18/(1+$K18),2)-$Q18)) | S18: =IF($E18="","",IFERROR(VLOOKUP($G18,tbl_natura,8,FALSE()),"")) | T18: =IF($E18="","",IFERROR(VLOOKUP($H18&"|"&$I18,tbl_deducere,6,FALSE()),"")&IF(AND($H18="Bon fiscal",$E18>decl_plafon_lei)," | peste plafonul facturii simplificate","")&IF(decl_platitor_tva<>"DA"," | societate neplătitoare de TVA","")&IF($L18="Scutit cu drept de deducere"," | operațiune scutită — TVA zero",""))
J19: =IF($E19="","",IFERROR(VLOOKUP($G19,tbl_natura,4,FALSE()),"cod invalid")) | K19: =IF($E19="","",IFERROR(VLOOKUP($G19,tbl_natura,5,FALSE()),0)) | L19: =IF($E19="","",IFERROR(VLOOKUP($G19,tbl_natura,6,FALSE()),"")) | M19: =IF($E19="","",IFERROR(VLOOKUP($G19,tbl_natura,7,FALSE()),0)) | N19: =IF($E19="","",IF(decl_platitor_tva<>"DA","NU",IF(IFERROR(VLOOKUP($H19&"|"&$I19,tbl_deducere,4,FALSE()),"NU")<>"DA","NU",IF(AND($H19="Bon fiscal",$E19>decl_plafon_lei),"NU",IF($K19=0,"NU","DA"))))) | O19: =IF($E19="","",IFERROR(VLOOKUP($H19&"|"&$I19,tbl_deducere,5,FALSE()),"NU")) | P19: =IF($E19="","",IF($O19<>"DA",0,$E19-$Q19)) | Q19: =IF($E19="","",IF($N19<>"DA",0,ROUND(($E19-$E19/(1+$K19))*$M19,2))) | R19: =IF($E19="","",IF($O19<>"DA",0,ROUND($E19-$E19/(1+$K19),2)-$Q19)) | S19: =IF($E19="","",IFERROR(VLOOKUP($G19,tbl_natura,8,FALSE()),"")) | T19: =IF($E19="","",IFERROR(VLOOKUP($H19&"|"&$I19,tbl_deducere,6,FALSE()),"")&IF(AND($H19="Bon fiscal",$E19>decl_plafon_lei)," | peste plafonul facturii simplificate","")&IF(decl_platitor_tva<>"DA"," | societate neplătitoare de TVA","")&IF($L19="Scutit cu drept de deducere"," | operațiune scutită — TVA zero",""))
J20: =IF($E20="","",IFERROR(VLOOKUP($G20,tbl_natura,4,FALSE()),"cod invalid")) | K20: =IF($E20="","",IFERROR(VLOOKUP($G20,tbl_natura,5,FALSE()),0)) | L20: =IF($E20="","",IFERROR(VLOOKUP($G20,tbl_natura,6,FALSE()),"")) | M20: =IF($E20="","",IFERROR(VLOOKUP($G20,tbl_natura,7,FALSE()),0)) | N20: =IF($E20="","",IF(decl_platitor_tva<>"DA","NU",IF(IFERROR(VLOOKUP($H20&"|"&$I20,tbl_deducere,4,FALSE()),"NU")<>"DA","NU",IF(AND($H20="Bon fiscal",$E20>decl_plafon_lei),"NU",IF($K20=0,"NU","DA"))))) | O20: =IF($E20="","",IFERROR(VLOOKUP($H20&"|"&$I20,tbl_deducere,5,FALSE()),"NU")) | P20: =IF($E20="","",IF($O20<>"DA",0,$E20-$Q20)) | Q20: =IF($E20="","",IF($N20<>"DA",0,ROUND(($E20-$E20/(1+$K20))*$M20,2))) | R20: =IF($E20="","",IF($O20<>"DA",0,ROUND($E20-$E20/(1+$K20),2)-$Q20)) | S20: =IF($E20="","",IFERROR(VLOOKUP($G20,tbl_natura,8,FALSE()),"")) | T20: =IF($E20="","",IFERROR(VLOOKUP($H20&"|"&$I20,tbl_deducere,6,FALSE()),"")&IF(AND($H20="Bon fiscal",$E20>decl_plafon_lei)," | peste plafonul facturii simplificate","")&IF(decl_platitor_tva<>"DA"," | societate neplătitoare de TVA","")&IF($L20="Scutit cu drept de deducere"," | operațiune scutită — TVA zero",""))
J21: =IF($E21="","",IFERROR(VLOOKUP($G21,tbl_natura,4,FALSE()),"cod invalid")) | K21: =IF($E21="","",IFERROR(VLOOKUP($G21,tbl_natura,5,FALSE()),0)) | L21: =IF($E21="","",IFERROR(VLOOKUP($G21,tbl_natura,6,FALSE()),"")) | M21: =IF($E21="","",IFERROR(VLOOKUP($G21,tbl_natura,7,FALSE()),0)) | N21: =IF($E21="","",IF(decl_platitor_tva<>"DA","NU",IF(IFERROR(VLOOKUP($H21&"|"&$I21,tbl_deducere,4,FALSE()),"NU")<>"DA","NU",IF(AND($H21="Bon fiscal",$E21>decl_plafon_lei),"NU",IF($K21=0,"NU","DA"))))) | O21: =IF($E21="","",IFERROR(VLOOKUP($H21&"|"&$I21,tbl_deducere,5,FALSE()),"NU")) | P21: =IF($E21="","",IF($O21<>"DA",0,$E21-$Q21)) | Q21: =IF($E21="","",IF($N21<>"DA",0,ROUND(($E21-$E21/(1+$K21))*$M21,2))) | R21: =IF($E21="","",IF($O21<>"DA",0,ROUND($E21-$E21/(1+$K21),2)-$Q21)) | S21: =IF($E21="","",IFERROR(VLOOKUP($G21,tbl_natura,8,FALSE()),"")) | T21: =IF($E21="","",IFERROR(VLOOKUP($H21&"|"&$I21,tbl_deducere,6,FALSE()),"")&IF(AND($H21="Bon fiscal",$E21>decl_plafon_lei)," | peste plafonul facturii simplificate","")&IF(decl_platitor_tva<>"DA"," | societate neplătitoare de TVA","")&IF($L21="Scutit cu drept de deducere"," | operațiune scutită — TVA zero",""))
J22: =IF($E22="","",IFERROR(VLOOKUP($G22,tbl_natura,4,FALSE()),"cod invalid")) | K22: =IF($E22="","",IFERROR(VLOOKUP($G22,tbl_natura,5,FALSE()),0)) | L22: =IF($E22="","",IFERROR(VLOOKUP($G22,tbl_natura,6,FALSE()),"")) | M22: =IF($E22="","",IFERROR(VLOOKUP($G22,tbl_natura,7,FALSE()),0)) | N22: =IF($E22="","",IF(decl_platitor_tva<>"DA","NU",IF(IFERROR(VLOOKUP($H22&"|"&$I22,tbl_deducere,4,FALSE()),"NU")<>"DA","NU",IF(AND($H22="Bon fiscal",$E22>decl_plafon_lei),"NU",IF($K22=0,"NU","DA"))))) | O22: =IF($E22="","",IFERROR(VLOOKUP($H22&"|"&$I22,tbl_deducere,5,FALSE()),"NU")) | P22: =IF($E22="","",IF($O22<>"DA",0,$E22-$Q22)) | Q22: =IF($E22="","",IF($N22<>"DA",0,ROUND(($E22-$E22/(1+$K22))*$M22,2))) | R22: =IF($E22="","",IF($O22<>"DA",0,ROUND($E22-$E22/(1+$K22),2)-$Q22)) | S22: =IF($E22="","",IFERROR(VLOOKUP($G22,tbl_natura,8,FALSE()),"")) | T22: =IF($E22="","",IFERROR(VLOOKUP($H22&"|"&$I22,tbl_deducere,6,FALSE()),"")&IF(AND($H22="Bon fiscal",$E22>decl_plafon_lei)," | peste plafonul facturii simplificate","")&IF(decl_platitor_tva<>"DA"," | societate neplătitoare de TVA","")&IF($L22="Scutit cu drept de deducere"," | operațiune scutită — TVA zero",""))
J23: =IF($E23="","",IFERROR(VLOOKUP($G23,tbl_natura,4,FALSE()),"cod invalid")) | K23: =IF($E23="","",IFERROR(VLOOKUP($G23,tbl_natura,5,FALSE()),0)) | L23: =IF($E23="","",IFERROR(VLOOKUP($G23,tbl_natura,6,FALSE()),"")) | M23: =IF($E23="","",IFERROR(VLOOKUP($G23,tbl_natura,7,FALSE()),0)) | N23: =IF($E23="","",IF(decl_platitor_tva<>"DA","NU",IF(IFERROR(VLOOKUP($H23&"|"&$I23,tbl_deducere,4,FALSE()),"NU")<>"DA","NU",IF(AND($H23="Bon fiscal",$E23>decl_plafon_lei),"NU",IF($K23=0,"NU","DA"))))) | O23: =IF($E23="","",IFERROR(VLOOKUP($H23&"|"&$I23,tbl_deducere,5,FALSE()),"NU")) | P23: =IF($E23="","",IF($O23<>"DA",0,$E23-$Q23)) | Q23: =IF($E23="","",IF($N23<>"DA",0,ROUND(($E23-$E23/(1+$K23))*$M23,2))) | R23: =IF($E23="","",IF($O23<>"DA",0,ROUND($E23-$E23/(1+$K23),2)-$Q23)) | S23: =IF($E23="","",IFERROR(VLOOKUP($G23,tbl_natura,8,FALSE()),"")) | T23: =IF($E23="","",IFERROR(VLOOKUP($H23&"|"&$I23,tbl_deducere,6,FALSE()),"")&IF(AND($H23="Bon fiscal",$E23>decl_plafon_lei)," | peste plafonul facturii simplificate","")&IF(decl_platitor_tva<>"DA"," | societate neplătitoare de TVA","")&IF($L23="Scutit cu drept de deducere"," | operațiune scutită — TVA zero",""))
J24: =IF($E24="","",IFERROR(VLOOKUP($G24,tbl_natura,4,FALSE()),"cod invalid")) | K24: =IF($E24="","",IFERROR(VLOOKUP($G24,tbl_natura,5,FALSE()),0)) | L24: =IF($E24="","",IFERROR(VLOOKUP($G24,tbl_natura,6,FALSE()),"")) | M24: =IF($E24="","",IFERROR(VLOOKUP($G24,tbl_natura,7,FALSE()),0)) | N24: =IF($E24="","",IF(decl_platitor_tva<>"DA","NU",IF(IFERROR(VLOOKUP($H24&"|"&$I24,tbl_deducere,4,FALSE()),"NU")<>"DA","NU",IF(AND($H24="Bon fiscal",$E24>decl_plafon_lei),"NU",IF($K24=0,"NU","DA"))))) | O24: =IF($E24="","",IFERROR(VLOOKUP($H24&"|"&$I24,tbl_deducere,5,FALSE()),"NU")) | P24: =IF($E24="","",IF($O24<>"DA",0,$E24-$Q24)) | Q24: =IF($E24="","",IF($N24<>"DA",0,ROUND(($E24-$E24/(1+$K24))*$M24,2))) | R24: =IF($E24="","",IF($O24<>"DA",0,ROUND($E24-$E24/(1+$K24),2)-$Q24)) | S24: =IF($E24="","",IFERROR(VLOOKUP($G24,tbl_natura,8,FALSE()),"")) | T24: =IF($E24="","",IFERROR(VLOOKUP($H24&"|"&$I24,tbl_deducere,6,FALSE()),"")&IF(AND($H24="Bon fiscal",$E24>decl_plafon_lei)," | peste plafonul facturii simplificate","")&IF(decl_platitor_tva<>"DA"," | societate neplătitoare de TVA","")&IF($L24="Scutit cu drept de deducere"," | operațiune scutită — TVA zero",""))
... J27: =IF($E27="","",IFERROR(VLOOKUP($G27,tbl_natura,4,FALSE()),"cod invalid")) | K27: =IF($E27="","",IFERROR(VLOOKUP($G27,tbl_natura,5,FALSE()),0)) | L27: =IF($E27="","",IFERROR(VLOOKUP($G27,tbl_natura,6,FALSE()),"")) | M27: =IF($E27="","",IFERROR(VLOOKUP($G27,tbl_natura,7,FALSE()),0)) | N27: =IF($E27="","",IF(decl_platitor_tva<>"DA","NU",IF(IFERROR(VLOOKUP($H27&"|"&$I27,tbl_deducere,4,FALSE()),"NU")<>"DA","NU",IF(AND($H27="Bon fiscal",$E27>decl_plafon_lei),"NU",IF($K27=0,"NU","DA"))))) | O27: =IF($E27="","",IFERROR(VLOOKUP($H27&"|"&$I27,tbl_deducere,5,FALSE()),"NU")) | P27: =IF($E27="","",IF($O27<>"DA",0,$E27-$Q27)) | Q27: =IF($E27="","",IF($N27<>"DA",0,ROUND(($E27-$E27/(1+$K27))*$M27,2))) | R27: =IF($E27="","",IF($O27<>"DA",0,ROUND($E27-$E27/(1+$K27),2)-$Q27)) | S27: =IF($E27="","",IFERROR(VLOOKUP($G27,tbl_natura,8,FALSE()),"")) | T27: =IF($E27="","",IFERROR(VLOOKUP($H27&"|"&$I27,tbl_deducere,6,FALSE()),"")&IF(AND($H27="Bon fiscal",$E27>decl_plafon_lei)," | peste plafonul facturii simplificate","")&IF(decl_platitor_tva<>"DA"," | societate neplătitoare de TVA","")&IF($L27="Scutit cu drept de deducere"," | operațiune scutită — TVA zero",""))
C29: TOTAL | F29: =SUM(E8:E27) -> 3938.76 | Q29: =SUM(P8:P27) -> 3938.76 | R29: =SUM(Q8:Q27) -> 0 | S29: =SUM(R8:R27) -> 76.02
C31: Control: bază + TVA deductibil + sume neacceptate = total decont | Q31: =Q29+R29+SUMIF($O$8:$O$27,"NU",$E$8:$E$27) -> 3938.76 | R31: =Q31-F29 -> 0 | S31: =IF(ROUND(R31,2)=0,"OK","EROARE") -> OK
B34: Sinteză pe cont — alimentează jurnalul de cheltuieli / Account summary
B36: Cont | C36: Denumire cont | D36: Sumă
B37: 624 | C37: Cheltuieli cu transportul de bunuri și personal | D37: =SUMIF($J$8:$J$27,$B37,$P$8:$P$27) -> 0
B38: 625 | C38: Cheltuieli cu deplasări, detașări și transferări | D38: =SUMIF($J$8:$J$27,$B38,$P$8:$P$27) -> 3938.76
B39: 6231 | C39: Cheltuieli de protocol | D39: =SUMIF($J$8:$J$27,$B39,$P$8:$P$27) -> 0
B40: 6022 | C40: Cheltuieli cu combustibilul | D40: =SUMIF($J$8:$J$27,$B40,$P$8:$P$27) -> 0
B41: 6028 | C41: Cheltuieli cu alte materiale consumabile | D41: =SUMIF($J$8:$J$27,$B41,$P$8:$P$27) -> 0
B42: 628 | C42: Alte cheltuieli cu serviciile executate de terți | D42: =SUMIF($J$8:$J$27,$B42,$P$8:$P$27) -> 0
B43: 6588 | C43: Alte cheltuieli de exploatare | D43: =SUMIF($J$8:$J$27,$B43,$P$8:$P$27) -> 0
B44: 4426 | C44: TVA deductibilă | D44: =$R$29 -> 0
C45: Total sinteză | D45: =SUM(D37:D44) -> 3938.76
C46: Verificare acoperire conturi (trebuie 0) | D46: =ROUND(D45-Q29-R29,2) -> 0
B48: Memo fiscal — impozit pe profit / Corporate tax memo
C50: Deductibil integral | D50: =SUMIF($S$8:$S$27,"Deductibil",$P$8:$P$27) -> 3938.76
C51: Deductibil limitat 2% (protocol) | D51: =SUMIF($S$8:$S$27,"Deductibil limitat 2%",$P$8:$P$27) -> 0
C52: Deductibil limitat 50% (vehicule) | D52: =SUMIF($S$8:$S$27,"Deductibil limitat 50%",$P$8:$P$27) -> 0
...

Sheet Jurnale
B2: Jurnale pe momente contabile / Journals by accounting moment
C4: Nu se scrie nimic manual în acest sheet. Toate sumele derivă din Declarații și Decont.
C5: Nothing is typed here. All amounts derive from Declarations and the claim register.
B7: Bloc 1 — Acordarea avansului de trezorerie / Cash advance granted
C9: =IF(decl_avans=0,"Nu se aplică — nu s-a acordat avans.","Data jurnal: data acordării avansului, conform extrasului de cont.") -> Nu se aplică — nu s-a acordat avans.
C10: =IF(decl_avans=0,"Not applicable — no advance was granted.","Journal date: advance date, per bank statement.") -> Not applicable — no advance was granted.
E12: Înregistrări / Entries
G14: Dr | J14: Cr
G15: Cont | H15: Sumă | I15: Descriere | J15: Cont | K15: Sumă | L15: Descriere
F16: Avans | G16: =decl_cont_avans -> 542 | H16: =decl_avans -> 0 | I16: ="Avans de trezorerie acordat titularului"&desc_sufix -> Avans de trezorerie acordat titularului - decont /31.07.2026 - CHIRIACESCU DIANA | J16: =decl_cont_trezorerie -> 5121 | K16: =decl_avans -> 0 | L16: ="Plata avansului de trezorerie"&desc_sufix -> Plata avansului de trezorerie - decont /31.07.2026 - CHIRIACESCU DIANA
E18: Sumar / Summary
H20: Dr | I20: Cr
F21: =decl_cont_avans -> 542 | G21: Avansuri de trezorerie | H21: =H16 -> 0
F22: =decl_cont_trezorerie -> 5121 | G22: Trezorerie | I22: =K16 -> 0
G24: Check (Dr − Cr = 0) | H24: =SUM(H21:H22) -> 0 | I24: =SUM(I21:I22) -> 0 | J24: =ROUND(H24-I24,2) -> 0
B27: Bloc 2 — Recunoașterea cheltuielilor din decont / Expense recognition
C29: Data jurnal: data decontului. Sumele vin din sinteza pe cont a registrului de linii.
C30: Journal date: claim date. Amounts come from the account summary of the line register.
E32: Înregistrări / Entries
G34: Dr | J34: Cr
G35: Cont | H35: Sumă | I35: Descriere | J35: Cont | K35: Sumă | L35: Descriere
F36: Cheltuieli decont | G36: =Decont!$B$37 -> 624 | H36: =Decont!$D$37 -> 0 | I36: ="Decont cheltuieli — "&Decont!$C$37&desc_sufix -> Decont cheltuieli — Cheltuieli cu transportul de bunuri și personal - decont /31.07.2026 - CHIRIACESCU DIANA | J36: =decl_cont_datorie -> 542 | K36: =dec_total_datorat -> 3938.76 | L36: ="Datorie față de titularul decontului"&desc_sufix -> Datorie față de titularul decontului - decont /31.07.2026 - CHIRIACESCU DIANA
G37: =Decont!$B$38 -> 625 | H37: =Decont!$D$38 -> 3938.76 | I37: ="Decont cheltuieli — "&Decont!$C$38&desc_sufix -> Decont cheltuieli — Cheltuieli cu deplasări, detașări și transferări - decont /31.07.2026 - CHIRIACESCU DIANA
G38: =Decont!$B$39 -> 6231 | H38: =Decont!$D$39 -> 0 | I38: ="Decont cheltuieli — "&Decont!$C$39&desc_sufix -> Decont cheltuieli — Cheltuieli de protocol - decont /31.07.2026 - CHIRIACESCU DIANA
G39: =Decont!$B$40 -> 6022 | H39: =Decont!$D$40 -> 0 | I39: ="Decont cheltuieli — "&Decont!$C$40&desc_sufix -> Decont cheltuieli — Cheltuieli cu combustibilul - decont /31.07.2026 - CHIRIACESCU DIANA
G40: =Decont!$B$41 -> 6028 | H40: =Decont!$D$41 -> 0 | I40: ="Decont cheltuieli — "&Decont!$C$41&desc_sufix -> Decont cheltuieli — Cheltuieli cu alte materiale consumabile - decont /31.07.2026 - CHIRIACESCU DIANA
G41: =Decont!$B$42 -> 628 | H41: =Decont!$D$42 -> 0 | I41: ="Decont cheltuieli — "&Decont!$C$42&desc_sufix -> Decont cheltuieli — Alte cheltuieli cu serviciile executate de terți - decont /31.07.2026 - CHIRIACESCU DIANA
G42: =Decont!$B$43 -> 6588 | H42: =Decont!$D$43 -> 0 | I42: ="Decont cheltuieli — "&Decont!$C$43&desc_sufix -> Decont cheltuieli — Alte cheltuieli de exploatare - decont /31.07.2026 - CHIRIACESCU DIANA
G43: =Decont!$B$44 -> 4426 | H43: =Decont!$D$44 -> 0 | I43: ="Decont cheltuieli — "&Decont!$C$44&desc_sufix -> Decont cheltuieli — TVA deductibilă - decont /31.07.2026 - CHIRIACESCU DIANA
E45: Sumar / Summary
H47: Dr | I47: Cr
F48: =G36 -> 624 | G48: =Decont!$C$37 -> Cheltuieli cu transportul de bunuri și personal | H48: =H36 -> 0
F49: =G37 -> 625 | G49: =Decont!$C$38 -> Cheltuieli cu deplasări, detașări și transferări | H49: =H37 -> 3938.76
F50: =G38 -> 6231 | G50: =Decont!$C$39 -> Cheltuieli de protocol | H50: =H38 -> 0
F51: =G39 -> 6022 | G51: =Decont!$C$40 -> Cheltuieli cu combustibilul | H51: =H39 -> 0
F52: =G40 -> 6028 | G52: =Decont!$C$41 -> Cheltuieli cu alte materiale consumabile | H52: =H40 -> 0
F53: =G41 -> 628 | G53: =Decont!$C$42 -> Alte cheltuieli cu serviciile executate de terți | H53: =H41 -> 0
F54: =G42 -> 6588 | G54: =Decont!$C$43 -> Alte cheltuieli de exploatare | H54: =H42 -> 0
F55: =G43 -> 4426 | G55: =Decont!$C$44 -> TVA deductibilă | H55: =H43 -> 0
F56: =decl_cont_datorie -> 542 | G56: Datorie față de titular | I56: =K36 -> 3938.76
...

Sheet NotaExport
B2: Notă contabilă pentru import / Journal entry export
C4: Un rând = o înregistrare. Filtrează pe coloana „Include” = DA înainte de import.
C5: One row = one entry. Filter Include = DA before importing.
B7: Nr. | C7: Bloc | D7: Data | E7: Cont Dr | F7: Cont Cr | G7: Sumă | H7: Descriere | I7: Analitic | J7: Document | K7: Include
B8: 1 | C8: Bloc 1 — Avans | D8: =IF(ROUND(Jurnale!H16,2)=0,"",decl_data_avans) | E8: =Jurnale!G16 -> 542 | F8: =Jurnale!J16 -> 5121 | G8: =Jurnale!H16 -> 0 | H8: =Jurnale!I16 -> Avans de trezorerie acordat titularului - decont /31.07.2026 - CHIRIACESCU DIANA | I8: =decl_titular -> CHIRIACESCU DIANA | J8: ="Decont nr. "&decl_nr_decont -> #REF! | K8: =IF(ROUND(G8,2)=0,"NU","DA") -> NU
B9: 2 | C9: Bloc 2 — Cheltuieli | D9: =IF(ROUND(Jurnale!H36,2)=0,"",decl_data_decont) | E9: =Jurnale!G36 -> 624 | F9: =Jurnale!J36 -> 542 | G9: =Jurnale!H36 -> 0 | H9: =Jurnale!I36 -> Decont cheltuieli — Cheltuieli cu transportul de bunuri și personal - decont /31.07.2026 - CHIRIACESCU DIANA | I9: =decl_titular -> CHIRIACESCU DIANA | J9: ="Decont nr. "&decl_nr_decont -> #REF! | K9: =IF(ROUND(G9,2)=0,"NU","DA") -> NU
B10: 3 | C10: Bloc 2 — Cheltuieli | D10: =IF(ROUND(Jurnale!H37,2)=0,"",decl_data_decont) -> 46234 | E10: =Jurnale!G37 -> 625 | F10: =Jurnale!J36 -> 542 | G10: =Jurnale!H37 -> 3938.76 | H10: =Jurnale!I37 -> Decont cheltuieli — Cheltuieli cu deplasări, detașări și transferări - decont /31.07.2026 - CHIRIACESCU DIANA | I10: =decl_titular -> CHIRIACESCU DIANA | J10: ="Decont nr. "&decl_nr_decont -> #REF! | K10: =IF(ROUND(G10,2)=0,"NU","DA") -> DA
B11: 4 | C11: Bloc 2 — Cheltuieli | D11: =IF(ROUND(Jurnale!H38,2)=0,"",decl_data_decont) | E11: =Jurnale!G38 -> 6231 | F11: =Jurnale!J36 -> 542 | G11: =Jurnale!H38 -> 0 | H11: =Jurnale!I38 -> Decont cheltuieli — Cheltuieli de protocol - decont /31.07.2026 - CHIRIACESCU DIANA | I11: =decl_titular -> CHIRIACESCU DIANA | J11: ="Decont nr. "&decl_nr_decont -> #REF! | K11: =IF(ROUND(G11,2)=0,"NU","DA") -> NU
B12: 5 | C12: Bloc 2 — Cheltuieli | D12: =IF(ROUND(Jurnale!H39,2)=0,"",decl_data_decont) | E12: =Jurnale!G39 -> 6022 | F12: =Jurnale!J36 -> 542 | G12: =Jurnale!H39 -> 0 | H12: =Jurnale!I39 -> Decont cheltuieli — Cheltuieli cu combustibilul - decont /31.07.2026 - CHIRIACESCU DIANA | I12: =decl_titular -> CHIRIACESCU DIANA | J12: ="Decont nr. "&decl_nr_decont -> #REF! | K12: =IF(ROUND(G12,2)=0,"NU","DA") -> NU
B13: 6 | C13: Bloc 2 — Cheltuieli | D13: =IF(ROUND(Jurnale!H40,2)=0,"",decl_data_decont) | E13: =Jurnale!G40 -> 6028 | F13: =Jurnale!J36 -> 542 | G13: =Jurnale!H40 -> 0 | H13: =Jurnale!I40 -> Decont cheltuieli — Cheltuieli cu alte materiale consumabile - decont /31.07.2026 - CHIRIACESCU DIANA | I13: =decl_titular -> CHIRIACESCU DIANA | J13: ="Decont nr. "&decl_nr_decont -> #REF! | K13: =IF(ROUND(G13,2)=0,"NU","DA") -> NU
B14: 7 | C14: Bloc 2 — Cheltuieli | D14: =IF(ROUND(Jurnale!H41,2)=0,"",decl_data_decont) | E14: =Jurnale!G41 -> 628 | F14: =Jurnale!J36 -> 542 | G14: =Jurnale!H41 -> 0 | H14: =Jurnale!I41 -> Decont cheltuieli — Alte cheltuieli cu serviciile executate de terți - decont /31.07.2026 - CHIRIACESCU DIANA | I14: =decl_titular -> CHIRIACESCU DIANA | J14: ="Decont nr. "&decl_nr_decont -> #REF! | K14: =IF(ROUND(G14,2)=0,"NU","DA") -> NU
B15: 8 | C15: Bloc 2 — Cheltuieli | D15: =IF(ROUND(Jurnale!H42,2)=0,"",decl_data_decont) | E15: =Jurnale!G42 -> 6588 | F15: =Jurnale!J36 -> 542 | G15: =Jurnale!H42 -> 0 | H15: =Jurnale!I42 -> Decont cheltuieli — Alte cheltuieli de exploatare - decont /31.07.2026 - CHIRIACESCU DIANA | I15: =decl_titular -> CHIRIACESCU DIANA | J15: ="Decont nr. "&decl_nr_decont -> #REF! | K15: =IF(ROUND(G15,2)=0,"NU","DA") -> NU
B16: 9 | C16: Bloc 2 — Cheltuieli | D16: =IF(ROUND(Jurnale!H43,2)=0,"",decl_data_decont) | E16: =Jurnale!G43 -> 4426 | F16: =Jurnale!J36 -> 542 | G16: =Jurnale!H43 -> 0 | H16: =Jurnale!I43 -> Decont cheltuieli — TVA deductibilă - decont /31.07.2026 - CHIRIACESCU DIANA | I16: =decl_titular -> CHIRIACESCU DIANA | J16: ="Decont nr. "&decl_nr_decont -> #REF! | K16: =IF(ROUND(G16,2)=0,"NU","DA") -> NU
B17: 10 | C17: Bloc 3 — Regularizare | D17: =IF(ROUND(Jurnale!H70,2)=0,"",decl_data_decont) | E17: =Jurnale!G70 -> 542 | F17: =Jurnale!J70 -> 542 | G17: =Jurnale!H70 -> 0 | H17: =Jurnale!I70 -> Compensarea avansului cu datoria față de titular - decont /31.07.2026 - CHIRIACESCU DIANA | I17: =decl_titular -> CHIRIACESCU DIANA | J17: ="Decont nr. "&decl_nr_decont -> #REF! | K17: =IF(ROUND(G17,2)=0,"NU","DA") -> NU
B18: 11 | C18: Bloc 4 — Plată | D18: =IF(ROUND(Jurnale!H90,2)=0,"",decl_data_plata) -> 46239 | E18: =Jurnale!G90 -> 542 | F18: =Jurnale!J90 -> 5121 | G18: =Jurnale!H90 -> 3938.76 | H18: =Jurnale!I90 -> Stingerea datoriei față de titular - decont /31.07.2026 - CHIRIACESCU DIANA | I18: =decl_titular -> CHIRIACESCU DIANA | J18: ="Decont nr. "&decl_nr_decont -> #REF! | K18: =IF(ROUND(G18,2)=0,"NU","DA") -> DA
B19: 12 | C19: Bloc 4 — Restituire | D19: =IF(ROUND(Jurnale!H91,2)=0,"",decl_data_plata) | E19: =Jurnale!G91 -> 5121 | F19: =Jurnale!J91 -> 542 | G19: =Jurnale!H91 -> 0 | H19: =Jurnale!I91 -> Încasarea avansului neutilizat de la titular - decont /31.07.2026 - CHIRIACESCU DIANA | I19: =decl_titular -> CHIRIACESCU DIANA | J19: ="Decont nr. "&decl_nr_decont -> #REF! | K19: =IF(ROUND(G19,2)=0,"NU","DA") -> NU
C21: Rânduri de importat (Include = DA) | G21: =COUNTIF($K$8:$K$19,"DA") -> 2
C22: Echilibrul Dr = Cr se verifică pe fiecare bloc în sheet-ul Jurnale, nu pe totalul acestei liste.
